
<!DOCTYPE html>
<html>
<head>
    <meta charset="utf-8">
    <title>Rapport de Tests - 2025-01-09 22:10:17</title>
    <style>
        body {
            background-color: #2d2d2d;
            margin: 0;
            padding: 20px;
            font-family: 'Segoe UI', Tahoma, Geneva, Verdana, sans-serif;
        }
        .test-report {
            background-color: #1e1e1e;
            color: #ffffff;
            padding: 20px;
            border-radius: 8px;
            box-shadow: 0 4px 6px rgba(0, 0, 0, 0.1);
            margin: 0 auto;
            max-width: 1200px;
        }
        .test-report pre {
            font-family: 'Consolas', 'Courier New', Courier, monospace;
            white-space: pre-wrap;
            margin: 0;
        }
        .header {
            color: #ffffff;
            margin-bottom: 20px;
            padding-bottom: 10px;
            border-bottom: 1px solid #444;
        }
    </style>
</head>
<body>
    <div class="test-report">
        <div class="header">
            <h1>Rapport de Tests</h1>
            <p>G√©n√©r√© le 2025-01-09 22:10:17</p>
        </div>
        <pre>[1m============================= test session starts ==============================[0m
platform linux -- Python 3.13.1, pytest-7.4.4, pluggy-1.5.0 -- /usr/local/bin/python3.13
cachedir: .pytest_cache
rootdir: /app
configfile: pyproject.toml
testpaths: tests
plugins: timeout-2.3.1, asyncio-0.21.2, anyio-3.7.1, cov-4.1.0
asyncio: mode=Mode.AUTO
[1mcollecting ... [0mcollected 34 items
tests/test_api_endpoints.py::TestAPI::test_join_queue_flow [32mPASSED[0m[32m        [  2%][0m
tests/test_api_endpoints.py::TestAPI::test_join_queue_flow_when_full [31mFAILED[0m[31m [  5%][0m
tests/test_api_endpoints.py::TestAPI::test_leave_queue [32mPASSED[0m[31m            [  8%][0m
tests/test_api_endpoints.py::TestAPI::test_get_status_nonexistent [32mPASSED[0m[31m [ 11%][0m
tests/test_api_endpoints.py::TestAPI::test_heartbeat [32mPASSED[0m[31m              [ 14%][0m
tests/test_api_endpoints.py::TestAPI::test_heartbeat_invalid [32mPASSED[0m[31m      [ 17%][0m
tests/test_api_endpoints.py::TestAPI::test_timers_async [31mFAILED[0m[31m           [ 20%][0m
tests/test_celery.py::test_celery_eager_mode [32mPASSED[0m[31m                      [ 23%][0m
tests/test_celery.py::test_celery_task_chaining [32mPASSED[0m[31m                   [ 26%][0m
tests/test_celery.py::test_celery_error_handling [32mPASSED[0m[31m                  [ 29%][0m
tests/test_integration.py::TestIntegration::test_concurrent_users [31mFAILED[0m[31m [ 32%][0m
tests/test_integration.py::TestIntegration::test_requeue_mechanism [32mPASSED[0m[31m [ 35%][0m
tests/test_queue_manager.py::TestQueueManager::test_fill_active_queue [32mPASSED[0m[31m [ 38%][0m
tests/test_queue_manager.py::TestQueueManager::test_add_to_queue [32mPASSED[0m[31m  [ 41%][0m
tests/test_queue_manager.py::TestQueueManager::test_draft_flow [32mPASSED[0m[31m    [ 44%][0m
tests/test_queue_manager.py::TestQueueManager::test_draft_expiration [32mPASSED[0m[31m [ 47%][0m
tests/test_queue_manager.py::TestQueueManager::test_error_handling [32mPASSED[0m[31m [ 50%][0m
tests/test_queue_manager.py::TestQueueManager::test_timer_edge_cases [32mPASSED[0m[31m [ 52%][0m
tests/test_queue_manager.py::TestQueueManager::test_slot_checker_lifecycle [32mPASSED[0m[31m [ 55%][0m
tests/test_queue_manager.py::TestQueueManager::test_verify_queue_state_errors [32mPASSED[0m[31m [ 58%][0m
tests/test_queue_manager.py::TestQueueManager::test_session_management [32mPASSED[0m[31m [ 61%][0m
tests/test_timers.py::TestTimers::test_draft_timer_redis [32mPASSED[0m[31m          [ 64%][0m
tests/test_timers.py::TestTimers::test_session_timer_redis [32mPASSED[0m[31m        [ 67%][0m
tests/test_timers.py::TestTimers::test_get_timers_endpoint_draft [31mFAILED[0m[31m  [ 70%][0m
tests/test_timers.py::TestTimers::test_get_timers_endpoint_session [31mFAILED[0m[31m [ 73%][0m
tests/test_timers.py::TestTimers::test_get_timers_endpoint_both [31mFAILED[0m[31m   [ 76%][0m
tests/test_timers.py::TestTimers::test_get_timers_endpoint_no_timers [32mPASSED[0m[31m [ 79%][0m
tests/test_timers.py::TestTimers::test_pubsub_connection_draft [31mFAILED[0m[31m    [ 82%][0m
tests/test_timers.py::TestTimers::test_pubsub_connection_session [32mPASSED[0m[31m  [ 85%][0m
tests/test_timers.py::TestTimers::test_pubsub_multiple_updates [31mFAILED[0m[31m    [ 88%][0m
tests/test_timers.py::test_update_timer_channel_expiration [32mPASSED[0m[31m        [ 91%][0m
tests/test_timers.py::test_update_timer_channel [32mPASSED[0m[31m                   [ 94%][0m
tests/test_timers_async.py::TestTimersAsync::test_pubsub_multiple_updates_async [31mFAILED[0m[31m [ 97%][0m
tests/test_timers_async.py::TestTimersAsync::test_update_timer_channel_async [32mPASSED[0m[31m [100%][0m
=================================== FAILURES ===================================
[31m[1m____________________ TestAPI.test_join_queue_flow_when_full ____________________[0m
self = <test_api_endpoints.TestAPI object at 0xffffb41e60d0>
test_client = <httpx.AsyncClient object at 0xffffb4072fd0>
redis_client = <redis.asyncio.client.Redis(<redis.asyncio.connection.ConnectionPool(<redis.asyncio.connection.Connection(host=redis-test,port=6379,db=1)>)>)>
>   ???
[1m[31mE   KeyError: 'position'[0m
[1m[31m/Users/chrysostomebeltran/Documents/GitHub/redis_queue/tests/test_api_endpoints.py[0m:99: KeyError
---------------------------- Captured stderr setup -----------------------------
2025-01-09 21:10:21 - test_logger - INFO - Connexion Redis √©tablie avec succ√®s
2025-01-09 21:10:21 - test_logger - INFO - QueueManager initialis√© avec succ√®s
2025-01-09 21:10:21 - test_logger - INFO - Client de test initialis√© avec succ√®s
------------------------------ Captured log setup ------------------------------
[32mINFO    [0m test_logger:conftest.py:132 Connexion Redis √©tablie avec succ√®s
[32mINFO    [0m test_logger:conftest.py:155 QueueManager initialis√© avec succ√®s
[32mINFO    [0m test_logger:conftest.py:168 Client de test initialis√© avec succ√®s
----------------------------- Captured stderr call -----------------------------
2025-01-09 21:10:21 - test_logger - INFO - Tentative d'ajout de l'utilisateur test_user_0
2025-01-09 21:10:21 - test_logger - INFO - Statut actuel: {'status': None}
2025-01-09 21:10:21 - test_logger - INFO - Tentative d'ajout √† la file d'attente pour test_user_0 avec statut None
2025-01-09 21:10:21 - test_logger - INFO - R√©sultats de la transaction Redis pour test_user_0: [1, 1, 1]
2025-01-09 21:10:21 - test_logger - INFO - V√©rification post-transaction pour test_user_0: queued=1, in_waiting=True
2025-01-09 21:10:21 - test_logger - INFO - Aucun historique de statuts trouv√© pour test_user_0
2025-01-09 21:10:21 - test_logger - INFO - Tentative d'offre de slot √† test_user_0
2025-01-09 21:10:21 - test_logger - INFO - Slot offert avec succ√®s √† test_user_0
2025-01-09 21:10:21 - test_logger - INFO - Tentative d'offre de slot √† test_user_0
2025-01-09 21:10:21 - test_logger - INFO - √âtat invalide pour test_user_0: d√©j√† en draft ou actif
2025-01-09 21:10:21 - test_logger - INFO - Connexion confirm√©e pour test_user_0
2025-01-09 21:10:21 - test_logger - INFO - Tentative d'ajout de l'utilisateur test_user_1
2025-01-09 21:10:21 - test_logger - INFO - Statut actuel: {'status': None}
2025-01-09 21:10:21 - test_logger - INFO - Tentative d'ajout √† la file d'attente pour test_user_1 avec statut None
2025-01-09 21:10:21 - test_logger - INFO - R√©sultats de la transaction Redis pour test_user_1: [1, 1, 1]
2025-01-09 21:10:21 - test_logger - INFO - V√©rification post-transaction pour test_user_1: queued=1, in_waiting=True
2025-01-09 21:10:21 - test_logger - INFO - Aucun historique de statuts trouv√© pour test_user_1
2025-01-09 21:10:21 - test_logger - INFO - Tentative d'offre de slot √† test_user_1
2025-01-09 21:10:21 - test_logger - INFO - Slot offert avec succ√®s √† test_user_1
2025-01-09 21:10:21 - test_logger - INFO - Tentative d'offre de slot √† test_user_1
2025-01-09 21:10:21 - test_logger - INFO - √âtat invalide pour test_user_1: d√©j√† en draft ou actif
2025-01-09 21:10:21 - test_logger - INFO - Connexion confirm√©e pour test_user_1
2025-01-09 21:10:21 - test_logger - INFO - Tentative d'ajout de l'utilisateur test_user_2
2025-01-09 21:10:21 - test_logger - INFO - Statut actuel: {'status': None}
2025-01-09 21:10:21 - test_logger - INFO - Tentative d'ajout √† la file d'attente pour test_user_2 avec statut None
2025-01-09 21:10:21 - test_logger - INFO - R√©sultats de la transaction Redis pour test_user_2: [1, 1, 1]
2025-01-09 21:10:21 - test_logger - INFO - V√©rification post-transaction pour test_user_2: queued=1, in_waiting=True
2025-01-09 21:10:21 - test_logger - INFO - Aucun historique de statuts trouv√© pour test_user_2
2025-01-09 21:10:21 - test_logger - INFO - Tentative d'offre de slot √† test_user_2
2025-01-09 21:10:21 - test_logger - INFO - Slot offert avec succ√®s √† test_user_2
2025-01-09 21:10:21 - test_logger - INFO - Tentative d'offre de slot √† test_user_2
2025-01-09 21:10:21 - test_logger - INFO - √âtat invalide pour test_user_2: d√©j√† en draft ou actif
2025-01-09 21:10:21 - test_logger - INFO - Connexion confirm√©e pour test_user_2
2025-01-09 21:10:21 - test_logger - INFO - Tentative d'ajout de l'utilisateur test_user_3
2025-01-09 21:10:21 - test_logger - INFO - Statut actuel: {'status': None}
2025-01-09 21:10:21 - test_logger - INFO - Tentative d'ajout √† la file d'attente pour test_user_3 avec statut None
2025-01-09 21:10:21 - test_logger - INFO - R√©sultats de la transaction Redis pour test_user_3: [1, 1, 1]
2025-01-09 21:10:21 - test_logger - INFO - V√©rification post-transaction pour test_user_3: queued=1, in_waiting=True
2025-01-09 21:10:21 - test_logger - INFO - Aucun historique de statuts trouv√© pour test_user_3
2025-01-09 21:10:21 - test_logger - INFO - Tentative d'offre de slot √† test_user_3
2025-01-09 21:10:21 - test_logger - INFO - Slot offert avec succ√®s √† test_user_3
2025-01-09 21:10:21 - test_logger - INFO - Tentative d'offre de slot √† test_user_3
2025-01-09 21:10:21 - test_logger - INFO - √âtat invalide pour test_user_3: d√©j√† en draft ou actif
2025-01-09 21:10:21 - test_logger - INFO - Connexion confirm√©e pour test_user_3
2025-01-09 21:10:21 - test_logger - INFO - Tentative d'ajout de l'utilisateur test_user_4
2025-01-09 21:10:21 - test_logger - INFO - Statut actuel: {'status': None}
2025-01-09 21:10:21 - test_logger - INFO - Tentative d'ajout √† la file d'attente pour test_user_4 avec statut None
2025-01-09 21:10:21 - test_logger - INFO - R√©sultats de la transaction Redis pour test_user_4: [1, 1, 1]
2025-01-09 21:10:21 - test_logger - INFO - V√©rification post-transaction pour test_user_4: queued=1, in_waiting=True
2025-01-09 21:10:21 - test_logger - INFO - Aucun historique de statuts trouv√© pour test_user_4
2025-01-09 21:10:21 - test_logger - INFO - Tentative d'offre de slot √† test_user_4
2025-01-09 21:10:21 - test_logger - INFO - Slot offert avec succ√®s √† test_user_4
2025-01-09 21:10:21 - test_logger - INFO - Tentative d'offre de slot √† test_user_4
2025-01-09 21:10:21 - test_logger - INFO - √âtat invalide pour test_user_4: d√©j√† en draft ou actif
2025-01-09 21:10:21 - test_logger - INFO - Connexion confirm√©e pour test_user_4
2025-01-09 21:10:21 - test_logger - INFO - Tentative d'ajout de l'utilisateur test_user_5
2025-01-09 21:10:21 - test_logger - INFO - Statut actuel: {'status': None}
2025-01-09 21:10:21 - test_logger - INFO - Tentative d'ajout √† la file d'attente pour test_user_5 avec statut None
2025-01-09 21:10:21 - test_logger - INFO - R√©sultats de la transaction Redis pour test_user_5: [1, 1, 1]
2025-01-09 21:10:21 - test_logger - INFO - V√©rification post-transaction pour test_user_5: queued=1, in_waiting=True
2025-01-09 21:10:21 - test_logger - INFO - Aucun historique de statuts trouv√© pour test_user_5
2025-01-09 21:10:21 - test_logger - INFO - Tentative d'offre de slot √† test_user_5
2025-01-09 21:10:21 - test_logger - INFO - Slot offert avec succ√®s √† test_user_5
2025-01-09 21:10:21 - test_logger - INFO - Tentative d'offre de slot √† test_user_5
2025-01-09 21:10:21 - test_logger - INFO - √âtat invalide pour test_user_5: d√©j√† en draft ou actif
2025-01-09 21:10:21 - test_logger - INFO - Connexion confirm√©e pour test_user_5
2025-01-09 21:10:21 - test_logger - INFO - Tentative d'ajout de l'utilisateur test_user_6
2025-01-09 21:10:21 - test_logger - INFO - Statut actuel: {'status': None}
2025-01-09 21:10:21 - test_logger - INFO - Tentative d'ajout √† la file d'attente pour test_user_6 avec statut None
2025-01-09 21:10:21 - test_logger - INFO - R√©sultats de la transaction Redis pour test_user_6: [1, 1, 1]
2025-01-09 21:10:21 - test_logger - INFO - V√©rification post-transaction pour test_user_6: queued=1, in_waiting=True
2025-01-09 21:10:21 - test_logger - INFO - Aucun historique de statuts trouv√© pour test_user_6
2025-01-09 21:10:21 - test_logger - INFO - Tentative d'offre de slot √† test_user_6
2025-01-09 21:10:21 - test_logger - INFO - Slot offert avec succ√®s √† test_user_6
2025-01-09 21:10:21 - test_logger - INFO - Tentative d'offre de slot √† test_user_6
2025-01-09 21:10:21 - test_logger - INFO - √âtat invalide pour test_user_6: d√©j√† en draft ou actif
2025-01-09 21:10:21 - test_logger - INFO - Connexion confirm√©e pour test_user_6
2025-01-09 21:10:21 - test_logger - INFO - Tentative d'ajout de l'utilisateur test_user_7
2025-01-09 21:10:21 - test_logger - INFO - Statut actuel: {'status': None}
2025-01-09 21:10:21 - test_logger - INFO - Tentative d'ajout √† la file d'attente pour test_user_7 avec statut None
2025-01-09 21:10:21 - test_logger - INFO - R√©sultats de la transaction Redis pour test_user_7: [1, 1, 1]
2025-01-09 21:10:21 - test_logger - INFO - V√©rification post-transaction pour test_user_7: queued=1, in_waiting=True
2025-01-09 21:10:21 - test_logger - INFO - Aucun historique de statuts trouv√© pour test_user_7
2025-01-09 21:10:21 - test_logger - INFO - Tentative d'offre de slot √† test_user_7
2025-01-09 21:10:21 - test_logger - INFO - Slot offert avec succ√®s √† test_user_7
2025-01-09 21:10:21 - test_logger - INFO - Tentative d'offre de slot √† test_user_7
2025-01-09 21:10:21 - test_logger - INFO - √âtat invalide pour test_user_7: d√©j√† en draft ou actif
2025-01-09 21:10:21 - test_logger - INFO - Connexion confirm√©e pour test_user_7
2025-01-09 21:10:21 - test_logger - INFO - Tentative d'ajout de l'utilisateur test_user_8
2025-01-09 21:10:21 - test_logger - INFO - Statut actuel: {'status': None}
2025-01-09 21:10:21 - test_logger - INFO - Tentative d'ajout √† la file d'attente pour test_user_8 avec statut None
2025-01-09 21:10:21 - test_logger - INFO - R√©sultats de la transaction Redis pour test_user_8: [1, 1, 1]
2025-01-09 21:10:21 - test_logger - INFO - V√©rification post-transaction pour test_user_8: queued=1, in_waiting=True
2025-01-09 21:10:21 - test_logger - INFO - Aucun historique de statuts trouv√© pour test_user_8
2025-01-09 21:10:21 - test_logger - INFO - Tentative d'offre de slot √† test_user_8
2025-01-09 21:10:21 - test_logger - INFO - Slot offert avec succ√®s √† test_user_8
2025-01-09 21:10:21 - test_logger - INFO - Tentative d'offre de slot √† test_user_8
2025-01-09 21:10:21 - test_logger - INFO - √âtat invalide pour test_user_8: d√©j√† en draft ou actif
2025-01-09 21:10:21 - test_logger - INFO - Connexion confirm√©e pour test_user_8
2025-01-09 21:10:21 - test_logger - INFO - Tentative d'ajout de l'utilisateur test_user_9
2025-01-09 21:10:21 - test_logger - INFO - Statut actuel: {'status': None}
2025-01-09 21:10:21 - test_logger - INFO - Tentative d'ajout √† la file d'attente pour test_user_9 avec statut None
2025-01-09 21:10:21 - test_logger - INFO - R√©sultats de la transaction Redis pour test_user_9: [1, 1, 1]
2025-01-09 21:10:21 - test_logger - INFO - V√©rification post-transaction pour test_user_9: queued=1, in_waiting=True
2025-01-09 21:10:21 - test_logger - INFO - Aucun historique de statuts trouv√© pour test_user_9
2025-01-09 21:10:21 - test_logger - INFO - Tentative d'offre de slot √† test_user_9
2025-01-09 21:10:21 - test_logger - INFO - Slot offert avec succ√®s √† test_user_9
2025-01-09 21:10:21 - test_logger - INFO - Tentative d'offre de slot √† test_user_9
2025-01-09 21:10:21 - test_logger - INFO - √âtat invalide pour test_user_9: d√©j√† en draft ou actif
2025-01-09 21:10:21 - test_logger - INFO - Connexion confirm√©e pour test_user_9
2025-01-09 21:10:21 - test_logger - INFO - Tentative d'ajout de l'utilisateur test_user_10
2025-01-09 21:10:21 - test_logger - INFO - Statut actuel: {'status': None}
2025-01-09 21:10:21 - test_logger - INFO - Tentative d'ajout √† la file d'attente pour test_user_10 avec statut None
2025-01-09 21:10:21 - test_logger - INFO - R√©sultats de la transaction Redis pour test_user_10: [1, 1, 1]
2025-01-09 21:10:21 - test_logger - INFO - V√©rification post-transaction pour test_user_10: queued=1, in_waiting=True
2025-01-09 21:10:21 - test_logger - INFO - Aucun historique de statuts trouv√© pour test_user_10
2025-01-09 21:10:21 - test_logger - INFO - Tentative d'offre de slot √† test_user_10
2025-01-09 21:10:21 - test_logger - INFO - Slot offert avec succ√®s √† test_user_10
2025-01-09 21:10:21 - test_logger - INFO - Tentative d'offre de slot √† test_user_10
2025-01-09 21:10:21 - test_logger - INFO - √âtat invalide pour test_user_10: d√©j√† en draft ou actif
2025-01-09 21:10:21 - test_logger - INFO - Connexion confirm√©e pour test_user_10
2025-01-09 21:10:21 - test_logger - INFO - Tentative d'ajout de l'utilisateur test_user_11
2025-01-09 21:10:21 - test_logger - INFO - Statut actuel: {'status': None}
2025-01-09 21:10:21 - test_logger - INFO - Tentative d'ajout √† la file d'attente pour test_user_11 avec statut None
2025-01-09 21:10:21 - test_logger - INFO - R√©sultats de la transaction Redis pour test_user_11: [1, 1, 1]
2025-01-09 21:10:21 - test_logger - INFO - V√©rification post-transaction pour test_user_11: queued=1, in_waiting=True
2025-01-09 21:10:21 - test_logger - INFO - Aucun historique de statuts trouv√© pour test_user_11
2025-01-09 21:10:21 - test_logger - INFO - Tentative d'offre de slot √† test_user_11
2025-01-09 21:10:21 - test_logger - INFO - Slot offert avec succ√®s √† test_user_11
2025-01-09 21:10:21 - test_logger - INFO - Tentative d'offre de slot √† test_user_11
2025-01-09 21:10:21 - test_logger - INFO - √âtat invalide pour test_user_11: d√©j√† en draft ou actif
2025-01-09 21:10:21 - test_logger - INFO - Connexion confirm√©e pour test_user_11
2025-01-09 21:10:21 - test_logger - INFO - Tentative d'ajout de l'utilisateur test_user_12
2025-01-09 21:10:21 - test_logger - INFO - Statut actuel: {'status': None}
2025-01-09 21:10:21 - test_logger - INFO - Tentative d'ajout √† la file d'attente pour test_user_12 avec statut None
2025-01-09 21:10:21 - test_logger - INFO - R√©sultats de la transaction Redis pour test_user_12: [1, 1, 1]
2025-01-09 21:10:21 - test_logger - INFO - V√©rification post-transaction pour test_user_12: queued=1, in_waiting=True
2025-01-09 21:10:21 - test_logger - INFO - Aucun historique de statuts trouv√© pour test_user_12
2025-01-09 21:10:21 - test_logger - INFO - Tentative d'offre de slot √† test_user_12
2025-01-09 21:10:21 - test_logger - INFO - Slot offert avec succ√®s √† test_user_12
2025-01-09 21:10:21 - test_logger - INFO - Tentative d'offre de slot √† test_user_12
2025-01-09 21:10:21 - test_logger - INFO - √âtat invalide pour test_user_12: d√©j√† en draft ou actif
2025-01-09 21:10:21 - test_logger - INFO - Connexion confirm√©e pour test_user_12
2025-01-09 21:10:21 - test_logger - INFO - Tentative d'ajout de l'utilisateur test_user_13
2025-01-09 21:10:21 - test_logger - INFO - Statut actuel: {'status': None}
2025-01-09 21:10:21 - test_logger - INFO - Tentative d'ajout √† la file d'attente pour test_user_13 avec statut None
2025-01-09 21:10:21 - test_logger - INFO - R√©sultats de la transaction Redis pour test_user_13: [1, 1, 1]
2025-01-09 21:10:21 - test_logger - INFO - V√©rification post-transaction pour test_user_13: queued=1, in_waiting=True
2025-01-09 21:10:21 - test_logger - INFO - Aucun historique de statuts trouv√© pour test_user_13
2025-01-09 21:10:21 - test_logger - INFO - Tentative d'offre de slot √† test_user_13
2025-01-09 21:10:21 - test_logger - INFO - Slot offert avec succ√®s √† test_user_13
2025-01-09 21:10:21 - test_logger - INFO - Tentative d'offre de slot √† test_user_13
2025-01-09 21:10:21 - test_logger - INFO - √âtat invalide pour test_user_13: d√©j√† en draft ou actif
2025-01-09 21:10:21 - test_logger - INFO - Connexion confirm√©e pour test_user_13
2025-01-09 21:10:21 - test_logger - INFO - Tentative d'ajout de l'utilisateur test_user_14
2025-01-09 21:10:21 - test_logger - INFO - Statut actuel: {'status': None}
2025-01-09 21:10:21 - test_logger - INFO - Tentative d'ajout √† la file d'attente pour test_user_14 avec statut None
2025-01-09 21:10:21 - test_logger - INFO - R√©sultats de la transaction Redis pour test_user_14: [1, 1, 1]
2025-01-09 21:10:21 - test_logger - INFO - V√©rification post-transaction pour test_user_14: queued=1, in_waiting=True
2025-01-09 21:10:21 - test_logger - INFO - Aucun historique de statuts trouv√© pour test_user_14
2025-01-09 21:10:21 - test_logger - INFO - Tentative d'offre de slot √† test_user_14
2025-01-09 21:10:21 - test_logger - INFO - Slot offert avec succ√®s √† test_user_14
2025-01-09 21:10:21 - test_logger - INFO - Tentative d'offre de slot √† test_user_14
2025-01-09 21:10:21 - test_logger - INFO - √âtat invalide pour test_user_14: d√©j√† en draft ou actif
2025-01-09 21:10:21 - test_logger - INFO - Connexion confirm√©e pour test_user_14
2025-01-09 21:10:21 - test_logger - INFO - Tentative d'ajout de l'utilisateur test_user_15
2025-01-09 21:10:21 - test_logger - INFO - Statut actuel: {'status': None}
2025-01-09 21:10:21 - test_logger - INFO - Tentative d'ajout √† la file d'attente pour test_user_15 avec statut None
2025-01-09 21:10:21 - test_logger - INFO - R√©sultats de la transaction Redis pour test_user_15: [1, 1, 1]
2025-01-09 21:10:21 - test_logger - INFO - V√©rification post-transaction pour test_user_15: queued=1, in_waiting=True
2025-01-09 21:10:21 - test_logger - INFO - Aucun historique de statuts trouv√© pour test_user_15
2025-01-09 21:10:21 - test_logger - INFO - Tentative d'offre de slot √† test_user_15
2025-01-09 21:10:21 - test_logger - INFO - Slot offert avec succ√®s √† test_user_15
2025-01-09 21:10:21 - test_logger - INFO - Tentative d'offre de slot √† test_user_15
2025-01-09 21:10:21 - test_logger - INFO - √âtat invalide pour test_user_15: d√©j√† en draft ou actif
2025-01-09 21:10:21 - test_logger - INFO - Connexion confirm√©e pour test_user_15
2025-01-09 21:10:21 - test_logger - INFO - Tentative d'ajout de l'utilisateur test_user_16
2025-01-09 21:10:21 - test_logger - INFO - Statut actuel: {'status': None}
2025-01-09 21:10:21 - test_logger - INFO - Tentative d'ajout √† la file d'attente pour test_user_16 avec statut None
2025-01-09 21:10:21 - test_logger - INFO - R√©sultats de la transaction Redis pour test_user_16: [1, 1, 1]
2025-01-09 21:10:21 - test_logger - INFO - V√©rification post-transaction pour test_user_16: queued=1, in_waiting=True
2025-01-09 21:10:21 - test_logger - INFO - Aucun historique de statuts trouv√© pour test_user_16
2025-01-09 21:10:21 - test_logger - INFO - Tentative d'offre de slot √† test_user_16
2025-01-09 21:10:21 - test_logger - INFO - Slot offert avec succ√®s √† test_user_16
2025-01-09 21:10:21 - test_logger - INFO - Tentative d'offre de slot √† test_user_16
2025-01-09 21:10:21 - test_logger - INFO - √âtat invalide pour test_user_16: d√©j√† en draft ou actif
2025-01-09 21:10:21 - test_logger - INFO - Connexion confirm√©e pour test_user_16
2025-01-09 21:10:21 - test_logger - INFO - Tentative d'ajout de l'utilisateur test_user_17
2025-01-09 21:10:21 - test_logger - INFO - Statut actuel: {'status': None}
2025-01-09 21:10:21 - test_logger - INFO - Tentative d'ajout √† la file d'attente pour test_user_17 avec statut None
2025-01-09 21:10:21 - test_logger - INFO - R√©sultats de la transaction Redis pour test_user_17: [1, 1, 1]
2025-01-09 21:10:21 - test_logger - INFO - V√©rification post-transaction pour test_user_17: queued=1, in_waiting=True
2025-01-09 21:10:21 - test_logger - INFO - Aucun historique de statuts trouv√© pour test_user_17
2025-01-09 21:10:21 - test_logger - INFO - Tentative d'offre de slot √† test_user_17
2025-01-09 21:10:21 - test_logger - INFO - Slot offert avec succ√®s √† test_user_17
2025-01-09 21:10:21 - test_logger - INFO - Tentative d'offre de slot √† test_user_17
2025-01-09 21:10:21 - test_logger - INFO - √âtat invalide pour test_user_17: d√©j√† en draft ou actif
2025-01-09 21:10:21 - test_logger - INFO - Connexion confirm√©e pour test_user_17
2025-01-09 21:10:21 - test_logger - INFO - Tentative d'ajout de l'utilisateur test_user_18
2025-01-09 21:10:21 - test_logger - INFO - Statut actuel: {'status': None}
2025-01-09 21:10:21 - test_logger - INFO - Tentative d'ajout √† la file d'attente pour test_user_18 avec statut None
2025-01-09 21:10:21 - test_logger - INFO - R√©sultats de la transaction Redis pour test_user_18: [1, 1, 1]
2025-01-09 21:10:21 - test_logger - INFO - V√©rification post-transaction pour test_user_18: queued=1, in_waiting=True
2025-01-09 21:10:21 - test_logger - INFO - Aucun historique de statuts trouv√© pour test_user_18
2025-01-09 21:10:21 - test_logger - INFO - Tentative d'offre de slot √† test_user_18
2025-01-09 21:10:21 - test_logger - INFO - Slot offert avec succ√®s √† test_user_18
2025-01-09 21:10:21 - test_logger - INFO - Tentative d'offre de slot √† test_user_18
2025-01-09 21:10:21 - test_logger - INFO - √âtat invalide pour test_user_18: d√©j√† en draft ou actif
2025-01-09 21:10:21 - test_logger - INFO - Connexion confirm√©e pour test_user_18
2025-01-09 21:10:21 - test_logger - INFO - Tentative d'ajout de l'utilisateur test_user_19
2025-01-09 21:10:21 - test_logger - INFO - Statut actuel: {'status': None}
2025-01-09 21:10:21 - test_logger - INFO - Tentative d'ajout √† la file d'attente pour test_user_19 avec statut None
2025-01-09 21:10:21 - test_logger - INFO - R√©sultats de la transaction Redis pour test_user_19: [1, 1, 1]
2025-01-09 21:10:21 - test_logger - INFO - V√©rification post-transaction pour test_user_19: queued=1, in_waiting=True
2025-01-09 21:10:21 - test_logger - INFO - Aucun historique de statuts trouv√© pour test_user_19
2025-01-09 21:10:21 - test_logger - INFO - Tentative d'offre de slot √† test_user_19
2025-01-09 21:10:21 - test_logger - INFO - Slot offert avec succ√®s √† test_user_19
2025-01-09 21:10:21 - test_logger - INFO - Tentative d'offre de slot √† test_user_19
2025-01-09 21:10:21 - test_logger - INFO - √âtat invalide pour test_user_19: d√©j√† en draft ou actif
2025-01-09 21:10:21 - test_logger - INFO - Connexion confirm√©e pour test_user_19
2025-01-09 21:10:21 - test_logger - INFO - Tentative d'ajout de l'utilisateur test_user_20
2025-01-09 21:10:21 - test_logger - INFO - Statut actuel: {'status': None}
2025-01-09 21:10:21 - test_logger - INFO - Tentative d'ajout √† la file d'attente pour test_user_20 avec statut None
2025-01-09 21:10:21 - test_logger - INFO - R√©sultats de la transaction Redis pour test_user_20: [1, 1, 1]
2025-01-09 21:10:21 - test_logger - INFO - V√©rification post-transaction pour test_user_20: queued=1, in_waiting=True
2025-01-09 21:10:21 - test_logger - INFO - Aucun historique de statuts trouv√© pour test_user_20
2025-01-09 21:10:21 - test_logger - INFO - Tentative d'offre de slot √† test_user_20
2025-01-09 21:10:21 - test_logger - INFO - Slot offert avec succ√®s √† test_user_20
2025-01-09 21:10:21 - test_logger - INFO - Tentative d'offre de slot √† test_user_20
2025-01-09 21:10:21 - test_logger - INFO - √âtat invalide pour test_user_20: d√©j√† en draft ou actif
2025-01-09 21:10:21 - test_logger - INFO - Connexion confirm√©e pour test_user_20
2025-01-09 21:10:21 - test_logger - INFO - Tentative d'ajout de l'utilisateur test_user_21
2025-01-09 21:10:21 - test_logger - INFO - Statut actuel: {'status': None}
2025-01-09 21:10:21 - test_logger - INFO - Tentative d'ajout √† la file d'attente pour test_user_21 avec statut None
2025-01-09 21:10:21 - test_logger - INFO - R√©sultats de la transaction Redis pour test_user_21: [1, 1, 1]
2025-01-09 21:10:21 - test_logger - INFO - V√©rification post-transaction pour test_user_21: queued=1, in_waiting=True
2025-01-09 21:10:21 - test_logger - INFO - Aucun historique de statuts trouv√© pour test_user_21
2025-01-09 21:10:21 - test_logger - INFO - Tentative d'offre de slot √† test_user_21
2025-01-09 21:10:21 - test_logger - INFO - Slot offert avec succ√®s √† test_user_21
2025-01-09 21:10:21 - test_logger - INFO - Tentative d'offre de slot √† test_user_21
2025-01-09 21:10:21 - test_logger - INFO - √âtat invalide pour test_user_21: d√©j√† en draft ou actif
2025-01-09 21:10:21 - test_logger - INFO - Connexion confirm√©e pour test_user_21
2025-01-09 21:10:21 - test_logger - INFO - Tentative d'ajout de l'utilisateur test_user_22
2025-01-09 21:10:21 - test_logger - INFO - Statut actuel: {'status': None}
2025-01-09 21:10:21 - test_logger - INFO - Tentative d'ajout √† la file d'attente pour test_user_22 avec statut None
2025-01-09 21:10:21 - test_logger - INFO - R√©sultats de la transaction Redis pour test_user_22: [1, 1, 1]
2025-01-09 21:10:21 - test_logger - INFO - V√©rification post-transaction pour test_user_22: queued=1, in_waiting=True
2025-01-09 21:10:21 - test_logger - INFO - Aucun historique de statuts trouv√© pour test_user_22
2025-01-09 21:10:21 - test_logger - INFO - Tentative d'offre de slot √† test_user_22
2025-01-09 21:10:21 - test_logger - INFO - Slot offert avec succ√®s √† test_user_22
2025-01-09 21:10:21 - test_logger - INFO - Tentative d'offre de slot √† test_user_22
2025-01-09 21:10:21 - test_logger - INFO - √âtat invalide pour test_user_22: d√©j√† en draft ou actif
2025-01-09 21:10:21 - test_logger - INFO - Connexion confirm√©e pour test_user_22
2025-01-09 21:10:21 - test_logger - INFO - Tentative d'ajout de l'utilisateur test_user_23
2025-01-09 21:10:21 - test_logger - INFO - Statut actuel: {'status': None}
2025-01-09 21:10:21 - test_logger - INFO - Tentative d'ajout √† la file d'attente pour test_user_23 avec statut None
2025-01-09 21:10:21 - test_logger - INFO - R√©sultats de la transaction Redis pour test_user_23: [1, 1, 1]
2025-01-09 21:10:21 - test_logger - INFO - V√©rification post-transaction pour test_user_23: queued=1, in_waiting=True
2025-01-09 21:10:21 - test_logger - INFO - Aucun historique de statuts trouv√© pour test_user_23
2025-01-09 21:10:21 - test_logger - INFO - Tentative d'offre de slot √† test_user_23
2025-01-09 21:10:21 - test_logger - INFO - Slot offert avec succ√®s √† test_user_23
2025-01-09 21:10:21 - test_logger - INFO - Tentative d'offre de slot √† test_user_23
2025-01-09 21:10:21 - test_logger - INFO - √âtat invalide pour test_user_23: d√©j√† en draft ou actif
2025-01-09 21:10:21 - test_logger - INFO - Connexion confirm√©e pour test_user_23
2025-01-09 21:10:21 - test_logger - INFO - Tentative d'ajout de l'utilisateur test_user_24
2025-01-09 21:10:21 - test_logger - INFO - Statut actuel: {'status': None}
2025-01-09 21:10:21 - test_logger - INFO - Tentative d'ajout √† la file d'attente pour test_user_24 avec statut None
2025-01-09 21:10:21 - test_logger - INFO - R√©sultats de la transaction Redis pour test_user_24: [1, 1, 1]
2025-01-09 21:10:21 - test_logger - INFO - V√©rification post-transaction pour test_user_24: queued=1, in_waiting=True
2025-01-09 21:10:21 - test_logger - INFO - Aucun historique de statuts trouv√© pour test_user_24
2025-01-09 21:10:21 - test_logger - INFO - Tentative d'offre de slot √† test_user_24
2025-01-09 21:10:21 - test_logger - INFO - Slot offert avec succ√®s √† test_user_24
2025-01-09 21:10:21 - test_logger - INFO - Tentative d'offre de slot √† test_user_24
2025-01-09 21:10:21 - test_logger - INFO - √âtat invalide pour test_user_24: d√©j√† en draft ou actif
2025-01-09 21:10:21 - test_logger - INFO - Connexion confirm√©e pour test_user_24
2025-01-09 21:10:21 - test_logger - INFO - Tentative d'ajout de l'utilisateur test_user_25
2025-01-09 21:10:21 - test_logger - INFO - Statut actuel: {'status': None}
2025-01-09 21:10:21 - test_logger - INFO - Tentative d'ajout √† la file d'attente pour test_user_25 avec statut None
2025-01-09 21:10:21 - test_logger - INFO - R√©sultats de la transaction Redis pour test_user_25: [1, 1, 1]
2025-01-09 21:10:21 - test_logger - INFO - V√©rification post-transaction pour test_user_25: queued=1, in_waiting=True
2025-01-09 21:10:21 - test_logger - INFO - Aucun historique de statuts trouv√© pour test_user_25
2025-01-09 21:10:21 - test_logger - INFO - Tentative d'offre de slot √† test_user_25
2025-01-09 21:10:21 - test_logger - INFO - Slot offert avec succ√®s √† test_user_25
2025-01-09 21:10:21 - test_logger - INFO - Tentative d'offre de slot √† test_user_25
2025-01-09 21:10:21 - test_logger - INFO - √âtat invalide pour test_user_25: d√©j√† en draft ou actif
2025-01-09 21:10:21 - test_logger - INFO - Connexion confirm√©e pour test_user_25
2025-01-09 21:10:21 - test_logger - INFO - Tentative d'ajout de l'utilisateur test_user_26
2025-01-09 21:10:21 - test_logger - INFO - Statut actuel: {'status': None}
2025-01-09 21:10:21 - test_logger - INFO - Tentative d'ajout √† la file d'attente pour test_user_26 avec statut None
2025-01-09 21:10:21 - test_logger - INFO - R√©sultats de la transaction Redis pour test_user_26: [1, 1, 1]
2025-01-09 21:10:21 - test_logger - INFO - V√©rification post-transaction pour test_user_26: queued=1, in_waiting=True
2025-01-09 21:10:21 - test_logger - INFO - Aucun historique de statuts trouv√© pour test_user_26
2025-01-09 21:10:21 - test_logger - INFO - Tentative d'offre de slot √† test_user_26
2025-01-09 21:10:21 - test_logger - INFO - Slot offert avec succ√®s √† test_user_26
2025-01-09 21:10:21 - test_logger - INFO - Tentative d'offre de slot √† test_user_26
2025-01-09 21:10:21 - test_logger - INFO - √âtat invalide pour test_user_26: d√©j√† en draft ou actif
2025-01-09 21:10:21 - test_logger - INFO - Connexion confirm√©e pour test_user_26
2025-01-09 21:10:21 - test_logger - INFO - Tentative d'ajout de l'utilisateur test_user_27
2025-01-09 21:10:21 - test_logger - INFO - Statut actuel: {'status': None}
2025-01-09 21:10:21 - test_logger - INFO - Tentative d'ajout √† la file d'attente pour test_user_27 avec statut None
2025-01-09 21:10:21 - test_logger - INFO - R√©sultats de la transaction Redis pour test_user_27: [1, 1, 1]
2025-01-09 21:10:21 - test_logger - INFO - V√©rification post-transaction pour test_user_27: queued=1, in_waiting=True
2025-01-09 21:10:21 - test_logger - INFO - Aucun historique de statuts trouv√© pour test_user_27
2025-01-09 21:10:21 - test_logger - INFO - Tentative d'offre de slot √† test_user_27
2025-01-09 21:10:21 - test_logger - INFO - Slot offert avec succ√®s √† test_user_27
2025-01-09 21:10:21 - test_logger - INFO - Tentative d'offre de slot √† test_user_27
2025-01-09 21:10:21 - test_logger - INFO - √âtat invalide pour test_user_27: d√©j√† en draft ou actif
2025-01-09 21:10:21 - test_logger - INFO - Connexion confirm√©e pour test_user_27
2025-01-09 21:10:21 - test_logger - INFO - Tentative d'ajout de l'utilisateur test_user_28
2025-01-09 21:10:21 - test_logger - INFO - Statut actuel: {'status': None}
2025-01-09 21:10:21 - test_logger - INFO - Tentative d'ajout √† la file d'attente pour test_user_28 avec statut None
2025-01-09 21:10:21 - test_logger - INFO - R√©sultats de la transaction Redis pour test_user_28: [1, 1, 1]
2025-01-09 21:10:21 - test_logger - INFO - V√©rification post-transaction pour test_user_28: queued=1, in_waiting=True
2025-01-09 21:10:21 - test_logger - INFO - Aucun historique de statuts trouv√© pour test_user_28
2025-01-09 21:10:21 - test_logger - INFO - Tentative d'offre de slot √† test_user_28
2025-01-09 21:10:21 - test_logger - INFO - √âtat invalide pour test_user_28: d√©j√† en draft ou actif
2025-01-09 21:10:21 - test_logger - INFO - Connexion confirm√©e pour test_user_28
2025-01-09 21:10:21 - test_logger - INFO - Tentative d'ajout de l'utilisateur test_user_29
2025-01-09 21:10:21 - test_logger - INFO - Statut actuel: {'status': None}
2025-01-09 21:10:21 - test_logger - INFO - Tentative d'ajout √† la file d'attente pour test_user_29 avec statut None
2025-01-09 21:10:21 - test_logger - INFO - R√©sultats de la transaction Redis pour test_user_29: [1, 1, 1]
2025-01-09 21:10:21 - test_logger - INFO - V√©rification post-transaction pour test_user_29: queued=1, in_waiting=True
2025-01-09 21:10:21 - test_logger - INFO - Aucun historique de statuts trouv√© pour test_user_29
2025-01-09 21:10:21 - test_logger - INFO - Tentative d'offre de slot √† test_user_29
2025-01-09 21:10:21 - test_logger - INFO - Slot offert avec succ√®s √† test_user_29
2025-01-09 21:10:21 - test_logger - INFO - Tentative d'offre de slot √† test_user_29
2025-01-09 21:10:21 - test_logger - INFO - √âtat invalide pour test_user_29: d√©j√† en draft ou actif
2025-01-09 21:10:21 - test_logger - INFO - Connexion confirm√©e pour test_user_29
2025-01-09 21:10:21 - test_logger - INFO - Tentative d'ajout de l'utilisateur test_user_30
2025-01-09 21:10:21 - test_logger - INFO - Statut actuel: {'status': None}
2025-01-09 21:10:21 - test_logger - INFO - Tentative d'ajout √† la file d'attente pour test_user_30 avec statut None
2025-01-09 21:10:21 - test_logger - INFO - R√©sultats de la transaction Redis pour test_user_30: [1, 1, 1]
2025-01-09 21:10:21 - test_logger - INFO - V√©rification post-transaction pour test_user_30: queued=1, in_waiting=True
2025-01-09 21:10:21 - test_logger - INFO - Aucun historique de statuts trouv√© pour test_user_30
2025-01-09 21:10:21 - test_logger - INFO - Tentative d'offre de slot √† test_user_30
2025-01-09 21:10:21 - test_logger - INFO - Slot offert avec succ√®s √† test_user_30
2025-01-09 21:10:21 - test_logger - INFO - Tentative d'offre de slot √† test_user_30
2025-01-09 21:10:21 - test_logger - INFO - √âtat invalide pour test_user_30: d√©j√† en draft ou actif
2025-01-09 21:10:21 - test_logger - INFO - Connexion confirm√©e pour test_user_30
2025-01-09 21:10:21 - test_logger - INFO - Tentative d'ajout de l'utilisateur test_user_31
2025-01-09 21:10:21 - test_logger - INFO - Statut actuel: {'status': None}
2025-01-09 21:10:21 - test_logger - INFO - Tentative d'ajout √† la file d'attente pour test_user_31 avec statut None
2025-01-09 21:10:21 - test_logger - INFO - R√©sultats de la transaction Redis pour test_user_31: [1, 1, 1]
2025-01-09 21:10:21 - test_logger - INFO - V√©rification post-transaction pour test_user_31: queued=1, in_waiting=True
2025-01-09 21:10:21 - test_logger - INFO - Aucun historique de statuts trouv√© pour test_user_31
2025-01-09 21:10:21 - test_logger - INFO - Tentative d'offre de slot √† test_user_31
2025-01-09 21:10:21 - test_logger - INFO - Slot offert avec succ√®s √† test_user_31
2025-01-09 21:10:21 - test_logger - INFO - Tentative d'offre de slot √† test_user_31
2025-01-09 21:10:21 - test_logger - INFO - √âtat invalide pour test_user_31: d√©j√† en draft ou actif
2025-01-09 21:10:21 - test_logger - INFO - Connexion confirm√©e pour test_user_31
2025-01-09 21:10:21 - test_logger - INFO - Tentative d'ajout de l'utilisateur test_user_32
2025-01-09 21:10:21 - test_logger - INFO - Statut actuel: {'status': None}
2025-01-09 21:10:21 - test_logger - INFO - Tentative d'ajout √† la file d'attente pour test_user_32 avec statut None
2025-01-09 21:10:21 - test_logger - INFO - R√©sultats de la transaction Redis pour test_user_32: [1, 1, 1]
2025-01-09 21:10:21 - test_logger - INFO - V√©rification post-transaction pour test_user_32: queued=1, in_waiting=True
2025-01-09 21:10:21 - test_logger - INFO - Aucun historique de statuts trouv√© pour test_user_32
2025-01-09 21:10:21 - test_logger - INFO - Tentative d'offre de slot √† test_user_32
2025-01-09 21:10:21 - test_logger - INFO - Slot offert avec succ√®s √† test_user_32
2025-01-09 21:10:21 - test_logger - INFO - Tentative d'offre de slot √† test_user_32
2025-01-09 21:10:21 - test_logger - INFO - √âtat invalide pour test_user_32: d√©j√† en draft ou actif
2025-01-09 21:10:21 - test_logger - INFO - Connexion confirm√©e pour test_user_32
2025-01-09 21:10:21 - test_logger - INFO - Tentative d'ajout de l'utilisateur test_user_33
2025-01-09 21:10:21 - test_logger - INFO - Statut actuel: {'status': None}
2025-01-09 21:10:21 - test_logger - INFO - Tentative d'ajout √† la file d'attente pour test_user_33 avec statut None
2025-01-09 21:10:21 - test_logger - INFO - R√©sultats de la transaction Redis pour test_user_33: [1, 1, 1]
2025-01-09 21:10:21 - test_logger - INFO - V√©rification post-transaction pour test_user_33: queued=1, in_waiting=True
2025-01-09 21:10:21 - test_logger - INFO - Aucun historique de statuts trouv√© pour test_user_33
2025-01-09 21:10:21 - test_logger - INFO - Tentative d'offre de slot √† test_user_33
2025-01-09 21:10:21 - test_logger - INFO - Slot offert avec succ√®s √† test_user_33
2025-01-09 21:10:21 - test_logger - INFO - Tentative d'offre de slot √† test_user_33
2025-01-09 21:10:21 - test_logger - INFO - √âtat invalide pour test_user_33: d√©j√† en draft ou actif
2025-01-09 21:10:21 - test_logger - INFO - Connexion confirm√©e pour test_user_33
2025-01-09 21:10:21 - test_logger - INFO - Tentative d'ajout de l'utilisateur test_user_34
2025-01-09 21:10:21 - test_logger - INFO - Statut actuel: {'status': None}
2025-01-09 21:10:21 - test_logger - INFO - Tentative d'ajout √† la file d'attente pour test_user_34 avec statut None
2025-01-09 21:10:21 - test_logger - INFO - R√©sultats de la transaction Redis pour test_user_34: [1, 1, 1]
2025-01-09 21:10:21 - test_logger - INFO - V√©rification post-transaction pour test_user_34: queued=1, in_waiting=True
2025-01-09 21:10:21 - test_logger - INFO - Aucun historique de statuts trouv√© pour test_user_34
2025-01-09 21:10:21 - test_logger - INFO - Tentative d'offre de slot √† test_user_34
2025-01-09 21:10:21 - test_logger - INFO - Slot offert avec succ√®s √† test_user_34
2025-01-09 21:10:21 - test_logger - INFO - Tentative d'offre de slot √† test_user_34
2025-01-09 21:10:21 - test_logger - INFO - √âtat invalide pour test_user_34: d√©j√† en draft ou actif
2025-01-09 21:10:21 - test_logger - INFO - Connexion confirm√©e pour test_user_34
2025-01-09 21:10:21 - test_logger - INFO - Tentative d'ajout de l'utilisateur test_user_35
2025-01-09 21:10:21 - test_logger - INFO - Statut actuel: {'status': None}
2025-01-09 21:10:21 - test_logger - INFO - Tentative d'ajout √† la file d'attente pour test_user_35 avec statut None
2025-01-09 21:10:21 - test_logger - INFO - R√©sultats de la transaction Redis pour test_user_35: [1, 1, 1]
2025-01-09 21:10:21 - test_logger - INFO - V√©rification post-transaction pour test_user_35: queued=1, in_waiting=True
2025-01-09 21:10:21 - test_logger - INFO - Aucun historique de statuts trouv√© pour test_user_35
2025-01-09 21:10:21 - test_logger - INFO - Tentative d'offre de slot √† test_user_35
2025-01-09 21:10:21 - test_logger - INFO - Slot offert avec succ√®s √† test_user_35
2025-01-09 21:10:21 - test_logger - INFO - Tentative d'offre de slot √† test_user_35
2025-01-09 21:10:21 - test_logger - INFO - √âtat invalide pour test_user_35: d√©j√† en draft ou actif
2025-01-09 21:10:21 - test_logger - INFO - Connexion confirm√©e pour test_user_35
2025-01-09 21:10:21 - test_logger - INFO - Tentative d'ajout de l'utilisateur test_user_36
2025-01-09 21:10:21 - test_logger - INFO - Statut actuel: {'status': None}
2025-01-09 21:10:21 - test_logger - INFO - Tentative d'ajout √† la file d'attente pour test_user_36 avec statut None
2025-01-09 21:10:21 - test_logger - INFO - R√©sultats de la transaction Redis pour test_user_36: [1, 1, 1]
2025-01-09 21:10:21 - test_logger - INFO - V√©rification post-transaction pour test_user_36: queued=1, in_waiting=True
2025-01-09 21:10:21 - test_logger - INFO - Aucun historique de statuts trouv√© pour test_user_36
2025-01-09 21:10:21 - test_logger - INFO - Tentative d'offre de slot √† test_user_36
2025-01-09 21:10:21 - test_logger - INFO - Slot offert avec succ√®s √† test_user_36
2025-01-09 21:10:21 - test_logger - INFO - Tentative d'offre de slot √† test_user_36
2025-01-09 21:10:21 - test_logger - INFO - √âtat invalide pour test_user_36: d√©j√† en draft ou actif
2025-01-09 21:10:21 - test_logger - INFO - Connexion confirm√©e pour test_user_36
2025-01-09 21:10:21 - test_logger - INFO - Tentative d'ajout de l'utilisateur test_user_37
2025-01-09 21:10:21 - test_logger - INFO - Statut actuel: {'status': None}
2025-01-09 21:10:21 - test_logger - INFO - Tentative d'ajout √† la file d'attente pour test_user_37 avec statut None
2025-01-09 21:10:21 - test_logger - INFO - R√©sultats de la transaction Redis pour test_user_37: [1, 1, 1]
2025-01-09 21:10:21 - test_logger - INFO - V√©rification post-transaction pour test_user_37: queued=1, in_waiting=True
2025-01-09 21:10:21 - test_logger - INFO - Aucun historique de statuts trouv√© pour test_user_37
2025-01-09 21:10:21 - test_logger - INFO - Tentative d'offre de slot √† test_user_37
2025-01-09 21:10:21 - test_logger - INFO - Slot offert avec succ√®s √† test_user_37
2025-01-09 21:10:21 - test_logger - INFO - Tentative d'offre de slot √† test_user_37
2025-01-09 21:10:21 - test_logger - INFO - √âtat invalide pour test_user_37: d√©j√† en draft ou actif
2025-01-09 21:10:21 - test_logger - INFO - Connexion confirm√©e pour test_user_37
2025-01-09 21:10:21 - test_logger - INFO - Tentative d'ajout de l'utilisateur test_user_38
2025-01-09 21:10:21 - test_logger - INFO - Statut actuel: {'status': None}
2025-01-09 21:10:21 - test_logger - INFO - Tentative d'ajout √† la file d'attente pour test_user_38 avec statut None
2025-01-09 21:10:21 - test_logger - INFO - R√©sultats de la transaction Redis pour test_user_38: [1, 1, 1]
2025-01-09 21:10:21 - test_logger - INFO - V√©rification post-transaction pour test_user_38: queued=1, in_waiting=True
2025-01-09 21:10:21 - test_logger - INFO - Aucun historique de statuts trouv√© pour test_user_38
2025-01-09 21:10:21 - test_logger - INFO - Tentative d'offre de slot √† test_user_38
2025-01-09 21:10:21 - test_logger - INFO - Slot offert avec succ√®s √† test_user_38
2025-01-09 21:10:21 - test_logger - INFO - Tentative d'offre de slot √† test_user_38
2025-01-09 21:10:21 - test_logger - INFO - √âtat invalide pour test_user_38: d√©j√† en draft ou actif
2025-01-09 21:10:21 - test_logger - INFO - Connexion confirm√©e pour test_user_38
2025-01-09 21:10:21 - test_logger - INFO - Tentative d'ajout de l'utilisateur test_user_39
2025-01-09 21:10:21 - test_logger - INFO - Statut actuel: {'status': None}
2025-01-09 21:10:21 - test_logger - INFO - Tentative d'ajout √† la file d'attente pour test_user_39 avec statut None
2025-01-09 21:10:21 - test_logger - INFO - R√©sultats de la transaction Redis pour test_user_39: [1, 1, 1]
2025-01-09 21:10:21 - test_logger - INFO - V√©rification post-transaction pour test_user_39: queued=1, in_waiting=True
2025-01-09 21:10:21 - test_logger - INFO - Aucun historique de statuts trouv√© pour test_user_39
2025-01-09 21:10:21 - test_logger - INFO - Tentative d'offre de slot √† test_user_39
2025-01-09 21:10:21 - test_logger - INFO - Slot offert avec succ√®s √† test_user_39
2025-01-09 21:10:21 - test_logger - INFO - Tentative d'offre de slot √† test_user_39
2025-01-09 21:10:21 - test_logger - INFO - √âtat invalide pour test_user_39: d√©j√† en draft ou actif
2025-01-09 21:10:21 - test_logger - INFO - Connexion confirm√©e pour test_user_39
2025-01-09 21:10:21 - test_logger - INFO - Tentative d'ajout de l'utilisateur test_user_40
2025-01-09 21:10:21 - test_logger - INFO - Statut actuel: {'status': None}
2025-01-09 21:10:21 - test_logger - INFO - Tentative d'ajout √† la file d'attente pour test_user_40 avec statut None
2025-01-09 21:10:21 - test_logger - INFO - R√©sultats de la transaction Redis pour test_user_40: [1, 1, 1]
2025-01-09 21:10:21 - test_logger - INFO - V√©rification post-transaction pour test_user_40: queued=1, in_waiting=True
2025-01-09 21:10:21 - test_logger - INFO - Aucun historique de statuts trouv√© pour test_user_40
2025-01-09 21:10:21 - test_logger - INFO - Tentative d'offre de slot √† test_user_40
2025-01-09 21:10:21 - test_logger - INFO - Slot offert avec succ√®s √† test_user_40
2025-01-09 21:10:21 - test_logger - INFO - Tentative d'offre de slot √† test_user_40
2025-01-09 21:10:21 - test_logger - INFO - √âtat invalide pour test_user_40: d√©j√† en draft ou actif
2025-01-09 21:10:21 - test_logger - INFO - Connexion confirm√©e pour test_user_40
2025-01-09 21:10:21 - test_logger - INFO - Tentative d'ajout de l'utilisateur test_user_41
2025-01-09 21:10:21 - test_logger - INFO - Statut actuel: {'status': None}
2025-01-09 21:10:21 - test_logger - INFO - Tentative d'ajout √† la file d'attente pour test_user_41 avec statut None
2025-01-09 21:10:21 - test_logger - INFO - R√©sultats de la transaction Redis pour test_user_41: [1, 1, 1]
2025-01-09 21:10:21 - test_logger - INFO - V√©rification post-transaction pour test_user_41: queued=1, in_waiting=True
2025-01-09 21:10:21 - test_logger - INFO - Aucun historique de statuts trouv√© pour test_user_41
2025-01-09 21:10:21 - test_logger - INFO - Tentative d'offre de slot √† test_user_41
2025-01-09 21:10:21 - test_logger - INFO - Slot offert avec succ√®s √† test_user_41
2025-01-09 21:10:21 - test_logger - INFO - Tentative d'offre de slot √† test_user_41
2025-01-09 21:10:21 - test_logger - INFO - √âtat invalide pour test_user_41: d√©j√† en draft ou actif
2025-01-09 21:10:21 - test_logger - INFO - Connexion confirm√©e pour test_user_41
2025-01-09 21:10:21 - test_logger - INFO - Tentative d'ajout de l'utilisateur test_user_42
2025-01-09 21:10:21 - test_logger - INFO - Statut actuel: {'status': None}
2025-01-09 21:10:21 - test_logger - INFO - Tentative d'ajout √† la file d'attente pour test_user_42 avec statut None
2025-01-09 21:10:21 - test_logger - INFO - R√©sultats de la transaction Redis pour test_user_42: [1, 1, 1]
2025-01-09 21:10:21 - test_logger - INFO - V√©rification post-transaction pour test_user_42: queued=1, in_waiting=True
2025-01-09 21:10:21 - test_logger - INFO - Aucun historique de statuts trouv√© pour test_user_42
2025-01-09 21:10:21 - test_logger - INFO - Tentative d'offre de slot √† test_user_42
2025-01-09 21:10:21 - test_logger - INFO - Slot offert avec succ√®s √† test_user_42
2025-01-09 21:10:21 - test_logger - INFO - Tentative d'offre de slot √† test_user_42
2025-01-09 21:10:21 - test_logger - INFO - √âtat invalide pour test_user_42: d√©j√† en draft ou actif
2025-01-09 21:10:21 - test_logger - INFO - Connexion confirm√©e pour test_user_42
2025-01-09 21:10:21 - test_logger - INFO - Tentative d'ajout de l'utilisateur test_user_43
2025-01-09 21:10:21 - test_logger - INFO - Statut actuel: {'status': None}
2025-01-09 21:10:21 - test_logger - INFO - Tentative d'ajout √† la file d'attente pour test_user_43 avec statut None
2025-01-09 21:10:21 - test_logger - INFO - R√©sultats de la transaction Redis pour test_user_43: [1, 1, 1]
2025-01-09 21:10:21 - test_logger - INFO - V√©rification post-transaction pour test_user_43: queued=1, in_waiting=True
2025-01-09 21:10:21 - test_logger - INFO - Aucun historique de statuts trouv√© pour test_user_43
2025-01-09 21:10:21 - test_logger - INFO - Tentative d'offre de slot √† test_user_43
2025-01-09 21:10:21 - test_logger - INFO - Slot offert avec succ√®s √† test_user_43
2025-01-09 21:10:21 - test_logger - INFO - Tentative d'offre de slot √† test_user_43
2025-01-09 21:10:21 - test_logger - INFO - √âtat invalide pour test_user_43: d√©j√† en draft ou actif
2025-01-09 21:10:21 - test_logger - INFO - Connexion confirm√©e pour test_user_43
2025-01-09 21:10:21 - test_logger - INFO - Tentative d'ajout de l'utilisateur test_user_44
2025-01-09 21:10:21 - test_logger - INFO - Statut actuel: {'status': None}
2025-01-09 21:10:21 - test_logger - INFO - Tentative d'ajout √† la file d'attente pour test_user_44 avec statut None
2025-01-09 21:10:21 - test_logger - INFO - R√©sultats de la transaction Redis pour test_user_44: [1, 1, 1]
2025-01-09 21:10:21 - test_logger - INFO - V√©rification post-transaction pour test_user_44: queued=1, in_waiting=True
2025-01-09 21:10:21 - test_logger - INFO - Aucun historique de statuts trouv√© pour test_user_44
2025-01-09 21:10:21 - test_logger - INFO - Tentative d'offre de slot √† test_user_44
2025-01-09 21:10:21 - test_logger - INFO - Slot offert avec succ√®s √† test_user_44
2025-01-09 21:10:21 - test_logger - INFO - Tentative d'offre de slot √† test_user_44
2025-01-09 21:10:21 - test_logger - INFO - √âtat invalide pour test_user_44: d√©j√† en draft ou actif
2025-01-09 21:10:21 - test_logger - INFO - Connexion confirm√©e pour test_user_44
2025-01-09 21:10:21 - test_logger - INFO - Tentative d'ajout de l'utilisateur test_user_45
2025-01-09 21:10:21 - test_logger - INFO - Statut actuel: {'status': None}
2025-01-09 21:10:21 - test_logger - INFO - Tentative d'ajout √† la file d'attente pour test_user_45 avec statut None
2025-01-09 21:10:21 - test_logger - INFO - R√©sultats de la transaction Redis pour test_user_45: [1, 1, 1]
2025-01-09 21:10:21 - test_logger - INFO - V√©rification post-transaction pour test_user_45: queued=1, in_waiting=True
2025-01-09 21:10:21 - test_logger - INFO - Aucun historique de statuts trouv√© pour test_user_45
2025-01-09 21:10:21 - test_logger - INFO - Tentative d'offre de slot √† test_user_45
2025-01-09 21:10:21 - test_logger - INFO - Slot offert avec succ√®s √† test_user_45
2025-01-09 21:10:21 - test_logger - INFO - Tentative d'offre de slot √† test_user_45
2025-01-09 21:10:21 - test_logger - INFO - √âtat invalide pour test_user_45: d√©j√† en draft ou actif
2025-01-09 21:10:21 - test_logger - INFO - Connexion confirm√©e pour test_user_45
2025-01-09 21:10:21 - test_logger - INFO - Tentative d'ajout de l'utilisateur test_user_46
2025-01-09 21:10:21 - test_logger - INFO - Statut actuel: {'status': None}
2025-01-09 21:10:21 - test_logger - INFO - Tentative d'ajout √† la file d'attente pour test_user_46 avec statut None
2025-01-09 21:10:21 - test_logger - INFO - R√©sultats de la transaction Redis pour test_user_46: [1, 1, 1]
2025-01-09 21:10:21 - test_logger - INFO - V√©rification post-transaction pour test_user_46: queued=1, in_waiting=True
2025-01-09 21:10:21 - test_logger - INFO - Aucun historique de statuts trouv√© pour test_user_46
2025-01-09 21:10:21 - test_logger - INFO - Tentative d'offre de slot √† test_user_46
2025-01-09 21:10:21 - test_logger - INFO - Slot offert avec succ√®s √† test_user_46
2025-01-09 21:10:21 - test_logger - INFO - Tentative d'offre de slot √† test_user_46
2025-01-09 21:10:21 - test_logger - INFO - √âtat invalide pour test_user_46: d√©j√† en draft ou actif
2025-01-09 21:10:21 - test_logger - INFO - Connexion confirm√©e pour test_user_46
2025-01-09 21:10:21 - test_logger - INFO - Tentative d'ajout de l'utilisateur test_user_47
2025-01-09 21:10:21 - test_logger - INFO - Statut actuel: {'status': None}
2025-01-09 21:10:21 - test_logger - INFO - Tentative d'ajout √† la file d'attente pour test_user_47 avec statut None
2025-01-09 21:10:21 - test_logger - INFO - R√©sultats de la transaction Redis pour test_user_47: [1, 1, 1]
2025-01-09 21:10:21 - test_logger - INFO - V√©rification post-transaction pour test_user_47: queued=1, in_waiting=True
2025-01-09 21:10:21 - test_logger - INFO - Aucun historique de statuts trouv√© pour test_user_47
2025-01-09 21:10:21 - test_logger - INFO - Tentative d'offre de slot √† test_user_47
2025-01-09 21:10:21 - test_logger - INFO - Slot offert avec succ√®s √† test_user_47
2025-01-09 21:10:21 - test_logger - INFO - Tentative d'offre de slot √† test_user_47
2025-01-09 21:10:21 - test_logger - INFO - √âtat invalide pour test_user_47: d√©j√† en draft ou actif
2025-01-09 21:10:21 - test_logger - INFO - Connexion confirm√©e pour test_user_47
2025-01-09 21:10:21 - test_logger - INFO - Tentative d'ajout de l'utilisateur test_user_48
2025-01-09 21:10:21 - test_logger - INFO - Statut actuel: {'status': None}
2025-01-09 21:10:21 - test_logger - INFO - Tentative d'ajout √† la file d'attente pour test_user_48 avec statut None
2025-01-09 21:10:21 - test_logger - INFO - R√©sultats de la transaction Redis pour test_user_48: [1, 1, 1]
2025-01-09 21:10:21 - test_logger - INFO - V√©rification post-transaction pour test_user_48: queued=1, in_waiting=True
2025-01-09 21:10:21 - test_logger - INFO - Aucun historique de statuts trouv√© pour test_user_48
2025-01-09 21:10:21 - test_logger - INFO - Tentative d'offre de slot √† test_user_48
2025-01-09 21:10:21 - test_logger - INFO - Slot offert avec succ√®s √† test_user_48
2025-01-09 21:10:21 - test_logger - INFO - Tentative d'offre de slot √† test_user_48
2025-01-09 21:10:21 - test_logger - INFO - √âtat invalide pour test_user_48: d√©j√† en draft ou actif
2025-01-09 21:10:21 - test_logger - INFO - Connexion confirm√©e pour test_user_48
2025-01-09 21:10:21 - test_logger - INFO - Tentative d'ajout de l'utilisateur test_user_49
2025-01-09 21:10:21 - test_logger - INFO - Statut actuel: {'status': None}
2025-01-09 21:10:21 - test_logger - INFO - Tentative d'ajout √† la file d'attente pour test_user_49 avec statut None
2025-01-09 21:10:21 - test_logger - INFO - R√©sultats de la transaction Redis pour test_user_49: [1, 1, 1]
2025-01-09 21:10:21 - test_logger - INFO - V√©rification post-transaction pour test_user_49: queued=1, in_waiting=True
2025-01-09 21:10:21 - test_logger - INFO - Aucun historique de statuts trouv√© pour test_user_49
2025-01-09 21:10:21 - test_logger - INFO - Tentative d'offre de slot √† test_user_49
2025-01-09 21:10:21 - test_logger - INFO - Slot offert avec succ√®s √† test_user_49
2025-01-09 21:10:21 - test_logger - INFO - Tentative d'offre de slot √† test_user_49
2025-01-09 21:10:21 - test_logger - INFO - √âtat invalide pour test_user_49: d√©j√† en draft ou actif
2025-01-09 21:10:21 - test_logger - INFO - Connexion confirm√©e pour test_user_49
2025-01-09 21:10:21 - test_logger - INFO - Tentative d'ajout de l'utilisateur test_user_50
2025-01-09 21:10:21 - test_logger - INFO - Statut actuel: {'status': None}
2025-01-09 21:10:21 - test_logger - INFO - Tentative d'ajout √† la file d'attente pour test_user_50 avec statut None
2025-01-09 21:10:21 - test_logger - INFO - R√©sultats de la transaction Redis pour test_user_50: [1, 1, 1]
2025-01-09 21:10:21 - test_logger - INFO - V√©rification post-transaction pour test_user_50: queued=1, in_waiting=True
2025-01-09 21:10:21 - test_logger - INFO - Aucun historique de statuts trouv√© pour test_user_50
------------------------------ Captured log call -------------------------------
[32mINFO    [0m test_logger:queue_manager.py:194 Tentative d'ajout de l'utilisateur test_user_0
[32mINFO    [0m test_logger:queue_manager.py:198 Statut actuel: {'status': None}
[32mINFO    [0m test_logger:queue_manager.py:212 Tentative d'ajout √† la file d'attente pour test_user_0 avec statut None
[32mINFO    [0m test_logger:queue_manager.py:220 R√©sultats de la transaction Redis pour test_user_0: [1, 1, 1]
[32mINFO    [0m test_logger:queue_manager.py:227 V√©rification post-transaction pour test_user_0: queued=1, in_waiting=True
[32mINFO    [0m test_logger:queue_manager.py:547 Aucun historique de statuts trouv√© pour test_user_0
[32mINFO    [0m test_logger:queue_manager.py:337 Tentative d'offre de slot √† test_user_0
[32mINFO    [0m test_logger:queue_manager.py:390 Slot offert avec succ√®s √† test_user_0
[32mINFO    [0m test_logger:queue_manager.py:337 Tentative d'offre de slot √† test_user_0
[32mINFO    [0m test_logger:queue_manager.py:349 √âtat invalide pour test_user_0: d√©j√† en draft ou actif
[32mINFO    [0m test_logger:queue_manager.py:444 Connexion confirm√©e pour test_user_0
[32mINFO    [0m test_logger:queue_manager.py:194 Tentative d'ajout de l'utilisateur test_user_1
[32mINFO    [0m test_logger:queue_manager.py:198 Statut actuel: {'status': None}
[32mINFO    [0m test_logger:queue_manager.py:212 Tentative d'ajout √† la file d'attente pour test_user_1 avec statut None
[32mINFO    [0m test_logger:queue_manager.py:220 R√©sultats de la transaction Redis pour test_user_1: [1, 1, 1]
[32mINFO    [0m test_logger:queue_manager.py:227 V√©rification post-transaction pour test_user_1: queued=1, in_waiting=True
[32mINFO    [0m test_logger:queue_manager.py:547 Aucun historique de statuts trouv√© pour test_user_1
[32mINFO    [0m test_logger:queue_manager.py:337 Tentative d'offre de slot √† test_user_1
[32mINFO    [0m test_logger:queue_manager.py:390 Slot offert avec succ√®s √† test_user_1
[32mINFO    [0m test_logger:queue_manager.py:337 Tentative d'offre de slot √† test_user_1
[32mINFO    [0m test_logger:queue_manager.py:349 √âtat invalide pour test_user_1: d√©j√† en draft ou actif
[32mINFO    [0m test_logger:queue_manager.py:444 Connexion confirm√©e pour test_user_1
[32mINFO    [0m test_logger:queue_manager.py:194 Tentative d'ajout de l'utilisateur test_user_2
[32mINFO    [0m test_logger:queue_manager.py:198 Statut actuel: {'status': None}
[32mINFO    [0m test_logger:queue_manager.py:212 Tentative d'ajout √† la file d'attente pour test_user_2 avec statut None
[32mINFO    [0m test_logger:queue_manager.py:220 R√©sultats de la transaction Redis pour test_user_2: [1, 1, 1]
[32mINFO    [0m test_logger:queue_manager.py:227 V√©rification post-transaction pour test_user_2: queued=1, in_waiting=True
[32mINFO    [0m test_logger:queue_manager.py:547 Aucun historique de statuts trouv√© pour test_user_2
[32mINFO    [0m test_logger:queue_manager.py:337 Tentative d'offre de slot √† test_user_2
[32mINFO    [0m test_logger:queue_manager.py:390 Slot offert avec succ√®s √† test_user_2
[32mINFO    [0m test_logger:queue_manager.py:337 Tentative d'offre de slot √† test_user_2
[32mINFO    [0m test_logger:queue_manager.py:349 √âtat invalide pour test_user_2: d√©j√† en draft ou actif
[32mINFO    [0m test_logger:queue_manager.py:444 Connexion confirm√©e pour test_user_2
[32mINFO    [0m test_logger:queue_manager.py:194 Tentative d'ajout de l'utilisateur test_user_3
[32mINFO    [0m test_logger:queue_manager.py:198 Statut actuel: {'status': None}
[32mINFO    [0m test_logger:queue_manager.py:212 Tentative d'ajout √† la file d'attente pour test_user_3 avec statut None
[32mINFO    [0m test_logger:queue_manager.py:220 R√©sultats de la transaction Redis pour test_user_3: [1, 1, 1]
[32mINFO    [0m test_logger:queue_manager.py:227 V√©rification post-transaction pour test_user_3: queued=1, in_waiting=True
[32mINFO    [0m test_logger:queue_manager.py:547 Aucun historique de statuts trouv√© pour test_user_3
[32mINFO    [0m test_logger:queue_manager.py:337 Tentative d'offre de slot √† test_user_3
[32mINFO    [0m test_logger:queue_manager.py:390 Slot offert avec succ√®s √† test_user_3
[32mINFO    [0m test_logger:queue_manager.py:337 Tentative d'offre de slot √† test_user_3
[32mINFO    [0m test_logger:queue_manager.py:349 √âtat invalide pour test_user_3: d√©j√† en draft ou actif
[32mINFO    [0m test_logger:queue_manager.py:444 Connexion confirm√©e pour test_user_3
[32mINFO    [0m test_logger:queue_manager.py:194 Tentative d'ajout de l'utilisateur test_user_4
[32mINFO    [0m test_logger:queue_manager.py:198 Statut actuel: {'status': None}
[32mINFO    [0m test_logger:queue_manager.py:212 Tentative d'ajout √† la file d'attente pour test_user_4 avec statut None
[32mINFO    [0m test_logger:queue_manager.py:220 R√©sultats de la transaction Redis pour test_user_4: [1, 1, 1]
[32mINFO    [0m test_logger:queue_manager.py:227 V√©rification post-transaction pour test_user_4: queued=1, in_waiting=True
[32mINFO    [0m test_logger:queue_manager.py:547 Aucun historique de statuts trouv√© pour test_user_4
[32mINFO    [0m test_logger:queue_manager.py:337 Tentative d'offre de slot √† test_user_4
[32mINFO    [0m test_logger:queue_manager.py:390 Slot offert avec succ√®s √† test_user_4
[32mINFO    [0m test_logger:queue_manager.py:337 Tentative d'offre de slot √† test_user_4
[32mINFO    [0m test_logger:queue_manager.py:349 √âtat invalide pour test_user_4: d√©j√† en draft ou actif
[32mINFO    [0m test_logger:queue_manager.py:444 Connexion confirm√©e pour test_user_4
[32mINFO    [0m test_logger:queue_manager.py:194 Tentative d'ajout de l'utilisateur test_user_5
[32mINFO    [0m test_logger:queue_manager.py:198 Statut actuel: {'status': None}
[32mINFO    [0m test_logger:queue_manager.py:212 Tentative d'ajout √† la file d'attente pour test_user_5 avec statut None
[32mINFO    [0m test_logger:queue_manager.py:220 R√©sultats de la transaction Redis pour test_user_5: [1, 1, 1]
[32mINFO    [0m test_logger:queue_manager.py:227 V√©rification post-transaction pour test_user_5: queued=1, in_waiting=True
[32mINFO    [0m test_logger:queue_manager.py:547 Aucun historique de statuts trouv√© pour test_user_5
[32mINFO    [0m test_logger:queue_manager.py:337 Tentative d'offre de slot √† test_user_5
[32mINFO    [0m test_logger:queue_manager.py:390 Slot offert avec succ√®s √† test_user_5
[32mINFO    [0m test_logger:queue_manager.py:337 Tentative d'offre de slot √† test_user_5
[32mINFO    [0m test_logger:queue_manager.py:349 √âtat invalide pour test_user_5: d√©j√† en draft ou actif
[32mINFO    [0m test_logger:queue_manager.py:444 Connexion confirm√©e pour test_user_5
[32mINFO    [0m test_logger:queue_manager.py:194 Tentative d'ajout de l'utilisateur test_user_6
[32mINFO    [0m test_logger:queue_manager.py:198 Statut actuel: {'status': None}
[32mINFO    [0m test_logger:queue_manager.py:212 Tentative d'ajout √† la file d'attente pour test_user_6 avec statut None
[32mINFO    [0m test_logger:queue_manager.py:220 R√©sultats de la transaction Redis pour test_user_6: [1, 1, 1]
[32mINFO    [0m test_logger:queue_manager.py:227 V√©rification post-transaction pour test_user_6: queued=1, in_waiting=True
[32mINFO    [0m test_logger:queue_manager.py:547 Aucun historique de statuts trouv√© pour test_user_6
[32mINFO    [0m test_logger:queue_manager.py:337 Tentative d'offre de slot √† test_user_6
[32mINFO    [0m test_logger:queue_manager.py:390 Slot offert avec succ√®s √† test_user_6
[32mINFO    [0m test_logger:queue_manager.py:337 Tentative d'offre de slot √† test_user_6
[32mINFO    [0m test_logger:queue_manager.py:349 √âtat invalide pour test_user_6: d√©j√† en draft ou actif
[32mINFO    [0m test_logger:queue_manager.py:444 Connexion confirm√©e pour test_user_6
[32mINFO    [0m test_logger:queue_manager.py:194 Tentative d'ajout de l'utilisateur test_user_7
[32mINFO    [0m test_logger:queue_manager.py:198 Statut actuel: {'status': None}
[32mINFO    [0m test_logger:queue_manager.py:212 Tentative d'ajout √† la file d'attente pour test_user_7 avec statut None
[32mINFO    [0m test_logger:queue_manager.py:220 R√©sultats de la transaction Redis pour test_user_7: [1, 1, 1]
[32mINFO    [0m test_logger:queue_manager.py:227 V√©rification post-transaction pour test_user_7: queued=1, in_waiting=True
[32mINFO    [0m test_logger:queue_manager.py:547 Aucun historique de statuts trouv√© pour test_user_7
[32mINFO    [0m test_logger:queue_manager.py:337 Tentative d'offre de slot √† test_user_7
[32mINFO    [0m test_logger:queue_manager.py:390 Slot offert avec succ√®s √† test_user_7
[32mINFO    [0m test_logger:queue_manager.py:337 Tentative d'offre de slot √† test_user_7
[32mINFO    [0m test_logger:queue_manager.py:349 √âtat invalide pour test_user_7: d√©j√† en draft ou actif
[32mINFO    [0m test_logger:queue_manager.py:444 Connexion confirm√©e pour test_user_7
[32mINFO    [0m test_logger:queue_manager.py:194 Tentative d'ajout de l'utilisateur test_user_8
[32mINFO    [0m test_logger:queue_manager.py:198 Statut actuel: {'status': None}
[32mINFO    [0m test_logger:queue_manager.py:212 Tentative d'ajout √† la file d'attente pour test_user_8 avec statut None
[32mINFO    [0m test_logger:queue_manager.py:220 R√©sultats de la transaction Redis pour test_user_8: [1, 1, 1]
[32mINFO    [0m test_logger:queue_manager.py:227 V√©rification post-transaction pour test_user_8: queued=1, in_waiting=True
[32mINFO    [0m test_logger:queue_manager.py:547 Aucun historique de statuts trouv√© pour test_user_8
[32mINFO    [0m test_logger:queue_manager.py:337 Tentative d'offre de slot √† test_user_8
[32mINFO    [0m test_logger:queue_manager.py:390 Slot offert avec succ√®s √† test_user_8
[32mINFO    [0m test_logger:queue_manager.py:337 Tentative d'offre de slot √† test_user_8
[32mINFO    [0m test_logger:queue_manager.py:349 √âtat invalide pour test_user_8: d√©j√† en draft ou actif
[32mINFO    [0m test_logger:queue_manager.py:444 Connexion confirm√©e pour test_user_8
[32mINFO    [0m test_logger:queue_manager.py:194 Tentative d'ajout de l'utilisateur test_user_9
[32mINFO    [0m test_logger:queue_manager.py:198 Statut actuel: {'status': None}
[32mINFO    [0m test_logger:queue_manager.py:212 Tentative d'ajout √† la file d'attente pour test_user_9 avec statut None
[32mINFO    [0m test_logger:queue_manager.py:220 R√©sultats de la transaction Redis pour test_user_9: [1, 1, 1]
[32mINFO    [0m test_logger:queue_manager.py:227 V√©rification post-transaction pour test_user_9: queued=1, in_waiting=True
[32mINFO    [0m test_logger:queue_manager.py:547 Aucun historique de statuts trouv√© pour test_user_9
[32mINFO    [0m test_logger:queue_manager.py:337 Tentative d'offre de slot √† test_user_9
[32mINFO    [0m test_logger:queue_manager.py:390 Slot offert avec succ√®s √† test_user_9
[32mINFO    [0m test_logger:queue_manager.py:337 Tentative d'offre de slot √† test_user_9
[32mINFO    [0m test_logger:queue_manager.py:349 √âtat invalide pour test_user_9: d√©j√† en draft ou actif
[32mINFO    [0m test_logger:queue_manager.py:444 Connexion confirm√©e pour test_user_9
[32mINFO    [0m test_logger:queue_manager.py:194 Tentative d'ajout de l'utilisateur test_user_10
[32mINFO    [0m test_logger:queue_manager.py:198 Statut actuel: {'status': None}
[32mINFO    [0m test_logger:queue_manager.py:212 Tentative d'ajout √† la file d'attente pour test_user_10 avec statut None
[32mINFO    [0m test_logger:queue_manager.py:220 R√©sultats de la transaction Redis pour test_user_10: [1, 1, 1]
[32mINFO    [0m test_logger:queue_manager.py:227 V√©rification post-transaction pour test_user_10: queued=1, in_waiting=True
[32mINFO    [0m test_logger:queue_manager.py:547 Aucun historique de statuts trouv√© pour test_user_10
[32mINFO    [0m test_logger:queue_manager.py:337 Tentative d'offre de slot √† test_user_10
[32mINFO    [0m test_logger:queue_manager.py:390 Slot offert avec succ√®s √† test_user_10
[32mINFO    [0m test_logger:queue_manager.py:337 Tentative d'offre de slot √† test_user_10
[32mINFO    [0m test_logger:queue_manager.py:349 √âtat invalide pour test_user_10: d√©j√† en draft ou actif
[32mINFO    [0m test_logger:queue_manager.py:444 Connexion confirm√©e pour test_user_10
[32mINFO    [0m test_logger:queue_manager.py:194 Tentative d'ajout de l'utilisateur test_user_11
[32mINFO    [0m test_logger:queue_manager.py:198 Statut actuel: {'status': None}
[32mINFO    [0m test_logger:queue_manager.py:212 Tentative d'ajout √† la file d'attente pour test_user_11 avec statut None
[32mINFO    [0m test_logger:queue_manager.py:220 R√©sultats de la transaction Redis pour test_user_11: [1, 1, 1]
[32mINFO    [0m test_logger:queue_manager.py:227 V√©rification post-transaction pour test_user_11: queued=1, in_waiting=True
[32mINFO    [0m test_logger:queue_manager.py:547 Aucun historique de statuts trouv√© pour test_user_11
[32mINFO    [0m test_logger:queue_manager.py:337 Tentative d'offre de slot √† test_user_11
[32mINFO    [0m test_logger:queue_manager.py:390 Slot offert avec succ√®s √† test_user_11
[32mINFO    [0m test_logger:queue_manager.py:337 Tentative d'offre de slot √† test_user_11
[32mINFO    [0m test_logger:queue_manager.py:349 √âtat invalide pour test_user_11: d√©j√† en draft ou actif
[32mINFO    [0m test_logger:queue_manager.py:444 Connexion confirm√©e pour test_user_11
[32mINFO    [0m test_logger:queue_manager.py:194 Tentative d'ajout de l'utilisateur test_user_12
[32mINFO    [0m test_logger:queue_manager.py:198 Statut actuel: {'status': None}
[32mINFO    [0m test_logger:queue_manager.py:212 Tentative d'ajout √† la file d'attente pour test_user_12 avec statut None
[32mINFO    [0m test_logger:queue_manager.py:220 R√©sultats de la transaction Redis pour test_user_12: [1, 1, 1]
[32mINFO    [0m test_logger:queue_manager.py:227 V√©rification post-transaction pour test_user_12: queued=1, in_waiting=True
[32mINFO    [0m test_logger:queue_manager.py:547 Aucun historique de statuts trouv√© pour test_user_12
[32mINFO    [0m test_logger:queue_manager.py:337 Tentative d'offre de slot √† test_user_12
[32mINFO    [0m test_logger:queue_manager.py:390 Slot offert avec succ√®s √† test_user_12
[32mINFO    [0m test_logger:queue_manager.py:337 Tentative d'offre de slot √† test_user_12
[32mINFO    [0m test_logger:queue_manager.py:349 √âtat invalide pour test_user_12: d√©j√† en draft ou actif
[32mINFO    [0m test_logger:queue_manager.py:444 Connexion confirm√©e pour test_user_12
[32mINFO    [0m test_logger:queue_manager.py:194 Tentative d'ajout de l'utilisateur test_user_13
[32mINFO    [0m test_logger:queue_manager.py:198 Statut actuel: {'status': None}
[32mINFO    [0m test_logger:queue_manager.py:212 Tentative d'ajout √† la file d'attente pour test_user_13 avec statut None
[32mINFO    [0m test_logger:queue_manager.py:220 R√©sultats de la transaction Redis pour test_user_13: [1, 1, 1]
[32mINFO    [0m test_logger:queue_manager.py:227 V√©rification post-transaction pour test_user_13: queued=1, in_waiting=True
[32mINFO    [0m test_logger:queue_manager.py:547 Aucun historique de statuts trouv√© pour test_user_13
[32mINFO    [0m test_logger:queue_manager.py:337 Tentative d'offre de slot √† test_user_13
[32mINFO    [0m test_logger:queue_manager.py:390 Slot offert avec succ√®s √† test_user_13
[32mINFO    [0m test_logger:queue_manager.py:337 Tentative d'offre de slot √† test_user_13
[32mINFO    [0m test_logger:queue_manager.py:349 √âtat invalide pour test_user_13: d√©j√† en draft ou actif
[32mINFO    [0m test_logger:queue_manager.py:444 Connexion confirm√©e pour test_user_13
[32mINFO    [0m test_logger:queue_manager.py:194 Tentative d'ajout de l'utilisateur test_user_14
[32mINFO    [0m test_logger:queue_manager.py:198 Statut actuel: {'status': None}
[32mINFO    [0m test_logger:queue_manager.py:212 Tentative d'ajout √† la file d'attente pour test_user_14 avec statut None
[32mINFO    [0m test_logger:queue_manager.py:220 R√©sultats de la transaction Redis pour test_user_14: [1, 1, 1]
[32mINFO    [0m test_logger:queue_manager.py:227 V√©rification post-transaction pour test_user_14: queued=1, in_waiting=True
[32mINFO    [0m test_logger:queue_manager.py:547 Aucun historique de statuts trouv√© pour test_user_14
[32mINFO    [0m test_logger:queue_manager.py:337 Tentative d'offre de slot √† test_user_14
[32mINFO    [0m test_logger:queue_manager.py:390 Slot offert avec succ√®s √† test_user_14
[32mINFO    [0m test_logger:queue_manager.py:337 Tentative d'offre de slot √† test_user_14
[32mINFO    [0m test_logger:queue_manager.py:349 √âtat invalide pour test_user_14: d√©j√† en draft ou actif
[32mINFO    [0m test_logger:queue_manager.py:444 Connexion confirm√©e pour test_user_14
[32mINFO    [0m test_logger:queue_manager.py:194 Tentative d'ajout de l'utilisateur test_user_15
[32mINFO    [0m test_logger:queue_manager.py:198 Statut actuel: {'status': None}
[32mINFO    [0m test_logger:queue_manager.py:212 Tentative d'ajout √† la file d'attente pour test_user_15 avec statut None
[32mINFO    [0m test_logger:queue_manager.py:220 R√©sultats de la transaction Redis pour test_user_15: [1, 1, 1]
[32mINFO    [0m test_logger:queue_manager.py:227 V√©rification post-transaction pour test_user_15: queued=1, in_waiting=True
[32mINFO    [0m test_logger:queue_manager.py:547 Aucun historique de statuts trouv√© pour test_user_15
[32mINFO    [0m test_logger:queue_manager.py:337 Tentative d'offre de slot √† test_user_15
[32mINFO    [0m test_logger:queue_manager.py:390 Slot offert avec succ√®s √† test_user_15
[32mINFO    [0m test_logger:queue_manager.py:337 Tentative d'offre de slot √† test_user_15
[32mINFO    [0m test_logger:queue_manager.py:349 √âtat invalide pour test_user_15: d√©j√† en draft ou actif
[32mINFO    [0m test_logger:queue_manager.py:444 Connexion confirm√©e pour test_user_15
[32mINFO    [0m test_logger:queue_manager.py:194 Tentative d'ajout de l'utilisateur test_user_16
[32mINFO    [0m test_logger:queue_manager.py:198 Statut actuel: {'status': None}
[32mINFO    [0m test_logger:queue_manager.py:212 Tentative d'ajout √† la file d'attente pour test_user_16 avec statut None
[32mINFO    [0m test_logger:queue_manager.py:220 R√©sultats de la transaction Redis pour test_user_16: [1, 1, 1]
[32mINFO    [0m test_logger:queue_manager.py:227 V√©rification post-transaction pour test_user_16: queued=1, in_waiting=True
[32mINFO    [0m test_logger:queue_manager.py:547 Aucun historique de statuts trouv√© pour test_user_16
[32mINFO    [0m test_logger:queue_manager.py:337 Tentative d'offre de slot √† test_user_16
[32mINFO    [0m test_logger:queue_manager.py:390 Slot offert avec succ√®s √† test_user_16
[32mINFO    [0m test_logger:queue_manager.py:337 Tentative d'offre de slot √† test_user_16
[32mINFO    [0m test_logger:queue_manager.py:349 √âtat invalide pour test_user_16: d√©j√† en draft ou actif
[32mINFO    [0m test_logger:queue_manager.py:444 Connexion confirm√©e pour test_user_16
[32mINFO    [0m test_logger:queue_manager.py:194 Tentative d'ajout de l'utilisateur test_user_17
[32mINFO    [0m test_logger:queue_manager.py:198 Statut actuel: {'status': None}
[32mINFO    [0m test_logger:queue_manager.py:212 Tentative d'ajout √† la file d'attente pour test_user_17 avec statut None
[32mINFO    [0m test_logger:queue_manager.py:220 R√©sultats de la transaction Redis pour test_user_17: [1, 1, 1]
[32mINFO    [0m test_logger:queue_manager.py:227 V√©rification post-transaction pour test_user_17: queued=1, in_waiting=True
[32mINFO    [0m test_logger:queue_manager.py:547 Aucun historique de statuts trouv√© pour test_user_17
[32mINFO    [0m test_logger:queue_manager.py:337 Tentative d'offre de slot √† test_user_17
[32mINFO    [0m test_logger:queue_manager.py:390 Slot offert avec succ√®s √† test_user_17
[32mINFO    [0m test_logger:queue_manager.py:337 Tentative d'offre de slot √† test_user_17
[32mINFO    [0m test_logger:queue_manager.py:349 √âtat invalide pour test_user_17: d√©j√† en draft ou actif
[32mINFO    [0m test_logger:queue_manager.py:444 Connexion confirm√©e pour test_user_17
[32mINFO    [0m test_logger:queue_manager.py:194 Tentative d'ajout de l'utilisateur test_user_18
[32mINFO    [0m test_logger:queue_manager.py:198 Statut actuel: {'status': None}
[32mINFO    [0m test_logger:queue_manager.py:212 Tentative d'ajout √† la file d'attente pour test_user_18 avec statut None
[32mINFO    [0m test_logger:queue_manager.py:220 R√©sultats de la transaction Redis pour test_user_18: [1, 1, 1]
[32mINFO    [0m test_logger:queue_manager.py:227 V√©rification post-transaction pour test_user_18: queued=1, in_waiting=True
[32mINFO    [0m test_logger:queue_manager.py:547 Aucun historique de statuts trouv√© pour test_user_18
[32mINFO    [0m test_logger:queue_manager.py:337 Tentative d'offre de slot √† test_user_18
[32mINFO    [0m test_logger:queue_manager.py:390 Slot offert avec succ√®s √† test_user_18
[32mINFO    [0m test_logger:queue_manager.py:337 Tentative d'offre de slot √† test_user_18
[32mINFO    [0m test_logger:queue_manager.py:349 √âtat invalide pour test_user_18: d√©j√† en draft ou actif
[32mINFO    [0m test_logger:queue_manager.py:444 Connexion confirm√©e pour test_user_18
[32mINFO    [0m test_logger:queue_manager.py:194 Tentative d'ajout de l'utilisateur test_user_19
[32mINFO    [0m test_logger:queue_manager.py:198 Statut actuel: {'status': None}
[32mINFO    [0m test_logger:queue_manager.py:212 Tentative d'ajout √† la file d'attente pour test_user_19 avec statut None
[32mINFO    [0m test_logger:queue_manager.py:220 R√©sultats de la transaction Redis pour test_user_19: [1, 1, 1]
[32mINFO    [0m test_logger:queue_manager.py:227 V√©rification post-transaction pour test_user_19: queued=1, in_waiting=True
[32mINFO    [0m test_logger:queue_manager.py:547 Aucun historique de statuts trouv√© pour test_user_19
[32mINFO    [0m test_logger:queue_manager.py:337 Tentative d'offre de slot √† test_user_19
[32mINFO    [0m test_logger:queue_manager.py:390 Slot offert avec succ√®s √† test_user_19
[32mINFO    [0m test_logger:queue_manager.py:337 Tentative d'offre de slot √† test_user_19
[32mINFO    [0m test_logger:queue_manager.py:349 √âtat invalide pour test_user_19: d√©j√† en draft ou actif
[32mINFO    [0m test_logger:queue_manager.py:444 Connexion confirm√©e pour test_user_19
[32mINFO    [0m test_logger:queue_manager.py:194 Tentative d'ajout de l'utilisateur test_user_20
[32mINFO    [0m test_logger:queue_manager.py:198 Statut actuel: {'status': None}
[32mINFO    [0m test_logger:queue_manager.py:212 Tentative d'ajout √† la file d'attente pour test_user_20 avec statut None
[32mINFO    [0m test_logger:queue_manager.py:220 R√©sultats de la transaction Redis pour test_user_20: [1, 1, 1]
[32mINFO    [0m test_logger:queue_manager.py:227 V√©rification post-transaction pour test_user_20: queued=1, in_waiting=True
[32mINFO    [0m test_logger:queue_manager.py:547 Aucun historique de statuts trouv√© pour test_user_20
[32mINFO    [0m test_logger:queue_manager.py:337 Tentative d'offre de slot √† test_user_20
[32mINFO    [0m test_logger:queue_manager.py:390 Slot offert avec succ√®s √† test_user_20
[32mINFO    [0m test_logger:queue_manager.py:337 Tentative d'offre de slot √† test_user_20
[32mINFO    [0m test_logger:queue_manager.py:349 √âtat invalide pour test_user_20: d√©j√† en draft ou actif
[32mINFO    [0m test_logger:queue_manager.py:444 Connexion confirm√©e pour test_user_20
[32mINFO    [0m test_logger:queue_manager.py:194 Tentative d'ajout de l'utilisateur test_user_21
[32mINFO    [0m test_logger:queue_manager.py:198 Statut actuel: {'status': None}
[32mINFO    [0m test_logger:queue_manager.py:212 Tentative d'ajout √† la file d'attente pour test_user_21 avec statut None
[32mINFO    [0m test_logger:queue_manager.py:220 R√©sultats de la transaction Redis pour test_user_21: [1, 1, 1]
[32mINFO    [0m test_logger:queue_manager.py:227 V√©rification post-transaction pour test_user_21: queued=1, in_waiting=True
[32mINFO    [0m test_logger:queue_manager.py:547 Aucun historique de statuts trouv√© pour test_user_21
[32mINFO    [0m test_logger:queue_manager.py:337 Tentative d'offre de slot √† test_user_21
[32mINFO    [0m test_logger:queue_manager.py:390 Slot offert avec succ√®s √† test_user_21
[32mINFO    [0m test_logger:queue_manager.py:337 Tentative d'offre de slot √† test_user_21
[32mINFO    [0m test_logger:queue_manager.py:349 √âtat invalide pour test_user_21: d√©j√† en draft ou actif
[32mINFO    [0m test_logger:queue_manager.py:444 Connexion confirm√©e pour test_user_21
[32mINFO    [0m test_logger:queue_manager.py:194 Tentative d'ajout de l'utilisateur test_user_22
[32mINFO    [0m test_logger:queue_manager.py:198 Statut actuel: {'status': None}
[32mINFO    [0m test_logger:queue_manager.py:212 Tentative d'ajout √† la file d'attente pour test_user_22 avec statut None
[32mINFO    [0m test_logger:queue_manager.py:220 R√©sultats de la transaction Redis pour test_user_22: [1, 1, 1]
[32mINFO    [0m test_logger:queue_manager.py:227 V√©rification post-transaction pour test_user_22: queued=1, in_waiting=True
[32mINFO    [0m test_logger:queue_manager.py:547 Aucun historique de statuts trouv√© pour test_user_22
[32mINFO    [0m test_logger:queue_manager.py:337 Tentative d'offre de slot √† test_user_22
[32mINFO    [0m test_logger:queue_manager.py:390 Slot offert avec succ√®s √† test_user_22
[32mINFO    [0m test_logger:queue_manager.py:337 Tentative d'offre de slot √† test_user_22
[32mINFO    [0m test_logger:queue_manager.py:349 √âtat invalide pour test_user_22: d√©j√† en draft ou actif
[32mINFO    [0m test_logger:queue_manager.py:444 Connexion confirm√©e pour test_user_22
[32mINFO    [0m test_logger:queue_manager.py:194 Tentative d'ajout de l'utilisateur test_user_23
[32mINFO    [0m test_logger:queue_manager.py:198 Statut actuel: {'status': None}
[32mINFO    [0m test_logger:queue_manager.py:212 Tentative d'ajout √† la file d'attente pour test_user_23 avec statut None
[32mINFO    [0m test_logger:queue_manager.py:220 R√©sultats de la transaction Redis pour test_user_23: [1, 1, 1]
[32mINFO    [0m test_logger:queue_manager.py:227 V√©rification post-transaction pour test_user_23: queued=1, in_waiting=True
[32mINFO    [0m test_logger:queue_manager.py:547 Aucun historique de statuts trouv√© pour test_user_23
[32mINFO    [0m test_logger:queue_manager.py:337 Tentative d'offre de slot √† test_user_23
[32mINFO    [0m test_logger:queue_manager.py:390 Slot offert avec succ√®s √† test_user_23
[32mINFO    [0m test_logger:queue_manager.py:337 Tentative d'offre de slot √† test_user_23
[32mINFO    [0m test_logger:queue_manager.py:349 √âtat invalide pour test_user_23: d√©j√† en draft ou actif
[32mINFO    [0m test_logger:queue_manager.py:444 Connexion confirm√©e pour test_user_23
[32mINFO    [0m test_logger:queue_manager.py:194 Tentative d'ajout de l'utilisateur test_user_24
[32mINFO    [0m test_logger:queue_manager.py:198 Statut actuel: {'status': None}
[32mINFO    [0m test_logger:queue_manager.py:212 Tentative d'ajout √† la file d'attente pour test_user_24 avec statut None
[32mINFO    [0m test_logger:queue_manager.py:220 R√©sultats de la transaction Redis pour test_user_24: [1, 1, 1]
[32mINFO    [0m test_logger:queue_manager.py:227 V√©rification post-transaction pour test_user_24: queued=1, in_waiting=True
[32mINFO    [0m test_logger:queue_manager.py:547 Aucun historique de statuts trouv√© pour test_user_24
[32mINFO    [0m test_logger:queue_manager.py:337 Tentative d'offre de slot √† test_user_24
[32mINFO    [0m test_logger:queue_manager.py:390 Slot offert avec succ√®s √† test_user_24
[32mINFO    [0m test_logger:queue_manager.py:337 Tentative d'offre de slot √† test_user_24
[32mINFO    [0m test_logger:queue_manager.py:349 √âtat invalide pour test_user_24: d√©j√† en draft ou actif
[32mINFO    [0m test_logger:queue_manager.py:444 Connexion confirm√©e pour test_user_24
[32mINFO    [0m test_logger:queue_manager.py:194 Tentative d'ajout de l'utilisateur test_user_25
[32mINFO    [0m test_logger:queue_manager.py:198 Statut actuel: {'status': None}
[32mINFO    [0m test_logger:queue_manager.py:212 Tentative d'ajout √† la file d'attente pour test_user_25 avec statut None
[32mINFO    [0m test_logger:queue_manager.py:220 R√©sultats de la transaction Redis pour test_user_25: [1, 1, 1]
[32mINFO    [0m test_logger:queue_manager.py:227 V√©rification post-transaction pour test_user_25: queued=1, in_waiting=True
[32mINFO    [0m test_logger:queue_manager.py:547 Aucun historique de statuts trouv√© pour test_user_25
[32mINFO    [0m test_logger:queue_manager.py:337 Tentative d'offre de slot √† test_user_25
[32mINFO    [0m test_logger:queue_manager.py:390 Slot offert avec succ√®s √† test_user_25
[32mINFO    [0m test_logger:queue_manager.py:337 Tentative d'offre de slot √† test_user_25
[32mINFO    [0m test_logger:queue_manager.py:349 √âtat invalide pour test_user_25: d√©j√† en draft ou actif
[32mINFO    [0m test_logger:queue_manager.py:444 Connexion confirm√©e pour test_user_25
[32mINFO    [0m test_logger:queue_manager.py:194 Tentative d'ajout de l'utilisateur test_user_26
[32mINFO    [0m test_logger:queue_manager.py:198 Statut actuel: {'status': None}
[32mINFO    [0m test_logger:queue_manager.py:212 Tentative d'ajout √† la file d'attente pour test_user_26 avec statut None
[32mINFO    [0m test_logger:queue_manager.py:220 R√©sultats de la transaction Redis pour test_user_26: [1, 1, 1]
[32mINFO    [0m test_logger:queue_manager.py:227 V√©rification post-transaction pour test_user_26: queued=1, in_waiting=True
[32mINFO    [0m test_logger:queue_manager.py:547 Aucun historique de statuts trouv√© pour test_user_26
[32mINFO    [0m test_logger:queue_manager.py:337 Tentative d'offre de slot √† test_user_26
[32mINFO    [0m test_logger:queue_manager.py:390 Slot offert avec succ√®s √† test_user_26
[32mINFO    [0m test_logger:queue_manager.py:337 Tentative d'offre de slot √† test_user_26
[32mINFO    [0m test_logger:queue_manager.py:349 √âtat invalide pour test_user_26: d√©j√† en draft ou actif
[32mINFO    [0m test_logger:queue_manager.py:444 Connexion confirm√©e pour test_user_26
[32mINFO    [0m test_logger:queue_manager.py:194 Tentative d'ajout de l'utilisateur test_user_27
[32mINFO    [0m test_logger:queue_manager.py:198 Statut actuel: {'status': None}
[32mINFO    [0m test_logger:queue_manager.py:212 Tentative d'ajout √† la file d'attente pour test_user_27 avec statut None
[32mINFO    [0m test_logger:queue_manager.py:220 R√©sultats de la transaction Redis pour test_user_27: [1, 1, 1]
[32mINFO    [0m test_logger:queue_manager.py:227 V√©rification post-transaction pour test_user_27: queued=1, in_waiting=True
[32mINFO    [0m test_logger:queue_manager.py:547 Aucun historique de statuts trouv√© pour test_user_27
[32mINFO    [0m test_logger:queue_manager.py:337 Tentative d'offre de slot √† test_user_27
[32mINFO    [0m test_logger:queue_manager.py:390 Slot offert avec succ√®s √† test_user_27
[32mINFO    [0m test_logger:queue_manager.py:337 Tentative d'offre de slot √† test_user_27
[32mINFO    [0m test_logger:queue_manager.py:349 √âtat invalide pour test_user_27: d√©j√† en draft ou actif
[32mINFO    [0m test_logger:queue_manager.py:444 Connexion confirm√©e pour test_user_27
[32mINFO    [0m test_logger:queue_manager.py:194 Tentative d'ajout de l'utilisateur test_user_28
[32mINFO    [0m test_logger:queue_manager.py:198 Statut actuel: {'status': None}
[32mINFO    [0m test_logger:queue_manager.py:212 Tentative d'ajout √† la file d'attente pour test_user_28 avec statut None
[32mINFO    [0m test_logger:queue_manager.py:220 R√©sultats de la transaction Redis pour test_user_28: [1, 1, 1]
[32mINFO    [0m test_logger:queue_manager.py:227 V√©rification post-transaction pour test_user_28: queued=1, in_waiting=True
[32mINFO    [0m test_logger:queue_manager.py:547 Aucun historique de statuts trouv√© pour test_user_28
[32mINFO    [0m test_logger:queue_manager.py:337 Tentative d'offre de slot √† test_user_28
[32mINFO    [0m test_logger:queue_manager.py:349 √âtat invalide pour test_user_28: d√©j√† en draft ou actif
[32mINFO    [0m test_logger:queue_manager.py:444 Connexion confirm√©e pour test_user_28
[32mINFO    [0m test_logger:queue_manager.py:194 Tentative d'ajout de l'utilisateur test_user_29
[32mINFO    [0m test_logger:queue_manager.py:198 Statut actuel: {'status': None}
[32mINFO    [0m test_logger:queue_manager.py:212 Tentative d'ajout √† la file d'attente pour test_user_29 avec statut None
[32mINFO    [0m test_logger:queue_manager.py:220 R√©sultats de la transaction Redis pour test_user_29: [1, 1, 1]
[32mINFO    [0m test_logger:queue_manager.py:227 V√©rification post-transaction pour test_user_29: queued=1, in_waiting=True
[32mINFO    [0m test_logger:queue_manager.py:547 Aucun historique de statuts trouv√© pour test_user_29
[32mINFO    [0m test_logger:queue_manager.py:337 Tentative d'offre de slot √† test_user_29
[32mINFO    [0m test_logger:queue_manager.py:390 Slot offert avec succ√®s √† test_user_29
[32mINFO    [0m test_logger:queue_manager.py:337 Tentative d'offre de slot √† test_user_29
[32mINFO    [0m test_logger:queue_manager.py:349 √âtat invalide pour test_user_29: d√©j√† en draft ou actif
[32mINFO    [0m test_logger:queue_manager.py:444 Connexion confirm√©e pour test_user_29
[32mINFO    [0m test_logger:queue_manager.py:194 Tentative d'ajout de l'utilisateur test_user_30
[32mINFO    [0m test_logger:queue_manager.py:198 Statut actuel: {'status': None}
[32mINFO    [0m test_logger:queue_manager.py:212 Tentative d'ajout √† la file d'attente pour test_user_30 avec statut None
[32mINFO    [0m test_logger:queue_manager.py:220 R√©sultats de la transaction Redis pour test_user_30: [1, 1, 1]
[32mINFO    [0m test_logger:queue_manager.py:227 V√©rification post-transaction pour test_user_30: queued=1, in_waiting=True
[32mINFO    [0m test_logger:queue_manager.py:547 Aucun historique de statuts trouv√© pour test_user_30
[32mINFO    [0m test_logger:queue_manager.py:337 Tentative d'offre de slot √† test_user_30
[32mINFO    [0m test_logger:queue_manager.py:390 Slot offert avec succ√®s √† test_user_30
[32mINFO    [0m test_logger:queue_manager.py:337 Tentative d'offre de slot √† test_user_30
[32mINFO    [0m test_logger:queue_manager.py:349 √âtat invalide pour test_user_30: d√©j√† en draft ou actif
[32mINFO    [0m test_logger:queue_manager.py:444 Connexion confirm√©e pour test_user_30
[32mINFO    [0m test_logger:queue_manager.py:194 Tentative d'ajout de l'utilisateur test_user_31
[32mINFO    [0m test_logger:queue_manager.py:198 Statut actuel: {'status': None}
[32mINFO    [0m test_logger:queue_manager.py:212 Tentative d'ajout √† la file d'attente pour test_user_31 avec statut None
[32mINFO    [0m test_logger:queue_manager.py:220 R√©sultats de la transaction Redis pour test_user_31: [1, 1, 1]
[32mINFO    [0m test_logger:queue_manager.py:227 V√©rification post-transaction pour test_user_31: queued=1, in_waiting=True
[32mINFO    [0m test_logger:queue_manager.py:547 Aucun historique de statuts trouv√© pour test_user_31
[32mINFO    [0m test_logger:queue_manager.py:337 Tentative d'offre de slot √† test_user_31
[32mINFO    [0m test_logger:queue_manager.py:390 Slot offert avec succ√®s √† test_user_31
[32mINFO    [0m test_logger:queue_manager.py:337 Tentative d'offre de slot √† test_user_31
[32mINFO    [0m test_logger:queue_manager.py:349 √âtat invalide pour test_user_31: d√©j√† en draft ou actif
[32mINFO    [0m test_logger:queue_manager.py:444 Connexion confirm√©e pour test_user_31
[32mINFO    [0m test_logger:queue_manager.py:194 Tentative d'ajout de l'utilisateur test_user_32
[32mINFO    [0m test_logger:queue_manager.py:198 Statut actuel: {'status': None}
[32mINFO    [0m test_logger:queue_manager.py:212 Tentative d'ajout √† la file d'attente pour test_user_32 avec statut None
[32mINFO    [0m test_logger:queue_manager.py:220 R√©sultats de la transaction Redis pour test_user_32: [1, 1, 1]
[32mINFO    [0m test_logger:queue_manager.py:227 V√©rification post-transaction pour test_user_32: queued=1, in_waiting=True
[32mINFO    [0m test_logger:queue_manager.py:547 Aucun historique de statuts trouv√© pour test_user_32
[32mINFO    [0m test_logger:queue_manager.py:337 Tentative d'offre de slot √† test_user_32
[32mINFO    [0m test_logger:queue_manager.py:390 Slot offert avec succ√®s √† test_user_32
[32mINFO    [0m test_logger:queue_manager.py:337 Tentative d'offre de slot √† test_user_32
[32mINFO    [0m test_logger:queue_manager.py:349 √âtat invalide pour test_user_32: d√©j√† en draft ou actif
[32mINFO    [0m test_logger:queue_manager.py:444 Connexion confirm√©e pour test_user_32
[32mINFO    [0m test_logger:queue_manager.py:194 Tentative d'ajout de l'utilisateur test_user_33
[32mINFO    [0m test_logger:queue_manager.py:198 Statut actuel: {'status': None}
[32mINFO    [0m test_logger:queue_manager.py:212 Tentative d'ajout √† la file d'attente pour test_user_33 avec statut None
[32mINFO    [0m test_logger:queue_manager.py:220 R√©sultats de la transaction Redis pour test_user_33: [1, 1, 1]
[32mINFO    [0m test_logger:queue_manager.py:227 V√©rification post-transaction pour test_user_33: queued=1, in_waiting=True
[32mINFO    [0m test_logger:queue_manager.py:547 Aucun historique de statuts trouv√© pour test_user_33
[32mINFO    [0m test_logger:queue_manager.py:337 Tentative d'offre de slot √† test_user_33
[32mINFO    [0m test_logger:queue_manager.py:390 Slot offert avec succ√®s √† test_user_33
[32mINFO    [0m test_logger:queue_manager.py:337 Tentative d'offre de slot √† test_user_33
[32mINFO    [0m test_logger:queue_manager.py:349 √âtat invalide pour test_user_33: d√©j√† en draft ou actif
[32mINFO    [0m test_logger:queue_manager.py:444 Connexion confirm√©e pour test_user_33
[32mINFO    [0m test_logger:queue_manager.py:194 Tentative d'ajout de l'utilisateur test_user_34
[32mINFO    [0m test_logger:queue_manager.py:198 Statut actuel: {'status': None}
[32mINFO    [0m test_logger:queue_manager.py:212 Tentative d'ajout √† la file d'attente pour test_user_34 avec statut None
[32mINFO    [0m test_logger:queue_manager.py:220 R√©sultats de la transaction Redis pour test_user_34: [1, 1, 1]
[32mINFO    [0m test_logger:queue_manager.py:227 V√©rification post-transaction pour test_user_34: queued=1, in_waiting=True
[32mINFO    [0m test_logger:queue_manager.py:547 Aucun historique de statuts trouv√© pour test_user_34
[32mINFO    [0m test_logger:queue_manager.py:337 Tentative d'offre de slot √† test_user_34
[32mINFO    [0m test_logger:queue_manager.py:390 Slot offert avec succ√®s √† test_user_34
[32mINFO    [0m test_logger:queue_manager.py:337 Tentative d'offre de slot √† test_user_34
[32mINFO    [0m test_logger:queue_manager.py:349 √âtat invalide pour test_user_34: d√©j√† en draft ou actif
[32mINFO    [0m test_logger:queue_manager.py:444 Connexion confirm√©e pour test_user_34
[32mINFO    [0m test_logger:queue_manager.py:194 Tentative d'ajout de l'utilisateur test_user_35
[32mINFO    [0m test_logger:queue_manager.py:198 Statut actuel: {'status': None}
[32mINFO    [0m test_logger:queue_manager.py:212 Tentative d'ajout √† la file d'attente pour test_user_35 avec statut None
[32mINFO    [0m test_logger:queue_manager.py:220 R√©sultats de la transaction Redis pour test_user_35: [1, 1, 1]
[32mINFO    [0m test_logger:queue_manager.py:227 V√©rification post-transaction pour test_user_35: queued=1, in_waiting=True
[32mINFO    [0m test_logger:queue_manager.py:547 Aucun historique de statuts trouv√© pour test_user_35
[32mINFO    [0m test_logger:queue_manager.py:337 Tentative d'offre de slot √† test_user_35
[32mINFO    [0m test_logger:queue_manager.py:390 Slot offert avec succ√®s √† test_user_35
[32mINFO    [0m test_logger:queue_manager.py:337 Tentative d'offre de slot √† test_user_35
[32mINFO    [0m test_logger:queue_manager.py:349 √âtat invalide pour test_user_35: d√©j√† en draft ou actif
[32mINFO    [0m test_logger:queue_manager.py:444 Connexion confirm√©e pour test_user_35
[32mINFO    [0m test_logger:queue_manager.py:194 Tentative d'ajout de l'utilisateur test_user_36
[32mINFO    [0m test_logger:queue_manager.py:198 Statut actuel: {'status': None}
[32mINFO    [0m test_logger:queue_manager.py:212 Tentative d'ajout √† la file d'attente pour test_user_36 avec statut None
[32mINFO    [0m test_logger:queue_manager.py:220 R√©sultats de la transaction Redis pour test_user_36: [1, 1, 1]
[32mINFO    [0m test_logger:queue_manager.py:227 V√©rification post-transaction pour test_user_36: queued=1, in_waiting=True
[32mINFO    [0m test_logger:queue_manager.py:547 Aucun historique de statuts trouv√© pour test_user_36
[32mINFO    [0m test_logger:queue_manager.py:337 Tentative d'offre de slot √† test_user_36
[32mINFO    [0m test_logger:queue_manager.py:390 Slot offert avec succ√®s √† test_user_36
[32mINFO    [0m test_logger:queue_manager.py:337 Tentative d'offre de slot √† test_user_36
[32mINFO    [0m test_logger:queue_manager.py:349 √âtat invalide pour test_user_36: d√©j√† en draft ou actif
[32mINFO    [0m test_logger:queue_manager.py:444 Connexion confirm√©e pour test_user_36
[32mINFO    [0m test_logger:queue_manager.py:194 Tentative d'ajout de l'utilisateur test_user_37
[32mINFO    [0m test_logger:queue_manager.py:198 Statut actuel: {'status': None}
[32mINFO    [0m test_logger:queue_manager.py:212 Tentative d'ajout √† la file d'attente pour test_user_37 avec statut None
[32mINFO    [0m test_logger:queue_manager.py:220 R√©sultats de la transaction Redis pour test_user_37: [1, 1, 1]
[32mINFO    [0m test_logger:queue_manager.py:227 V√©rification post-transaction pour test_user_37: queued=1, in_waiting=True
[32mINFO    [0m test_logger:queue_manager.py:547 Aucun historique de statuts trouv√© pour test_user_37
[32mINFO    [0m test_logger:queue_manager.py:337 Tentative d'offre de slot √† test_user_37
[32mINFO    [0m test_logger:queue_manager.py:390 Slot offert avec succ√®s √† test_user_37
[32mINFO    [0m test_logger:queue_manager.py:337 Tentative d'offre de slot √† test_user_37
[32mINFO    [0m test_logger:queue_manager.py:349 √âtat invalide pour test_user_37: d√©j√† en draft ou actif
[32mINFO    [0m test_logger:queue_manager.py:444 Connexion confirm√©e pour test_user_37
[32mINFO    [0m test_logger:queue_manager.py:194 Tentative d'ajout de l'utilisateur test_user_38
[32mINFO    [0m test_logger:queue_manager.py:198 Statut actuel: {'status': None}
[32mINFO    [0m test_logger:queue_manager.py:212 Tentative d'ajout √† la file d'attente pour test_user_38 avec statut None
[32mINFO    [0m test_logger:queue_manager.py:220 R√©sultats de la transaction Redis pour test_user_38: [1, 1, 1]
[32mINFO    [0m test_logger:queue_manager.py:227 V√©rification post-transaction pour test_user_38: queued=1, in_waiting=True
[32mINFO    [0m test_logger:queue_manager.py:547 Aucun historique de statuts trouv√© pour test_user_38
[32mINFO    [0m test_logger:queue_manager.py:337 Tentative d'offre de slot √† test_user_38
[32mINFO    [0m test_logger:queue_manager.py:390 Slot offert avec succ√®s √† test_user_38
[32mINFO    [0m test_logger:queue_manager.py:337 Tentative d'offre de slot √† test_user_38
[32mINFO    [0m test_logger:queue_manager.py:349 √âtat invalide pour test_user_38: d√©j√† en draft ou actif
[32mINFO    [0m test_logger:queue_manager.py:444 Connexion confirm√©e pour test_user_38
[32mINFO    [0m test_logger:queue_manager.py:194 Tentative d'ajout de l'utilisateur test_user_39
[32mINFO    [0m test_logger:queue_manager.py:198 Statut actuel: {'status': None}
[32mINFO    [0m test_logger:queue_manager.py:212 Tentative d'ajout √† la file d'attente pour test_user_39 avec statut None
[32mINFO    [0m test_logger:queue_manager.py:220 R√©sultats de la transaction Redis pour test_user_39: [1, 1, 1]
[32mINFO    [0m test_logger:queue_manager.py:227 V√©rification post-transaction pour test_user_39: queued=1, in_waiting=True
[32mINFO    [0m test_logger:queue_manager.py:547 Aucun historique de statuts trouv√© pour test_user_39
[32mINFO    [0m test_logger:queue_manager.py:337 Tentative d'offre de slot √† test_user_39
[32mINFO    [0m test_logger:queue_manager.py:390 Slot offert avec succ√®s √† test_user_39
[32mINFO    [0m test_logger:queue_manager.py:337 Tentative d'offre de slot √† test_user_39
[32mINFO    [0m test_logger:queue_manager.py:349 √âtat invalide pour test_user_39: d√©j√† en draft ou actif
[32mINFO    [0m test_logger:queue_manager.py:444 Connexion confirm√©e pour test_user_39
[32mINFO    [0m test_logger:queue_manager.py:194 Tentative d'ajout de l'utilisateur test_user_40
[32mINFO    [0m test_logger:queue_manager.py:198 Statut actuel: {'status': None}
[32mINFO    [0m test_logger:queue_manager.py:212 Tentative d'ajout √† la file d'attente pour test_user_40 avec statut None
[32mINFO    [0m test_logger:queue_manager.py:220 R√©sultats de la transaction Redis pour test_user_40: [1, 1, 1]
[32mINFO    [0m test_logger:queue_manager.py:227 V√©rification post-transaction pour test_user_40: queued=1, in_waiting=True
[32mINFO    [0m test_logger:queue_manager.py:547 Aucun historique de statuts trouv√© pour test_user_40
[32mINFO    [0m test_logger:queue_manager.py:337 Tentative d'offre de slot √† test_user_40
[32mINFO    [0m test_logger:queue_manager.py:390 Slot offert avec succ√®s √† test_user_40
[32mINFO    [0m test_logger:queue_manager.py:337 Tentative d'offre de slot √† test_user_40
[32mINFO    [0m test_logger:queue_manager.py:349 √âtat invalide pour test_user_40: d√©j√† en draft ou actif
[32mINFO    [0m test_logger:queue_manager.py:444 Connexion confirm√©e pour test_user_40
[32mINFO    [0m test_logger:queue_manager.py:194 Tentative d'ajout de l'utilisateur test_user_41
[32mINFO    [0m test_logger:queue_manager.py:198 Statut actuel: {'status': None}
[32mINFO    [0m test_logger:queue_manager.py:212 Tentative d'ajout √† la file d'attente pour test_user_41 avec statut None
[32mINFO    [0m test_logger:queue_manager.py:220 R√©sultats de la transaction Redis pour test_user_41: [1, 1, 1]
[32mINFO    [0m test_logger:queue_manager.py:227 V√©rification post-transaction pour test_user_41: queued=1, in_waiting=True
[32mINFO    [0m test_logger:queue_manager.py:547 Aucun historique de statuts trouv√© pour test_user_41
[32mINFO    [0m test_logger:queue_manager.py:337 Tentative d'offre de slot √† test_user_41
[32mINFO    [0m test_logger:queue_manager.py:390 Slot offert avec succ√®s √† test_user_41
[32mINFO    [0m test_logger:queue_manager.py:337 Tentative d'offre de slot √† test_user_41
[32mINFO    [0m test_logger:queue_manager.py:349 √âtat invalide pour test_user_41: d√©j√† en draft ou actif
[32mINFO    [0m test_logger:queue_manager.py:444 Connexion confirm√©e pour test_user_41
[32mINFO    [0m test_logger:queue_manager.py:194 Tentative d'ajout de l'utilisateur test_user_42
[32mINFO    [0m test_logger:queue_manager.py:198 Statut actuel: {'status': None}
[32mINFO    [0m test_logger:queue_manager.py:212 Tentative d'ajout √† la file d'attente pour test_user_42 avec statut None
[32mINFO    [0m test_logger:queue_manager.py:220 R√©sultats de la transaction Redis pour test_user_42: [1, 1, 1]
[32mINFO    [0m test_logger:queue_manager.py:227 V√©rification post-transaction pour test_user_42: queued=1, in_waiting=True
[32mINFO    [0m test_logger:queue_manager.py:547 Aucun historique de statuts trouv√© pour test_user_42
[32mINFO    [0m test_logger:queue_manager.py:337 Tentative d'offre de slot √† test_user_42
[32mINFO    [0m test_logger:queue_manager.py:390 Slot offert avec succ√®s √† test_user_42
[32mINFO    [0m test_logger:queue_manager.py:337 Tentative d'offre de slot √† test_user_42
[32mINFO    [0m test_logger:queue_manager.py:349 √âtat invalide pour test_user_42: d√©j√† en draft ou actif
[32mINFO    [0m test_logger:queue_manager.py:444 Connexion confirm√©e pour test_user_42
[32mINFO    [0m test_logger:queue_manager.py:194 Tentative d'ajout de l'utilisateur test_user_43
[32mINFO    [0m test_logger:queue_manager.py:198 Statut actuel: {'status': None}
[32mINFO    [0m test_logger:queue_manager.py:212 Tentative d'ajout √† la file d'attente pour test_user_43 avec statut None
[32mINFO    [0m test_logger:queue_manager.py:220 R√©sultats de la transaction Redis pour test_user_43: [1, 1, 1]
[32mINFO    [0m test_logger:queue_manager.py:227 V√©rification post-transaction pour test_user_43: queued=1, in_waiting=True
[32mINFO    [0m test_logger:queue_manager.py:547 Aucun historique de statuts trouv√© pour test_user_43
[32mINFO    [0m test_logger:queue_manager.py:337 Tentative d'offre de slot √† test_user_43
[32mINFO    [0m test_logger:queue_manager.py:390 Slot offert avec succ√®s √† test_user_43
[32mINFO    [0m test_logger:queue_manager.py:337 Tentative d'offre de slot √† test_user_43
[32mINFO    [0m test_logger:queue_manager.py:349 √âtat invalide pour test_user_43: d√©j√† en draft ou actif
[32mINFO    [0m test_logger:queue_manager.py:444 Connexion confirm√©e pour test_user_43
[32mINFO    [0m test_logger:queue_manager.py:194 Tentative d'ajout de l'utilisateur test_user_44
[32mINFO    [0m test_logger:queue_manager.py:198 Statut actuel: {'status': None}
[32mINFO    [0m test_logger:queue_manager.py:212 Tentative d'ajout √† la file d'attente pour test_user_44 avec statut None
[32mINFO    [0m test_logger:queue_manager.py:220 R√©sultats de la transaction Redis pour test_user_44: [1, 1, 1]
[32mINFO    [0m test_logger:queue_manager.py:227 V√©rification post-transaction pour test_user_44: queued=1, in_waiting=True
[32mINFO    [0m test_logger:queue_manager.py:547 Aucun historique de statuts trouv√© pour test_user_44
[32mINFO    [0m test_logger:queue_manager.py:337 Tentative d'offre de slot √† test_user_44
[32mINFO    [0m test_logger:queue_manager.py:390 Slot offert avec succ√®s √† test_user_44
[32mINFO    [0m test_logger:queue_manager.py:337 Tentative d'offre de slot √† test_user_44
[32mINFO    [0m test_logger:queue_manager.py:349 √âtat invalide pour test_user_44: d√©j√† en draft ou actif
[32mINFO    [0m test_logger:queue_manager.py:444 Connexion confirm√©e pour test_user_44
[32mINFO    [0m test_logger:queue_manager.py:194 Tentative d'ajout de l'utilisateur test_user_45
[32mINFO    [0m test_logger:queue_manager.py:198 Statut actuel: {'status': None}
[32mINFO    [0m test_logger:queue_manager.py:212 Tentative d'ajout √† la file d'attente pour test_user_45 avec statut None
[32mINFO    [0m test_logger:queue_manager.py:220 R√©sultats de la transaction Redis pour test_user_45: [1, 1, 1]
[32mINFO    [0m test_logger:queue_manager.py:227 V√©rification post-transaction pour test_user_45: queued=1, in_waiting=True
[32mINFO    [0m test_logger:queue_manager.py:547 Aucun historique de statuts trouv√© pour test_user_45
[32mINFO    [0m test_logger:queue_manager.py:337 Tentative d'offre de slot √† test_user_45
[32mINFO    [0m test_logger:queue_manager.py:390 Slot offert avec succ√®s √† test_user_45
[32mINFO    [0m test_logger:queue_manager.py:337 Tentative d'offre de slot √† test_user_45
[32mINFO    [0m test_logger:queue_manager.py:349 √âtat invalide pour test_user_45: d√©j√† en draft ou actif
[32mINFO    [0m test_logger:queue_manager.py:444 Connexion confirm√©e pour test_user_45
[32mINFO    [0m test_logger:queue_manager.py:194 Tentative d'ajout de l'utilisateur test_user_46
[32mINFO    [0m test_logger:queue_manager.py:198 Statut actuel: {'status': None}
[32mINFO    [0m test_logger:queue_manager.py:212 Tentative d'ajout √† la file d'attente pour test_user_46 avec statut None
[32mINFO    [0m test_logger:queue_manager.py:220 R√©sultats de la transaction Redis pour test_user_46: [1, 1, 1]
[32mINFO    [0m test_logger:queue_manager.py:227 V√©rification post-transaction pour test_user_46: queued=1, in_waiting=True
[32mINFO    [0m test_logger:queue_manager.py:547 Aucun historique de statuts trouv√© pour test_user_46
[32mINFO    [0m test_logger:queue_manager.py:337 Tentative d'offre de slot √† test_user_46
[32mINFO    [0m test_logger:queue_manager.py:390 Slot offert avec succ√®s √† test_user_46
[32mINFO    [0m test_logger:queue_manager.py:337 Tentative d'offre de slot √† test_user_46
[32mINFO    [0m test_logger:queue_manager.py:349 √âtat invalide pour test_user_46: d√©j√† en draft ou actif
[32mINFO    [0m test_logger:queue_manager.py:444 Connexion confirm√©e pour test_user_46
[32mINFO    [0m test_logger:queue_manager.py:194 Tentative d'ajout de l'utilisateur test_user_47
[32mINFO    [0m test_logger:queue_manager.py:198 Statut actuel: {'status': None}
[32mINFO    [0m test_logger:queue_manager.py:212 Tentative d'ajout √† la file d'attente pour test_user_47 avec statut None
[32mINFO    [0m test_logger:queue_manager.py:220 R√©sultats de la transaction Redis pour test_user_47: [1, 1, 1]
[32mINFO    [0m test_logger:queue_manager.py:227 V√©rification post-transaction pour test_user_47: queued=1, in_waiting=True
[32mINFO    [0m test_logger:queue_manager.py:547 Aucun historique de statuts trouv√© pour test_user_47
[32mINFO    [0m test_logger:queue_manager.py:337 Tentative d'offre de slot √† test_user_47
[32mINFO    [0m test_logger:queue_manager.py:390 Slot offert avec succ√®s √† test_user_47
[32mINFO    [0m test_logger:queue_manager.py:337 Tentative d'offre de slot √† test_user_47
[32mINFO    [0m test_logger:queue_manager.py:349 √âtat invalide pour test_user_47: d√©j√† en draft ou actif
[32mINFO    [0m test_logger:queue_manager.py:444 Connexion confirm√©e pour test_user_47
[32mINFO    [0m test_logger:queue_manager.py:194 Tentative d'ajout de l'utilisateur test_user_48
[32mINFO    [0m test_logger:queue_manager.py:198 Statut actuel: {'status': None}
[32mINFO    [0m test_logger:queue_manager.py:212 Tentative d'ajout √† la file d'attente pour test_user_48 avec statut None
[32mINFO    [0m test_logger:queue_manager.py:220 R√©sultats de la transaction Redis pour test_user_48: [1, 1, 1]
[32mINFO    [0m test_logger:queue_manager.py:227 V√©rification post-transaction pour test_user_48: queued=1, in_waiting=True
[32mINFO    [0m test_logger:queue_manager.py:547 Aucun historique de statuts trouv√© pour test_user_48
[32mINFO    [0m test_logger:queue_manager.py:337 Tentative d'offre de slot √† test_user_48
[32mINFO    [0m test_logger:queue_manager.py:390 Slot offert avec succ√®s √† test_user_48
[32mINFO    [0m test_logger:queue_manager.py:337 Tentative d'offre de slot √† test_user_48
[32mINFO    [0m test_logger:queue_manager.py:349 √âtat invalide pour test_user_48: d√©j√† en draft ou actif
[32mINFO    [0m test_logger:queue_manager.py:444 Connexion confirm√©e pour test_user_48
[32mINFO    [0m test_logger:queue_manager.py:194 Tentative d'ajout de l'utilisateur test_user_49
[32mINFO    [0m test_logger:queue_manager.py:198 Statut actuel: {'status': None}
[32mINFO    [0m test_logger:queue_manager.py:212 Tentative d'ajout √† la file d'attente pour test_user_49 avec statut None
[32mINFO    [0m test_logger:queue_manager.py:220 R√©sultats de la transaction Redis pour test_user_49: [1, 1, 1]
[32mINFO    [0m test_logger:queue_manager.py:227 V√©rification post-transaction pour test_user_49: queued=1, in_waiting=True
[32mINFO    [0m test_logger:queue_manager.py:547 Aucun historique de statuts trouv√© pour test_user_49
[32mINFO    [0m test_logger:queue_manager.py:337 Tentative d'offre de slot √† test_user_49
[32mINFO    [0m test_logger:queue_manager.py:390 Slot offert avec succ√®s √† test_user_49
[32mINFO    [0m test_logger:queue_manager.py:337 Tentative d'offre de slot √† test_user_49
[32mINFO    [0m test_logger:queue_manager.py:349 √âtat invalide pour test_user_49: d√©j√† en draft ou actif
[32mINFO    [0m test_logger:queue_manager.py:444 Connexion confirm√©e pour test_user_49
[32mINFO    [0m test_logger:queue_manager.py:194 Tentative d'ajout de l'utilisateur test_user_50
[32mINFO    [0m test_logger:queue_manager.py:198 Statut actuel: {'status': None}
[32mINFO    [0m test_logger:queue_manager.py:212 Tentative d'ajout √† la file d'attente pour test_user_50 avec statut None
[32mINFO    [0m test_logger:queue_manager.py:220 R√©sultats de la transaction Redis pour test_user_50: [1, 1, 1]
[32mINFO    [0m test_logger:queue_manager.py:227 V√©rification post-transaction pour test_user_50: queued=1, in_waiting=True
[32mINFO    [0m test_logger:queue_manager.py:547 Aucun historique de statuts trouv√© pour test_user_50
[1m[31mERROR   [0m test_api_endpoints:test_api_endpoints.py:110 Test failed with error: 'position'
[1m[31mERROR   [0m test_api_endpoints:test_api_endpoints.py:111 √âtat final:
[1m[31mERROR   [0m test_api_endpoints:test_api_endpoints.py:112 Active users: {'test_user_48', 'test_user_34', 'test_user_35', 'test_user_44', 'test_user_4', 'test_user_32', 'test_user_46', 'test_user_25', 'test_user_36', 'test_user_31', 'test_user_7', 'test_user_20', 'test_user_2', 'test_user_5', 'test_user_47', 'test_user_39', 'test_user_49', 'test_user_9', 'test_user_27', 'test_user_17', 'test_user_22', 'test_user_13', 'test_user_18', 'test_user_19', 'test_user_33', 'test_user_8', 'test_user_43', 'test_user_16', 'test_user_45', 'test_user_40', 'test_user_6', 'test_user_42', 'test_user_37', 'test_user_38', 'test_user_41', 'test_user_28', 'test_user_3', 'test_user_11', 'test_user_15', 'test_user_14', 'test_user_10', 'test_user_21', 'test_user_29', 'test_user_26', 'test_user_30', 'test_user_24', 'test_user_12', 'test_user_0', 'test_user_1', 'test_user_23'}
[1m[31mERROR   [0m test_api_endpoints:test_api_endpoints.py:113 Queued users: {'test_user_50'}
[1m[31mERROR   [0m test_api_endpoints:test_api_endpoints.py:114 Draft users: set()
[31m[1m__________________________ TestAPI.test_timers_async ___________________________[0m
self = <test_api_endpoints.TestAPI object at 0xffffb424fdf0>
test_client = <httpx.AsyncClient object at 0xffffb405cf30>
redis_client = <redis.asyncio.client.Redis(<redis.asyncio.connection.ConnectionPool(<redis.asyncio.connection.Connection(host=redis-test,port=6379,db=1)>)>)>
test_logger = <Logger test_logger (INFO)>
>   ???
[1m[31mE   KeyError: 'timer_type'[0m
[1m[31m/Users/chrysostomebeltran/Documents/GitHub/redis_queue/tests/test_api_endpoints.py[0m:217: KeyError
---------------------------- Captured stderr setup -----------------------------
2025-01-09 21:10:21 - test_logger - INFO - Connexion Redis √©tablie avec succ√®s
2025-01-09 21:10:21 - test_logger - INFO - QueueManager initialis√© avec succ√®s
2025-01-09 21:10:21 - test_logger - INFO - Client de test initialis√© avec succ√®s
------------------------------ Captured log setup ------------------------------
[32mINFO    [0m test_logger:conftest.py:132 Connexion Redis √©tablie avec succ√®s
[32mINFO    [0m test_logger:conftest.py:155 QueueManager initialis√© avec succ√®s
[32mINFO    [0m test_logger:conftest.py:168 Client de test initialis√© avec succ√®s
----------------------------- Captured stderr call -----------------------------
2025-01-09 21:10:21 - test_logger - INFO - Mode Celery configur√©: EAGER=True
2025-01-09 21:10:21 - test_logger - INFO - File active remplie
2025-01-09 21:10:21 - test_logger - INFO - Tentative d'ajout de l'utilisateur test_user_timers
2025-01-09 21:10:21 - test_logger - INFO - Statut actuel: {'status': None}
2025-01-09 21:10:21 - test_logger - INFO - Tentative d'ajout √† la file d'attente pour test_user_timers avec statut None
2025-01-09 21:10:21 - test_logger - INFO - R√©sultats de la transaction Redis pour test_user_timers: [1, 1, 1]
2025-01-09 21:10:21 - test_logger - INFO - V√©rification post-transaction pour test_user_timers: queued=1, in_waiting=True
2025-01-09 21:10:21 - test_logger - INFO - Aucun historique de statuts trouv√© pour test_user_timers
2025-01-09 21:10:21 - test_logger - INFO - Utilisateur test_user_timers ajout√© √† la file
2025-01-09 21:10:21 - test_logger - INFO - R√©cup√©ration des timers pour test_user_timers
2025-01-09 21:10:21 - test_logger - WARNING - Aucun timer actif pour test_user_timers
2025-01-09 21:10:21 - test_logger - WARNING - Nettoyage de l'√©tat incoh√©rent pour test_user_timers
2025-01-09 21:10:21 - test_logger - INFO - √âtat nettoy√© pour test_user_timers
2025-01-09 21:10:21 - test_logger - INFO - Nettoyage termin√©
------------------------------ Captured log call -------------------------------
[32mINFO    [0m test_logger:test_api_endpoints.py:195 Mode Celery configur√©: EAGER=True
[32mINFO    [0m test_logger:test_api_endpoints.py:206 File active remplie
[32mINFO    [0m test_logger:queue_manager.py:194 Tentative d'ajout de l'utilisateur test_user_timers
[32mINFO    [0m test_logger:queue_manager.py:198 Statut actuel: {'status': None}
[32mINFO    [0m test_logger:queue_manager.py:212 Tentative d'ajout √† la file d'attente pour test_user_timers avec statut None
[32mINFO    [0m test_logger:queue_manager.py:220 R√©sultats de la transaction Redis pour test_user_timers: [1, 1, 1]
[32mINFO    [0m test_logger:queue_manager.py:227 V√©rification post-transaction pour test_user_timers: queued=1, in_waiting=True
[32mINFO    [0m test_logger:queue_manager.py:547 Aucun historique de statuts trouv√© pour test_user_timers
[32mINFO    [0m test_logger:test_api_endpoints.py:211 Utilisateur test_user_timers ajout√© √† la file
[32mINFO    [0m test_logger:queue_manager.py:680 R√©cup√©ration des timers pour test_user_timers
[33mWARNING [0m test_logger:queue_manager.py:696 Aucun timer actif pour test_user_timers
[33mWARNING [0m test_logger:queue_manager.py:734 Nettoyage de l'√©tat incoh√©rent pour test_user_timers
[32mINFO    [0m test_logger:queue_manager.py:745 √âtat nettoy√© pour test_user_timers
[32mINFO    [0m test_logger:test_api_endpoints.py:269 Nettoyage termin√©
[31m[1m____________________ TestIntegration.test_concurrent_users _____________________[0m
self = <test_integration.TestIntegration object at 0xffffb419ccd0>
redis_client = <redis.asyncio.client.Redis(<redis.asyncio.connection.ConnectionPool(<redis.asyncio.connection.Connection(host=redis-test,port=6379,db=1)>)>)>
test_logger = <Logger test_logger (INFO)>
>   ???
[1m[31mE   AssertionError: La file d'attente devrait contenir 5 utilisateurs[0m
[1m[31mE   assert 1 == 5[0m
[1m[31m/Users/chrysostomebeltran/Documents/GitHub/redis_queue/tests/test_integration.py[0m:33: AssertionError
---------------------------- Captured stderr setup -----------------------------
2025-01-09 21:10:22 - test_logger - INFO - Connexion Redis √©tablie avec succ√®s
------------------------------ Captured log setup ------------------------------
[32mINFO    [0m test_logger:conftest.py:132 Connexion Redis √©tablie avec succ√®s
----------------------------- Captured stderr call -----------------------------
2025-01-09 21:10:22 - test_logger - INFO - D√©marrage du test d'ajout concurrent
2025-01-09 21:10:22 - test_logger - INFO - Ajout concurrent de 5 utilisateurs
2025-01-09 21:10:22 - test_logger - INFO - Tentative d'ajout de l'utilisateur user_0
2025-01-09 21:10:22 - test_logger - INFO - Tentative d'ajout de l'utilisateur user_1
2025-01-09 21:10:22 - test_logger - INFO - Tentative d'ajout de l'utilisateur user_2
2025-01-09 21:10:22 - test_logger - INFO - Tentative d'ajout de l'utilisateur user_3
2025-01-09 21:10:22 - test_logger - INFO - Tentative d'ajout de l'utilisateur user_4
2025-01-09 21:10:22 - test_logger - INFO - Statut actuel: {'status': None}
2025-01-09 21:10:22 - test_logger - INFO - Tentative d'ajout √† la file d'attente pour user_0 avec statut None
2025-01-09 21:10:22 - test_logger - INFO - R√©sultats de la transaction Redis pour user_0: [1, 1, 1]
2025-01-09 21:10:22 - test_logger - INFO - Statut actuel: {'status': None}
2025-01-09 21:10:22 - test_logger - INFO - V√©rification post-transaction pour user_0: queued=1, in_waiting=True
2025-01-09 21:10:22 - test_logger - INFO - Statut actuel: {'status': None}
2025-01-09 21:10:22 - test_logger - INFO - Statut actuel: {'status': None}
2025-01-09 21:10:22 - test_logger - INFO - Statut actuel: {'status': None}
2025-01-09 21:10:22 - test_logger - INFO - Tentative d'ajout √† la file d'attente pour user_1 avec statut None
2025-01-09 21:10:22 - test_logger - INFO - Tentative d'ajout √† la file d'attente pour user_2 avec statut None
2025-01-09 21:10:22 - test_logger - INFO - Tentative d'ajout √† la file d'attente pour user_3 avec statut None
2025-01-09 21:10:22 - test_logger - INFO - Tentative d'ajout √† la file d'attente pour user_4 avec statut None
2025-01-09 21:10:22 - test_logger - INFO - R√©sultats de la transaction Redis pour user_1: [2, 1, 2]
2025-01-09 21:10:22 - test_logger - INFO - R√©sultats de la transaction Redis pour user_2: [3, 1, 3]
2025-01-09 21:10:22 - test_logger - INFO - R√©sultats de la transaction Redis pour user_3: [4, 1, 4]
2025-01-09 21:10:22 - test_logger - INFO - R√©sultats de la transaction Redis pour user_4: [5, 1, 5]
2025-01-09 21:10:22 - test_logger - INFO - Aucun historique de statuts trouv√© pour user_0
2025-01-09 21:10:22 - test_logger - INFO - V√©rification post-transaction pour user_1: queued=1, in_waiting=True
2025-01-09 21:10:22 - test_logger - INFO - V√©rification post-transaction pour user_3: queued=1, in_waiting=True
2025-01-09 21:10:22 - test_logger - INFO - V√©rification post-transaction pour user_2: queued=1, in_waiting=True
2025-01-09 21:10:22 - test_logger - INFO - V√©rification post-transaction pour user_4: queued=1, in_waiting=True
2025-01-09 21:10:22 - test_logger - INFO - Aucun historique de statuts trouv√© pour user_1
2025-01-09 21:10:22 - test_logger - INFO - Aucun historique de statuts trouv√© pour user_3
2025-01-09 21:10:22 - test_logger - INFO - Aucun historique de statuts trouv√© pour user_2
2025-01-09 21:10:22 - test_logger - INFO - Aucun historique de statuts trouv√© pour user_4
2025-01-09 21:10:22 - test_logger - INFO - √âtat imm√©diat - File d'attente: 1, Utilisateurs en file: 0
------------------------------ Captured log call -------------------------------
[32mINFO    [0m test_logger:test_integration.py:11 D√©marrage du test d'ajout concurrent
[32mINFO    [0m test_logger:test_integration.py:20 Ajout concurrent de 5 utilisateurs
[32mINFO    [0m test_logger:queue_manager.py:194 Tentative d'ajout de l'utilisateur user_0
[32mINFO    [0m test_logger:queue_manager.py:194 Tentative d'ajout de l'utilisateur user_1
[32mINFO    [0m test_logger:queue_manager.py:194 Tentative d'ajout de l'utilisateur user_2
[32mINFO    [0m test_logger:queue_manager.py:194 Tentative d'ajout de l'utilisateur user_3
[32mINFO    [0m test_logger:queue_manager.py:194 Tentative d'ajout de l'utilisateur user_4
[32mINFO    [0m test_logger:queue_manager.py:198 Statut actuel: {'status': None}
[32mINFO    [0m test_logger:queue_manager.py:212 Tentative d'ajout √† la file d'attente pour user_0 avec statut None
[32mINFO    [0m test_logger:queue_manager.py:220 R√©sultats de la transaction Redis pour user_0: [1, 1, 1]
[32mINFO    [0m test_logger:queue_manager.py:198 Statut actuel: {'status': None}
[32mINFO    [0m test_logger:queue_manager.py:227 V√©rification post-transaction pour user_0: queued=1, in_waiting=True
[32mINFO    [0m test_logger:queue_manager.py:198 Statut actuel: {'status': None}
[32mINFO    [0m test_logger:queue_manager.py:198 Statut actuel: {'status': None}
[32mINFO    [0m test_logger:queue_manager.py:198 Statut actuel: {'status': None}
[32mINFO    [0m test_logger:queue_manager.py:212 Tentative d'ajout √† la file d'attente pour user_1 avec statut None
[32mINFO    [0m test_logger:queue_manager.py:212 Tentative d'ajout √† la file d'attente pour user_2 avec statut None
[32mINFO    [0m test_logger:queue_manager.py:212 Tentative d'ajout √† la file d'attente pour user_3 avec statut None
[32mINFO    [0m test_logger:queue_manager.py:212 Tentative d'ajout √† la file d'attente pour user_4 avec statut None
[32mINFO    [0m test_logger:queue_manager.py:220 R√©sultats de la transaction Redis pour user_1: [2, 1, 2]
[32mINFO    [0m test_logger:queue_manager.py:220 R√©sultats de la transaction Redis pour user_2: [3, 1, 3]
[32mINFO    [0m test_logger:queue_manager.py:220 R√©sultats de la transaction Redis pour user_3: [4, 1, 4]
[32mINFO    [0m test_logger:queue_manager.py:220 R√©sultats de la transaction Redis pour user_4: [5, 1, 5]
[32mINFO    [0m test_logger:queue_manager.py:547 Aucun historique de statuts trouv√© pour user_0
[32mINFO    [0m test_logger:queue_manager.py:227 V√©rification post-transaction pour user_1: queued=1, in_waiting=True
[32mINFO    [0m test_logger:queue_manager.py:227 V√©rification post-transaction pour user_3: queued=1, in_waiting=True
[32mINFO    [0m test_logger:queue_manager.py:227 V√©rification post-transaction pour user_2: queued=1, in_waiting=True
[32mINFO    [0m test_logger:queue_manager.py:227 V√©rification post-transaction pour user_4: queued=1, in_waiting=True
[32mINFO    [0m test_logger:queue_manager.py:547 Aucun historique de statuts trouv√© pour user_1
[32mINFO    [0m test_logger:queue_manager.py:547 Aucun historique de statuts trouv√© pour user_3
[32mINFO    [0m test_logger:queue_manager.py:547 Aucun historique de statuts trouv√© pour user_2
[32mINFO    [0m test_logger:queue_manager.py:547 Aucun historique de statuts trouv√© pour user_4
[32mINFO    [0m test_logger:test_integration.py:30 √âtat imm√©diat - File d'attente: 1, Utilisateurs en file: 0
[31m[1m__________________ TestTimers.test_get_timers_endpoint_draft ___________________[0m
self = <test_timers.TestTimers object at 0xffffb40b0050>
test_client = <httpx.AsyncClient object at 0xffffb370f8a0>
redis_client = <redis.asyncio.client.Redis(<redis.asyncio.connection.ConnectionPool(<redis.asyncio.connection.Connection(host=redis-test,port=6379,db=1)>)>)>
>   ???
[1m[31mE   KeyError: 'timer_type'[0m
[1m[31m/Users/chrysostomebeltran/Documents/GitHub/redis_queue/tests/test_timers.py[0m:79: KeyError
---------------------------- Captured stderr setup -----------------------------
2025-01-09 21:10:27 - test_logger - INFO - Connexion Redis √©tablie avec succ√®s
2025-01-09 21:10:27 - test_logger - INFO - Client de test initialis√© avec succ√®s
------------------------------ Captured log setup ------------------------------
[32mINFO    [0m test_logger:conftest.py:132 Connexion Redis √©tablie avec succ√®s
[32mINFO    [0m test_logger:conftest.py:168 Client de test initialis√© avec succ√®s
----------------------------- Captured stderr call -----------------------------
2025-01-09 21:10:27 - test_logger - INFO - R√©cup√©ration des timers pour test_user_api_draft
2025-01-09 21:10:46 - test_logger - ERROR - Erreur lors de la r√©cup√©ration des timers pour test_user_api_draft: Error 111 connecting to localhost:6379. Connection refused.
------------------------------ Captured log call -------------------------------
[32mINFO    [0m test_logger:queue_manager.py:680 R√©cup√©ration des timers pour test_user_api_draft
[33mWARNING [0m kombu.connection:connection.py:669 No hostname was supplied. Reverting to default 'localhost'
[1m[31mERROR   [0m celery.backends.redis:redis.py:391 Connection to Redis lost: Retry (0/20) now.
[1m[31mERROR   [0m celery.backends.redis:redis.py:391 Connection to Redis lost: Retry (1/20) in 1.00 second.
[1m[31mERROR   [0m celery.backends.redis:redis.py:391 Connection to Redis lost: Retry (2/20) in 1.00 second.
[1m[31mERROR   [0m celery.backends.redis:redis.py:391 Connection to Redis lost: Retry (3/20) in 1.00 second.
[1m[31mERROR   [0m celery.backends.redis:redis.py:391 Connection to Redis lost: Retry (4/20) in 1.00 second.
[1m[31mERROR   [0m celery.backends.redis:redis.py:391 Connection to Redis lost: Retry (5/20) in 1.00 second.
[1m[31mERROR   [0m celery.backends.redis:redis.py:391 Connection to Redis lost: Retry (6/20) in 1.00 second.
[1m[31mERROR   [0m celery.backends.redis:redis.py:391 Connection to Redis lost: Retry (7/20) in 1.00 second.
[1m[31mERROR   [0m celery.backends.redis:redis.py:391 Connection to Redis lost: Retry (8/20) in 1.00 second.
[1m[31mERROR   [0m celery.backends.redis:redis.py:391 Connection to Redis lost: Retry (9/20) in 1.00 second.
[1m[31mERROR   [0m celery.backends.redis:redis.py:391 Connection to Redis lost: Retry (10/20) in 1.00 second.
[1m[31mERROR   [0m celery.backends.redis:redis.py:391 Connection to Redis lost: Retry (11/20) in 1.00 second.
[1m[31mERROR   [0m celery.backends.redis:redis.py:391 Connection to Redis lost: Retry (12/20) in 1.00 second.
[1m[31mERROR   [0m celery.backends.redis:redis.py:391 Connection to Redis lost: Retry (13/20) in 1.00 second.
[1m[31mERROR   [0m celery.backends.redis:redis.py:391 Connection to Redis lost: Retry (14/20) in 1.00 second.
[1m[31mERROR   [0m celery.backends.redis:redis.py:391 Connection to Redis lost: Retry (15/20) in 1.00 second.
[1m[31mERROR   [0m celery.backends.redis:redis.py:391 Connection to Redis lost: Retry (16/20) in 1.00 second.
[1m[31mERROR   [0m celery.backends.redis:redis.py:391 Connection to Redis lost: Retry (17/20) in 1.00 second.
[1m[31mERROR   [0m celery.backends.redis:redis.py:391 Connection to Redis lost: Retry (18/20) in 1.00 second.
[1m[31mERROR   [0m celery.backends.redis:redis.py:391 Connection to Redis lost: Retry (19/20) in 1.00 second.
[31mCRITICAL[0m celery.backends.redis:redis.py:132 
Retry limit exceeded while trying to reconnect to the Celery redis result store backend. The Celery application must be restarted.
[1m[31mERROR   [0m test_logger:queue_manager.py:728 Erreur lors de la r√©cup√©ration des timers pour test_user_api_draft: Error 111 connecting to localhost:6379. Connection refused.
[31m[1m_________________ TestTimers.test_get_timers_endpoint_session __________________[0m
self = <test_timers.TestTimers object at 0xffffb40b0180>
test_client = <httpx.AsyncClient object at 0xffffb2d31350>
redis_client = <redis.asyncio.client.Redis(<redis.asyncio.connection.ConnectionPool(<redis.asyncio.connection.Connection(host=redis-test,port=6379,db=1)>)>)>
>   ???
[1m[31mE   KeyError: 'timer_type'[0m
[1m[31m/Users/chrysostomebeltran/Documents/GitHub/redis_queue/tests/test_timers.py[0m:97: KeyError
---------------------------- Captured stderr setup -----------------------------
2025-01-09 21:10:46 - test_logger - INFO - Connexion Redis √©tablie avec succ√®s
2025-01-09 21:10:46 - test_logger - INFO - Client de test initialis√© avec succ√®s
------------------------------ Captured log setup ------------------------------
[32mINFO    [0m test_logger:conftest.py:132 Connexion Redis √©tablie avec succ√®s
[32mINFO    [0m test_logger:conftest.py:168 Client de test initialis√© avec succ√®s
----------------------------- Captured stderr call -----------------------------
2025-01-09 21:10:46 - test_logger - INFO - R√©cup√©ration des timers pour test_user_api_session
2025-01-09 21:11:06 - test_logger - ERROR - Erreur lors de la r√©cup√©ration des timers pour test_user_api_session: Error 111 connecting to localhost:6379. Connection refused.
------------------------------ Captured log call -------------------------------
[32mINFO    [0m test_logger:queue_manager.py:680 R√©cup√©ration des timers pour test_user_api_session
[1m[31mERROR   [0m celery.backends.redis:redis.py:391 Connection to Redis lost: Retry (0/20) now.
[1m[31mERROR   [0m celery.backends.redis:redis.py:391 Connection to Redis lost: Retry (1/20) in 1.00 second.
[1m[31mERROR   [0m celery.backends.redis:redis.py:391 Connection to Redis lost: Retry (2/20) in 1.00 second.
[1m[31mERROR   [0m celery.backends.redis:redis.py:391 Connection to Redis lost: Retry (3/20) in 1.00 second.
[1m[31mERROR   [0m celery.backends.redis:redis.py:391 Connection to Redis lost: Retry (4/20) in 1.00 second.
[1m[31mERROR   [0m celery.backends.redis:redis.py:391 Connection to Redis lost: Retry (5/20) in 1.00 second.
[1m[31mERROR   [0m celery.backends.redis:redis.py:391 Connection to Redis lost: Retry (6/20) in 1.00 second.
[1m[31mERROR   [0m celery.backends.redis:redis.py:391 Connection to Redis lost: Retry (7/20) in 1.00 second.
[1m[31mERROR   [0m celery.backends.redis:redis.py:391 Connection to Redis lost: Retry (8/20) in 1.00 second.
[1m[31mERROR   [0m celery.backends.redis:redis.py:391 Connection to Redis lost: Retry (9/20) in 1.00 second.
[1m[31mERROR   [0m celery.backends.redis:redis.py:391 Connection to Redis lost: Retry (10/20) in 1.00 second.
[1m[31mERROR   [0m celery.backends.redis:redis.py:391 Connection to Redis lost: Retry (11/20) in 1.00 second.
[1m[31mERROR   [0m celery.backends.redis:redis.py:391 Connection to Redis lost: Retry (12/20) in 1.00 second.
[1m[31mERROR   [0m celery.backends.redis:redis.py:391 Connection to Redis lost: Retry (13/20) in 1.00 second.
[1m[31mERROR   [0m celery.backends.redis:redis.py:391 Connection to Redis lost: Retry (14/20) in 1.00 second.
[1m[31mERROR   [0m celery.backends.redis:redis.py:391 Connection to Redis lost: Retry (15/20) in 1.00 second.
[1m[31mERROR   [0m celery.backends.redis:redis.py:391 Connection to Redis lost: Retry (16/20) in 1.00 second.
[1m[31mERROR   [0m celery.backends.redis:redis.py:391 Connection to Redis lost: Retry (17/20) in 1.00 second.
[1m[31mERROR   [0m celery.backends.redis:redis.py:391 Connection to Redis lost: Retry (18/20) in 1.00 second.
[1m[31mERROR   [0m celery.backends.redis:redis.py:391 Connection to Redis lost: Retry (19/20) in 1.00 second.
[31mCRITICAL[0m celery.backends.redis:redis.py:132 
Retry limit exceeded while trying to reconnect to the Celery redis result store backend. The Celery application must be restarted.
[1m[31mERROR   [0m test_logger:queue_manager.py:728 Erreur lors de la r√©cup√©ration des timers pour test_user_api_session: Error 111 connecting to localhost:6379. Connection refused.
[31m[1m___________________ TestTimers.test_get_timers_endpoint_both ___________________[0m
self = <test_timers.TestTimers object at 0xffffb40b4290>
test_client = <httpx.AsyncClient object at 0xffffb2d32d50>
redis_client = <redis.asyncio.client.Redis(<redis.asyncio.connection.ConnectionPool(<redis.asyncio.connection.Connection(host=redis-test,port=6379,db=1)>)>)>
>   ???
[1m[31mE   KeyError: 'timer_type'[0m
[1m[31m/Users/chrysostomebeltran/Documents/GitHub/redis_queue/tests/test_timers.py[0m:124: KeyError
---------------------------- Captured stderr setup -----------------------------
2025-01-09 21:11:06 - test_logger - INFO - Connexion Redis √©tablie avec succ√®s
2025-01-09 21:11:06 - test_logger - INFO - Client de test initialis√© avec succ√®s
------------------------------ Captured log setup ------------------------------
[32mINFO    [0m test_logger:conftest.py:132 Connexion Redis √©tablie avec succ√®s
[32mINFO    [0m test_logger:conftest.py:168 Client de test initialis√© avec succ√®s
----------------------------- Captured stderr call -----------------------------
2025-01-09 21:11:06 - test_logger - INFO - R√©cup√©ration des timers pour test_user_api_session
2025-01-09 21:11:25 - test_logger - ERROR - Erreur lors de la r√©cup√©ration des timers pour test_user_api_session: Error 111 connecting to localhost:6379. Connection refused.
2025-01-09 21:11:25 - test_logger - INFO - R√©cup√©ration des timers pour test_user_api_draft
2025-01-09 21:11:44 - test_logger - ERROR - Erreur lors de la r√©cup√©ration des timers pour test_user_api_draft: Error 111 connecting to localhost:6379. Connection refused.
------------------------------ Captured log call -------------------------------
[32mINFO    [0m test_logger:queue_manager.py:680 R√©cup√©ration des timers pour test_user_api_session
[1m[31mERROR   [0m celery.backends.redis:redis.py:391 Connection to Redis lost: Retry (0/20) now.
[1m[31mERROR   [0m celery.backends.redis:redis.py:391 Connection to Redis lost: Retry (1/20) in 1.00 second.
[1m[31mERROR   [0m celery.backends.redis:redis.py:391 Connection to Redis lost: Retry (2/20) in 1.00 second.
[1m[31mERROR   [0m celery.backends.redis:redis.py:391 Connection to Redis lost: Retry (3/20) in 1.00 second.
[1m[31mERROR   [0m celery.backends.redis:redis.py:391 Connection to Redis lost: Retry (4/20) in 1.00 second.
[1m[31mERROR   [0m celery.backends.redis:redis.py:391 Connection to Redis lost: Retry (5/20) in 1.00 second.
[1m[31mERROR   [0m celery.backends.redis:redis.py:391 Connection to Redis lost: Retry (6/20) in 1.00 second.
[1m[31mERROR   [0m celery.backends.redis:redis.py:391 Connection to Redis lost: Retry (7/20) in 1.00 second.
[1m[31mERROR   [0m celery.backends.redis:redis.py:391 Connection to Redis lost: Retry (8/20) in 1.00 second.
[1m[31mERROR   [0m celery.backends.redis:redis.py:391 Connection to Redis lost: Retry (9/20) in 1.00 second.
[1m[31mERROR   [0m celery.backends.redis:redis.py:391 Connection to Redis lost: Retry (10/20) in 1.00 second.
[1m[31mERROR   [0m celery.backends.redis:redis.py:391 Connection to Redis lost: Retry (11/20) in 1.00 second.
[1m[31mERROR   [0m celery.backends.redis:redis.py:391 Connection to Redis lost: Retry (12/20) in 1.00 second.
[1m[31mERROR   [0m celery.backends.redis:redis.py:391 Connection to Redis lost: Retry (13/20) in 1.00 second.
[1m[31mERROR   [0m celery.backends.redis:redis.py:391 Connection to Redis lost: Retry (14/20) in 1.00 second.
[1m[31mERROR   [0m celery.backends.redis:redis.py:391 Connection to Redis lost: Retry (15/20) in 1.00 second.
[1m[31mERROR   [0m celery.backends.redis:redis.py:391 Connection to Redis lost: Retry (16/20) in 1.00 second.
[1m[31mERROR   [0m celery.backends.redis:redis.py:391 Connection to Redis lost: Retry (17/20) in 1.00 second.
[1m[31mERROR   [0m celery.backends.redis:redis.py:391 Connection to Redis lost: Retry (18/20) in 1.00 second.
[1m[31mERROR   [0m celery.backends.redis:redis.py:391 Connection to Redis lost: Retry (19/20) in 1.00 second.
[31mCRITICAL[0m celery.backends.redis:redis.py:132 
Retry limit exceeded while trying to reconnect to the Celery redis result store backend. The Celery application must be restarted.
[1m[31mERROR   [0m test_logger:queue_manager.py:728 Erreur lors de la r√©cup√©ration des timers pour test_user_api_session: Error 111 connecting to localhost:6379. Connection refused.
[32mINFO    [0m test_logger:queue_manager.py:680 R√©cup√©ration des timers pour test_user_api_draft
[1m[31mERROR   [0m celery.backends.redis:redis.py:391 Connection to Redis lost: Retry (0/20) now.
[1m[31mERROR   [0m celery.backends.redis:redis.py:391 Connection to Redis lost: Retry (1/20) in 1.00 second.
[1m[31mERROR   [0m celery.backends.redis:redis.py:391 Connection to Redis lost: Retry (2/20) in 1.00 second.
[1m[31mERROR   [0m celery.backends.redis:redis.py:391 Connection to Redis lost: Retry (3/20) in 1.00 second.
[1m[31mERROR   [0m celery.backends.redis:redis.py:391 Connection to Redis lost: Retry (4/20) in 1.00 second.
[1m[31mERROR   [0m celery.backends.redis:redis.py:391 Connection to Redis lost: Retry (5/20) in 1.00 second.
[1m[31mERROR   [0m celery.backends.redis:redis.py:391 Connection to Redis lost: Retry (6/20) in 1.00 second.
[1m[31mERROR   [0m celery.backends.redis:redis.py:391 Connection to Redis lost: Retry (7/20) in 1.00 second.
[1m[31mERROR   [0m celery.backends.redis:redis.py:391 Connection to Redis lost: Retry (8/20) in 1.00 second.
[1m[31mERROR   [0m celery.backends.redis:redis.py:391 Connection to Redis lost: Retry (9/20) in 1.00 second.
[1m[31mERROR   [0m celery.backends.redis:redis.py:391 Connection to Redis lost: Retry (10/20) in 1.00 second.
[1m[31mERROR   [0m celery.backends.redis:redis.py:391 Connection to Redis lost: Retry (11/20) in 1.00 second.
[1m[31mERROR   [0m celery.backends.redis:redis.py:391 Connection to Redis lost: Retry (12/20) in 1.00 second.
[1m[31mERROR   [0m celery.backends.redis:redis.py:391 Connection to Redis lost: Retry (13/20) in 1.00 second.
[1m[31mERROR   [0m celery.backends.redis:redis.py:391 Connection to Redis lost: Retry (14/20) in 1.00 second.
[1m[31mERROR   [0m celery.backends.redis:redis.py:391 Connection to Redis lost: Retry (15/20) in 1.00 second.
[1m[31mERROR   [0m celery.backends.redis:redis.py:391 Connection to Redis lost: Retry (16/20) in 1.00 second.
[1m[31mERROR   [0m celery.backends.redis:redis.py:391 Connection to Redis lost: Retry (17/20) in 1.00 second.
[1m[31mERROR   [0m celery.backends.redis:redis.py:391 Connection to Redis lost: Retry (18/20) in 1.00 second.
[1m[31mERROR   [0m celery.backends.redis:redis.py:391 Connection to Redis lost: Retry (19/20) in 1.00 second.
[31mCRITICAL[0m celery.backends.redis:redis.py:132 
Retry limit exceeded while trying to reconnect to the Celery redis result store backend. The Celery application must be restarted.
[1m[31mERROR   [0m test_logger:queue_manager.py:728 Erreur lors de la r√©cup√©ration des timers pour test_user_api_draft: Error 111 connecting to localhost:6379. Connection refused.
[31m[1m___________________ TestTimers.test_pubsub_connection_draft ____________________[0m
self = <test_timers.TestTimers object at 0xffffb41497b0>
queue_manager_with_checker = <app.queue_manager.QueueManager object at 0xffffb2d6d850>
test_client = <httpx.AsyncClient object at 0xffffb2d863f0>
test_logger = <Logger test_logger (INFO)>
redis_client = <redis.asyncio.client.Redis(<redis.asyncio.connection.ConnectionPool(<redis.asyncio.connection.Connection(host=redis-test,port=6379,db=1)>)>)>
>   ???
[1m[31m/Users/chrysostomebeltran/Documents/GitHub/redis_queue/tests/test_timers.py[0m:184: 
_ _ _ _ _ _ _ _ _ _ _ _ _ _ _ _ _ _ _ _ _ _ _ _ _ _ _ _ _ _ _ _ _ _ _ _ _ _ _ _ 
[1m[31m/usr/local/lib/python3.13/asyncio/tasks.py[0m:507: in wait_for
    return await fut
_ _ _ _ _ _ _ _ _ _ _ _ _ _ _ _ _ _ _ _ _ _ _ _ _ _ _ _ _ _ _ _ _ _ _ _ _ _ _ _ 
>   ???
[1m[31mE   AssertionError: Timer type incorrect: {}[0m
[1m[31mE   assert None == 'draft'[0m
[1m[31mE    +  where None = <built-in method get of dict object at 0xffffb3762dc0>('timer_type')[0m
[1m[31mE    +    where <built-in method get of dict object at 0xffffb3762dc0> = {}.get[0m
[1m[31m/Users/chrysostomebeltran/Documents/GitHub/redis_queue/tests/test_timers.py[0m:180: AssertionError
---------------------------- Captured stderr setup -----------------------------
2025-01-09 21:11:44 - test_logger - INFO - Connexion Redis √©tablie avec succ√®s
2025-01-09 21:11:44 - test_logger - INFO - Slot checker d√©marr√© avec succ√®s
2025-01-09 21:11:44 - test_logger - INFO - Client de test initialis√© avec succ√®s
------------------------------ Captured log setup ------------------------------
[32mINFO    [0m test_logger:conftest.py:132 Connexion Redis √©tablie avec succ√®s
[32mINFO    [0m test_logger:conftest.py:179 Slot checker d√©marr√© avec succ√®s
[32mINFO    [0m test_logger:conftest.py:168 Client de test initialis√© avec succ√®s
----------------------------- Captured stderr call -----------------------------
2025-01-09 21:11:44 - test_logger - INFO - D√©marrage du test pubsub draft
2025-01-09 21:11:44 - test_logger - INFO - Tentative d'ajout de l'utilisateur test_user_pubsub_draft
2025-01-09 21:11:44 - test_logger - INFO - Statut actuel: {'status': None}
2025-01-09 21:11:44 - test_logger - INFO - Tentative d'ajout √† la file d'attente pour test_user_pubsub_draft avec statut None
2025-01-09 21:11:44 - test_logger - INFO - R√©sultats de la transaction Redis pour test_user_pubsub_draft: [1, 1, 1]
2025-01-09 21:11:44 - test_logger - INFO - V√©rification post-transaction pour test_user_pubsub_draft: queued=1, in_waiting=True
2025-01-09 21:11:44 - test_logger - INFO - Aucun historique de statuts trouv√© pour test_user_pubsub_draft
2025-01-09 21:11:44 - test_logger - INFO - Tentative d'offre de slot √† test_user_pubsub_draft
2025-01-09 21:11:44 - test_logger - INFO - Slot offert avec succ√®s √† test_user_pubsub_draft
2025-01-09 21:11:44 - test_logger - INFO - Utilisateur plac√© en draft avec succ√®s
2025-01-09 21:11:44 - test_logger - INFO - R√©cup√©ration des timers pour test_user_pubsub_draft
2025-01-09 21:12:03 - test_logger - ERROR - Erreur lors de la r√©cup√©ration des timers pour test_user_pubsub_draft: Error 111 connecting to localhost:6379. Connection refused.
2025-01-09 21:12:03 - test_logger - INFO - Timers re√ßus: {}
2025-01-09 21:12:03 - test_logger - ERROR - Erreur lors du test pubsub draft: Timer type incorrect: {}
assert None == 'draft'
 +  where None = <built-in method get of dict object at 0xffffb3762dc0>('timer_type')
 +    where <built-in method get of dict object at 0xffffb3762dc0> = {}.get
2025-01-09 21:12:03 - test_logger - INFO - Fin du test pubsub draft
------------------------------ Captured log call -------------------------------
[32mINFO    [0m test_logger:test_timers.py:148 D√©marrage du test pubsub draft
[32mINFO    [0m test_logger:queue_manager.py:194 Tentative d'ajout de l'utilisateur test_user_pubsub_draft
[32mINFO    [0m test_logger:queue_manager.py:198 Statut actuel: {'status': None}
[32mINFO    [0m test_logger:queue_manager.py:212 Tentative d'ajout √† la file d'attente pour test_user_pubsub_draft avec statut None
[32mINFO    [0m test_logger:queue_manager.py:220 R√©sultats de la transaction Redis pour test_user_pubsub_draft: [1, 1, 1]
[32mINFO    [0m test_logger:queue_manager.py:227 V√©rification post-transaction pour test_user_pubsub_draft: queued=1, in_waiting=True
[32mINFO    [0m test_logger:queue_manager.py:547 Aucun historique de statuts trouv√© pour test_user_pubsub_draft
[32mINFO    [0m test_logger:queue_manager.py:337 Tentative d'offre de slot √† test_user_pubsub_draft
[32mINFO    [0m test_logger:queue_manager.py:390 Slot offert avec succ√®s √† test_user_pubsub_draft
[32mINFO    [0m test_logger:test_timers.py:169 Utilisateur plac√© en draft avec succ√®s
[32mINFO    [0m test_logger:queue_manager.py:680 R√©cup√©ration des timers pour test_user_pubsub_draft
[1m[31mERROR   [0m celery.backends.redis:redis.py:391 Connection to Redis lost: Retry (0/20) now.
[1m[31mERROR   [0m celery.backends.redis:redis.py:391 Connection to Redis lost: Retry (1/20) in 1.00 second.
[1m[31mERROR   [0m celery.backends.redis:redis.py:391 Connection to Redis lost: Retry (2/20) in 1.00 second.
[1m[31mERROR   [0m celery.backends.redis:redis.py:391 Connection to Redis lost: Retry (3/20) in 1.00 second.
[1m[31mERROR   [0m celery.backends.redis:redis.py:391 Connection to Redis lost: Retry (4/20) in 1.00 second.
[1m[31mERROR   [0m celery.backends.redis:redis.py:391 Connection to Redis lost: Retry (5/20) in 1.00 second.
[1m[31mERROR   [0m celery.backends.redis:redis.py:391 Connection to Redis lost: Retry (6/20) in 1.00 second.
[1m[31mERROR   [0m celery.backends.redis:redis.py:391 Connection to Redis lost: Retry (7/20) in 1.00 second.
[1m[31mERROR   [0m celery.backends.redis:redis.py:391 Connection to Redis lost: Retry (8/20) in 1.00 second.
[1m[31mERROR   [0m celery.backends.redis:redis.py:391 Connection to Redis lost: Retry (9/20) in 1.00 second.
[1m[31mERROR   [0m celery.backends.redis:redis.py:391 Connection to Redis lost: Retry (10/20) in 1.00 second.
[1m[31mERROR   [0m celery.backends.redis:redis.py:391 Connection to Redis lost: Retry (11/20) in 1.00 second.
[1m[31mERROR   [0m celery.backends.redis:redis.py:391 Connection to Redis lost: Retry (12/20) in 1.00 second.
[1m[31mERROR   [0m celery.backends.redis:redis.py:391 Connection to Redis lost: Retry (13/20) in 1.00 second.
[1m[31mERROR   [0m celery.backends.redis:redis.py:391 Connection to Redis lost: Retry (14/20) in 1.00 second.
[1m[31mERROR   [0m celery.backends.redis:redis.py:391 Connection to Redis lost: Retry (15/20) in 1.00 second.
[1m[31mERROR   [0m celery.backends.redis:redis.py:391 Connection to Redis lost: Retry (16/20) in 1.00 second.
[1m[31mERROR   [0m celery.backends.redis:redis.py:391 Connection to Redis lost: Retry (17/20) in 1.00 second.
[1m[31mERROR   [0m celery.backends.redis:redis.py:391 Connection to Redis lost: Retry (18/20) in 1.00 second.
[1m[31mERROR   [0m celery.backends.redis:redis.py:391 Connection to Redis lost: Retry (19/20) in 1.00 second.
[31mCRITICAL[0m celery.backends.redis:redis.py:132 
Retry limit exceeded while trying to reconnect to the Celery redis result store backend. The Celery application must be restarted.
[1m[31mERROR   [0m test_logger:queue_manager.py:728 Erreur lors de la r√©cup√©ration des timers pour test_user_pubsub_draft: Error 111 connecting to localhost:6379. Connection refused.
[32mINFO    [0m test_logger:test_timers.py:177 Timers re√ßus: {}
[1m[31mERROR   [0m test_logger:test_timers.py:190 Erreur lors du test pubsub draft: Timer type incorrect: {}
assert None == 'draft'
 +  where None = <built-in method get of dict object at 0xffffb3762dc0>('timer_type')
 +    where <built-in method get of dict object at 0xffffb3762dc0> = {}.get
[32mINFO    [0m test_logger:test_timers.py:196 Fin du test pubsub draft
[31m[1m___________________ TestTimers.test_pubsub_multiple_updates ____________________[0m
self = <redis.connection.Connection(host=localhost,port=6379,db=1)>
    def connect(self):
        "Connects to the Redis server if not already connected"
        if self._sock:
            return
        try:
>           sock = self.retry.call_with_retry(
                lambda: self._connect(), lambda error: self.disconnect(error)
            )
[1m[31m/usr/local/lib/python3.13/site-packages/redis/connection.py[0m:357: 
_ _ _ _ _ _ _ _ _ _ _ _ _ _ _ _ _ _ _ _ _ _ _ _ _ _ _ _ _ _ _ _ _ _ _ _ _ _ _ _ 
[1m[31m/usr/local/lib/python3.13/site-packages/redis/retry.py[0m:62: in call_with_retry
    return do()
[1m[31m/usr/local/lib/python3.13/site-packages/redis/connection.py[0m:358: in <lambda>
    lambda: self._connect(), lambda error: self.disconnect(error)
[1m[31m/usr/local/lib/python3.13/site-packages/redis/connection.py[0m:730: in _connect
    raise err
_ _ _ _ _ _ _ _ _ _ _ _ _ _ _ _ _ _ _ _ _ _ _ _ _ _ _ _ _ _ _ _ _ _ _ _ _ _ _ _ 
self = <redis.connection.Connection(host=localhost,port=6379,db=1)>
    def _connect(self):
        "Create a TCP socket connection"
        # we want to mimic what socket.create_connection does to support
        # ipv4/ipv6, but we want to set options prior to calling
        # socket.connect()
        err = None
        for res in socket.getaddrinfo(
            self.host, self.port, self.socket_type, socket.SOCK_STREAM
        ):
            family, socktype, proto, canonname, socket_address = res
            sock = None
            try:
                sock = socket.socket(family, socktype, proto)
                # TCP_NODELAY
                sock.setsockopt(socket.IPPROTO_TCP, socket.TCP_NODELAY, 1)
                # TCP_KEEPALIVE
                if self.socket_keepalive:
                    sock.setsockopt(socket.SOL_SOCKET, socket.SO_KEEPALIVE, 1)
                    for k, v in self.socket_keepalive_options.items():
                        sock.setsockopt(socket.IPPROTO_TCP, k, v)
                # set the socket_connect_timeout before we connect
                sock.settimeout(self.socket_connect_timeout)
                # connect
>               sock.connect(socket_address)
[1m[31mE               ConnectionRefusedError: [Errno 111] Connection refused[0m
[1m[31m/usr/local/lib/python3.13/site-packages/redis/connection.py[0m:718: ConnectionRefusedError
[33mDuring handling of the above exception, another exception occurred:[0m
self = <celery.backends.redis.ResultConsumer object at 0xffffb2d2ccd0>
    @contextmanager
    def reconnect_on_error(self):
        try:
>           yield
[1m[31m/usr/local/lib/python3.13/site-packages/celery/backends/redis.py[0m:127: 
_ _ _ _ _ _ _ _ _ _ _ _ _ _ _ _ _ _ _ _ _ _ _ _ _ _ _ _ _ _ _ _ _ _ _ _ _ _ _ _ 
[1m[31m/usr/local/lib/python3.13/site-packages/celery/backends/redis.py[0m:177: in _consume_from
    self._pubsub.subscribe(key)
[1m[31m/usr/local/lib/python3.13/site-packages/redis/client.py[0m:957: in subscribe
    ret_val = self.execute_command("SUBSCRIBE", *new_channels.keys())
[1m[31m/usr/local/lib/python3.13/site-packages/redis/client.py[0m:786: in execute_command
    self.connection = self.connection_pool.get_connection(
[1m[31m/usr/local/lib/python3.13/site-packages/redis/connection.py[0m:1422: in get_connection
    connection.connect()
_ _ _ _ _ _ _ _ _ _ _ _ _ _ _ _ _ _ _ _ _ _ _ _ _ _ _ _ _ _ _ _ _ _ _ _ _ _ _ _ 
self = <redis.connection.Connection(host=localhost,port=6379,db=1)>
    def connect(self):
        "Connects to the Redis server if not already connected"
        if self._sock:
            return
        try:
            sock = self.retry.call_with_retry(
                lambda: self._connect(), lambda error: self.disconnect(error)
            )
        except socket.timeout:
            raise TimeoutError("Timeout connecting to server")
        except OSError as e:
>           raise ConnectionError(self._error_message(e))
[1m[31mE           redis.exceptions.ConnectionError: Error 111 connecting to localhost:6379. Connection refused.[0m
[1m[31m/usr/local/lib/python3.13/site-packages/redis/connection.py[0m:363: ConnectionError
[33mDuring handling of the above exception, another exception occurred:[0m
self = <redis.connection.Connection(host=localhost,port=6379,db=1)>
    def connect(self):
        "Connects to the Redis server if not already connected"
        if self._sock:
            return
        try:
>           sock = self.retry.call_with_retry(
                lambda: self._connect(), lambda error: self.disconnect(error)
            )
[1m[31m/usr/local/lib/python3.13/site-packages/redis/connection.py[0m:357: 
_ _ _ _ _ _ _ _ _ _ _ _ _ _ _ _ _ _ _ _ _ _ _ _ _ _ _ _ _ _ _ _ _ _ _ _ _ _ _ _ 
[1m[31m/usr/local/lib/python3.13/site-packages/redis/retry.py[0m:62: in call_with_retry
    return do()
[1m[31m/usr/local/lib/python3.13/site-packages/redis/connection.py[0m:358: in <lambda>
    lambda: self._connect(), lambda error: self.disconnect(error)
[1m[31m/usr/local/lib/python3.13/site-packages/redis/connection.py[0m:730: in _connect
    raise err
_ _ _ _ _ _ _ _ _ _ _ _ _ _ _ _ _ _ _ _ _ _ _ _ _ _ _ _ _ _ _ _ _ _ _ _ _ _ _ _ 
self = <redis.connection.Connection(host=localhost,port=6379,db=1)>
    def _connect(self):
        "Create a TCP socket connection"
        # we want to mimic what socket.create_connection does to support
        # ipv4/ipv6, but we want to set options prior to calling
        # socket.connect()
        err = None
        for res in socket.getaddrinfo(
            self.host, self.port, self.socket_type, socket.SOCK_STREAM
        ):
            family, socktype, proto, canonname, socket_address = res
            sock = None
            try:
                sock = socket.socket(family, socktype, proto)
                # TCP_NODELAY
                sock.setsockopt(socket.IPPROTO_TCP, socket.TCP_NODELAY, 1)
                # TCP_KEEPALIVE
                if self.socket_keepalive:
                    sock.setsockopt(socket.SOL_SOCKET, socket.SO_KEEPALIVE, 1)
                    for k, v in self.socket_keepalive_options.items():
                        sock.setsockopt(socket.IPPROTO_TCP, k, v)
                # set the socket_connect_timeout before we connect
                sock.settimeout(self.socket_connect_timeout)
                # connect
>               sock.connect(socket_address)
[1m[31mE               ConnectionRefusedError: [Errno 111] Connection refused[0m
[1m[31m/usr/local/lib/python3.13/site-packages/redis/connection.py[0m:718: ConnectionRefusedError
[33mDuring handling of the above exception, another exception occurred:[0m
self = <Connection: redis://localhost:6379 at 0xffffb3733c50>
ConnectionError = <class 'kombu.exceptions.OperationalError'>
ChannelError = <class 'kombu.exceptions.OperationalError'>
    @contextmanager
    def _reraise_as_library_errors(
            self,
            ConnectionError=exceptions.OperationalError,
            ChannelError=exceptions.OperationalError):
        try:
>           yield
[1m[31m/usr/local/lib/python3.13/site-packages/kombu/connection.py[0m:472: 
_ _ _ _ _ _ _ _ _ _ _ _ _ _ _ _ _ _ _ _ _ _ _ _ _ _ _ _ _ _ _ _ _ _ _ _ _ _ _ _ 
[1m[31m/usr/local/lib/python3.13/site-packages/celery/app/base.py[0m:800: in send_task
    self.backend.on_task_call(P, task_id)
[1m[31m/usr/local/lib/python3.13/site-packages/celery/backends/redis.py[0m:373: in on_task_call
    self.result_consumer.consume_from(task_id)
[1m[31m/usr/local/lib/python3.13/site-packages/celery/backends/redis.py[0m:169: in consume_from
    return self.start(task_id)
[1m[31m/usr/local/lib/python3.13/site-packages/celery/backends/redis.py[0m:147: in start
    self._consume_from(initial_task_id)
[1m[31m/usr/local/lib/python3.13/site-packages/celery/backends/redis.py[0m:176: in _consume_from
    with self.reconnect_on_error():
[1m[31m/usr/local/lib/python3.13/contextlib.py[0m:162: in __exit__
    self.gen.throw(value)
[1m[31m/usr/local/lib/python3.13/site-packages/celery/backends/redis.py[0m:130: in reconnect_on_error
    self._ensure(self._reconnect_pubsub, ())
[1m[31m/usr/local/lib/python3.13/site-packages/celery/backends/redis.py[0m:384: in ensure
    return retry_over_time(
[1m[31m/usr/local/lib/python3.13/site-packages/kombu/utils/functional.py[0m:318: in retry_over_time
    return fun(*args, **kwargs)
[1m[31m/usr/local/lib/python3.13/site-packages/celery/backends/redis.py[0m:106: in _reconnect_pubsub
    metas = self.backend.client.mget(self.subscribed_to)
[1m[31m/usr/local/lib/python3.13/site-packages/redis/commands/core.py[0m:2009: in mget
    return self.execute_command("MGET", *args, **options)
[1m[31m/usr/local/lib/python3.13/site-packages/redis/client.py[0m:559: in execute_command
    return self._execute_command(*args, **options)
[1m[31m/usr/local/lib/python3.13/site-packages/redis/client.py[0m:565: in _execute_command
    conn = self.connection or pool.get_connection(command_name, **options)
[1m[31m/usr/local/lib/python3.13/site-packages/redis/connection.py[0m:1422: in get_connection
    connection.connect()
_ _ _ _ _ _ _ _ _ _ _ _ _ _ _ _ _ _ _ _ _ _ _ _ _ _ _ _ _ _ _ _ _ _ _ _ _ _ _ _ 
self = <redis.connection.Connection(host=localhost,port=6379,db=1)>
    def connect(self):
        "Connects to the Redis server if not already connected"
        if self._sock:
            return
        try:
            sock = self.retry.call_with_retry(
                lambda: self._connect(), lambda error: self.disconnect(error)
            )
        except socket.timeout:
            raise TimeoutError("Timeout connecting to server")
        except OSError as e:
>           raise ConnectionError(self._error_message(e))
[1m[31mE           redis.exceptions.ConnectionError: Error 111 connecting to localhost:6379. Connection refused.[0m
[1m[31m/usr/local/lib/python3.13/site-packages/redis/connection.py[0m:363: ConnectionError
[33mThe above exception was the direct cause of the following exception:[0m
self = <test_timers.TestTimers object at 0xffffb415d850>
test_client = <httpx.AsyncClient object at 0xffffb2d4d9b0>
redis_client = <redis.asyncio.client.Redis(<redis.asyncio.connection.ConnectionPool(<redis.asyncio.connection.Connection(host=redis-test,port=6379,db=1)>)>)>
queue_manager_with_checker = <app.queue_manager.QueueManager object at 0xffffb2d6f4d0>
test_logger = <Logger test_logger (INFO)>
>   ???
[1m[31m/Users/chrysostomebeltran/Documents/GitHub/redis_queue/tests/test_timers.py[0m:357: 
_ _ _ _ _ _ _ _ _ _ _ _ _ _ _ _ _ _ _ _ _ _ _ _ _ _ _ _ _ _ _ _ _ _ _ _ _ _ _ _ 
[1m[31m/usr/local/lib/python3.13/site-packages/celery/app/base.py[0m:798: in send_task
    with P.connection._reraise_as_library_errors():
[1m[31m/usr/local/lib/python3.13/contextlib.py[0m:162: in __exit__
    self.gen.throw(value)
_ _ _ _ _ _ _ _ _ _ _ _ _ _ _ _ _ _ _ _ _ _ _ _ _ _ _ _ _ _ _ _ _ _ _ _ _ _ _ _ 
self = <Connection: redis://localhost:6379 at 0xffffb3733c50>
ConnectionError = <class 'kombu.exceptions.OperationalError'>
ChannelError = <class 'kombu.exceptions.OperationalError'>
    @contextmanager
    def _reraise_as_library_errors(
            self,
            ConnectionError=exceptions.OperationalError,
            ChannelError=exceptions.OperationalError):
        try:
            yield
        except (ConnectionError, ChannelError):
            raise
        except self.recoverable_connection_errors as exc:
>           raise ConnectionError(str(exc)) from exc
[1m[31mE           kombu.exceptions.OperationalError: Error 111 connecting to localhost:6379. Connection refused.[0m
[1m[31m/usr/local/lib/python3.13/site-packages/kombu/connection.py[0m:476: OperationalError
---------------------------- Captured stderr setup -----------------------------
2025-01-09 21:12:07 - test_logger - INFO - Connexion Redis √©tablie avec succ√®s
2025-01-09 21:12:07 - test_logger - INFO - Client de test initialis√© avec succ√®s
2025-01-09 21:12:07 - test_logger - INFO - Slot checker d√©marr√© avec succ√®s
------------------------------ Captured log setup ------------------------------
[32mINFO    [0m test_logger:conftest.py:132 Connexion Redis √©tablie avec succ√®s
[32mINFO    [0m test_logger:conftest.py:168 Client de test initialis√© avec succ√®s
[32mINFO    [0m test_logger:conftest.py:179 Slot checker d√©marr√© avec succ√®s
----------------------------- Captured stderr call -----------------------------
2025-01-09 21:12:07 - test_logger - INFO - Celery configur√© en mode asynchrone
2025-01-09 21:12:07 - test_logger - INFO - Tentative d'ajout de l'utilisateur test_user_pubsub_multiple
2025-01-09 21:12:07 - test_logger - INFO - Statut actuel: {'status': None}
2025-01-09 21:12:07 - test_logger - INFO - Tentative d'ajout √† la file d'attente pour test_user_pubsub_multiple avec statut None
2025-01-09 21:12:07 - test_logger - INFO - R√©sultats de la transaction Redis pour test_user_pubsub_multiple: [1, 1, 1]
2025-01-09 21:12:07 - test_logger - INFO - V√©rification post-transaction pour test_user_pubsub_multiple: queued=1, in_waiting=True
2025-01-09 21:12:07 - test_logger - INFO - Aucun historique de statuts trouv√© pour test_user_pubsub_multiple
2025-01-09 21:12:07 - test_logger - INFO - Tentative d'offre de slot √† test_user_pubsub_multiple
2025-01-09 21:12:07 - test_logger - INFO - Slot offert avec succ√®s √† test_user_pubsub_multiple
2025-01-09 21:12:07 - test_logger - INFO - Utilisateur test_user_pubsub_multiple plac√© en draft avec succ√®s
2025-01-09 21:12:07 - test_logger - INFO - Abonnement PubSub r√©ussi pour le channel timer:channel:test_user_pubsub_multiple
2025-01-09 21:12:07 - test_logger - INFO - TTL du draft: 300
2025-01-09 21:12:26 - test_logger - INFO - Test termin√©, nettoyage effectu√©
------------------------------ Captured log call -------------------------------
[32mINFO    [0m test_logger:test_timers.py:318 Celery configur√© en mode asynchrone
[32mINFO    [0m test_logger:queue_manager.py:194 Tentative d'ajout de l'utilisateur test_user_pubsub_multiple
[32mINFO    [0m test_logger:queue_manager.py:198 Statut actuel: {'status': None}
[32mINFO    [0m test_logger:queue_manager.py:212 Tentative d'ajout √† la file d'attente pour test_user_pubsub_multiple avec statut None
[32mINFO    [0m test_logger:queue_manager.py:220 R√©sultats de la transaction Redis pour test_user_pubsub_multiple: [1, 1, 1]
[32mINFO    [0m test_logger:queue_manager.py:227 V√©rification post-transaction pour test_user_pubsub_multiple: queued=1, in_waiting=True
[32mINFO    [0m test_logger:queue_manager.py:547 Aucun historique de statuts trouv√© pour test_user_pubsub_multiple
[32mINFO    [0m test_logger:queue_manager.py:337 Tentative d'offre de slot √† test_user_pubsub_multiple
[32mINFO    [0m test_logger:queue_manager.py:390 Slot offert avec succ√®s √† test_user_pubsub_multiple
[32mINFO    [0m test_logger:test_timers.py:340 Utilisateur test_user_pubsub_multiple plac√© en draft avec succ√®s
[32mINFO    [0m test_logger:test_timers.py:348 Abonnement PubSub r√©ussi pour le channel timer:channel:test_user_pubsub_multiple
[32mINFO    [0m test_logger:test_timers.py:353 TTL du draft: 300
[1m[31mERROR   [0m celery.backends.redis:redis.py:391 Connection to Redis lost: Retry (0/20) now.
[1m[31mERROR   [0m celery.backends.redis:redis.py:391 Connection to Redis lost: Retry (1/20) in 1.00 second.
[1m[31mERROR   [0m celery.backends.redis:redis.py:391 Connection to Redis lost: Retry (2/20) in 1.00 second.
[1m[31mERROR   [0m celery.backends.redis:redis.py:391 Connection to Redis lost: Retry (3/20) in 1.00 second.
[1m[31mERROR   [0m celery.backends.redis:redis.py:391 Connection to Redis lost: Retry (4/20) in 1.00 second.
[1m[31mERROR   [0m celery.backends.redis:redis.py:391 Connection to Redis lost: Retry (5/20) in 1.00 second.
[1m[31mERROR   [0m celery.backends.redis:redis.py:391 Connection to Redis lost: Retry (6/20) in 1.00 second.
[1m[31mERROR   [0m celery.backends.redis:redis.py:391 Connection to Redis lost: Retry (7/20) in 1.00 second.
[1m[31mERROR   [0m celery.backends.redis:redis.py:391 Connection to Redis lost: Retry (8/20) in 1.00 second.
[1m[31mERROR   [0m celery.backends.redis:redis.py:391 Connection to Redis lost: Retry (9/20) in 1.00 second.
[1m[31mERROR   [0m celery.backends.redis:redis.py:391 Connection to Redis lost: Retry (10/20) in 1.00 second.
[1m[31mERROR   [0m celery.backends.redis:redis.py:391 Connection to Redis lost: Retry (11/20) in 1.00 second.
[1m[31mERROR   [0m celery.backends.redis:redis.py:391 Connection to Redis lost: Retry (12/20) in 1.00 second.
[1m[31mERROR   [0m celery.backends.redis:redis.py:391 Connection to Redis lost: Retry (13/20) in 1.00 second.
[1m[31mERROR   [0m celery.backends.redis:redis.py:391 Connection to Redis lost: Retry (14/20) in 1.00 second.
[1m[31mERROR   [0m celery.backends.redis:redis.py:391 Connection to Redis lost: Retry (15/20) in 1.00 second.
[1m[31mERROR   [0m celery.backends.redis:redis.py:391 Connection to Redis lost: Retry (16/20) in 1.00 second.
[1m[31mERROR   [0m celery.backends.redis:redis.py:391 Connection to Redis lost: Retry (17/20) in 1.00 second.
[1m[31mERROR   [0m celery.backends.redis:redis.py:391 Connection to Redis lost: Retry (18/20) in 1.00 second.
[1m[31mERROR   [0m celery.backends.redis:redis.py:391 Connection to Redis lost: Retry (19/20) in 1.00 second.
[31mCRITICAL[0m celery.backends.redis:redis.py:132 
Retry limit exceeded while trying to reconnect to the Celery redis result store backend. The Celery application must be restarted.
[32mINFO    [0m test_logger:test_timers.py:411 Test termin√©, nettoyage effectu√©
[31m[1m______________ TestTimersAsync.test_pubsub_multiple_updates_async ______________[0m
self = <redis.connection.Connection(host=localhost,port=6379,db=1)>
    def connect(self):
        "Connects to the Redis server if not already connected"
        if self._sock:
            return
        try:
>           sock = self.retry.call_with_retry(
                lambda: self._connect(), lambda error: self.disconnect(error)
            )
[1m[31m/usr/local/lib/python3.13/site-packages/redis/connection.py[0m:357: 
_ _ _ _ _ _ _ _ _ _ _ _ _ _ _ _ _ _ _ _ _ _ _ _ _ _ _ _ _ _ _ _ _ _ _ _ _ _ _ _ 
[1m[31m/usr/local/lib/python3.13/site-packages/redis/retry.py[0m:62: in call_with_retry
    return do()
[1m[31m/usr/local/lib/python3.13/site-packages/redis/connection.py[0m:358: in <lambda>
    lambda: self._connect(), lambda error: self.disconnect(error)
[1m[31m/usr/local/lib/python3.13/site-packages/redis/connection.py[0m:730: in _connect
    raise err
_ _ _ _ _ _ _ _ _ _ _ _ _ _ _ _ _ _ _ _ _ _ _ _ _ _ _ _ _ _ _ _ _ _ _ _ _ _ _ _ 
self = <redis.connection.Connection(host=localhost,port=6379,db=1)>
    def _connect(self):
        "Create a TCP socket connection"
        # we want to mimic what socket.create_connection does to support
        # ipv4/ipv6, but we want to set options prior to calling
        # socket.connect()
        err = None
        for res in socket.getaddrinfo(
            self.host, self.port, self.socket_type, socket.SOCK_STREAM
        ):
            family, socktype, proto, canonname, socket_address = res
            sock = None
            try:
                sock = socket.socket(family, socktype, proto)
                # TCP_NODELAY
                sock.setsockopt(socket.IPPROTO_TCP, socket.TCP_NODELAY, 1)
                # TCP_KEEPALIVE
                if self.socket_keepalive:
                    sock.setsockopt(socket.SOL_SOCKET, socket.SO_KEEPALIVE, 1)
                    for k, v in self.socket_keepalive_options.items():
                        sock.setsockopt(socket.IPPROTO_TCP, k, v)
                # set the socket_connect_timeout before we connect
                sock.settimeout(self.socket_connect_timeout)
                # connect
>               sock.connect(socket_address)
[1m[31mE               ConnectionRefusedError: [Errno 111] Connection refused[0m
[1m[31m/usr/local/lib/python3.13/site-packages/redis/connection.py[0m:718: ConnectionRefusedError
[33mDuring handling of the above exception, another exception occurred:[0m
self = <celery.backends.redis.ResultConsumer object at 0xffffb4072e90>
    @contextmanager
    def reconnect_on_error(self):
        try:
>           yield
[1m[31m/usr/local/lib/python3.13/site-packages/celery/backends/redis.py[0m:127: 
_ _ _ _ _ _ _ _ _ _ _ _ _ _ _ _ _ _ _ _ _ _ _ _ _ _ _ _ _ _ _ _ _ _ _ _ _ _ _ _ 
[1m[31m/usr/local/lib/python3.13/site-packages/celery/backends/redis.py[0m:177: in _consume_from
    self._pubsub.subscribe(key)
[1m[31m/usr/local/lib/python3.13/site-packages/redis/client.py[0m:957: in subscribe
    ret_val = self.execute_command("SUBSCRIBE", *new_channels.keys())
[1m[31m/usr/local/lib/python3.13/site-packages/redis/client.py[0m:786: in execute_command
    self.connection = self.connection_pool.get_connection(
[1m[31m/usr/local/lib/python3.13/site-packages/redis/connection.py[0m:1422: in get_connection
    connection.connect()
_ _ _ _ _ _ _ _ _ _ _ _ _ _ _ _ _ _ _ _ _ _ _ _ _ _ _ _ _ _ _ _ _ _ _ _ _ _ _ _ 
self = <redis.connection.Connection(host=localhost,port=6379,db=1)>
    def connect(self):
        "Connects to the Redis server if not already connected"
        if self._sock:
            return
        try:
            sock = self.retry.call_with_retry(
                lambda: self._connect(), lambda error: self.disconnect(error)
            )
        except socket.timeout:
            raise TimeoutError("Timeout connecting to server")
        except OSError as e:
>           raise ConnectionError(self._error_message(e))
[1m[31mE           redis.exceptions.ConnectionError: Error 111 connecting to localhost:6379. Connection refused.[0m
[1m[31m/usr/local/lib/python3.13/site-packages/redis/connection.py[0m:363: ConnectionError
[33mDuring handling of the above exception, another exception occurred:[0m
self = <redis.connection.Connection(host=localhost,port=6379,db=1)>
    def connect(self):
        "Connects to the Redis server if not already connected"
        if self._sock:
            return
        try:
>           sock = self.retry.call_with_retry(
                lambda: self._connect(), lambda error: self.disconnect(error)
            )
[1m[31m/usr/local/lib/python3.13/site-packages/redis/connection.py[0m:357: 
_ _ _ _ _ _ _ _ _ _ _ _ _ _ _ _ _ _ _ _ _ _ _ _ _ _ _ _ _ _ _ _ _ _ _ _ _ _ _ _ 
[1m[31m/usr/local/lib/python3.13/site-packages/redis/retry.py[0m:62: in call_with_retry
    return do()
[1m[31m/usr/local/lib/python3.13/site-packages/redis/connection.py[0m:358: in <lambda>
    lambda: self._connect(), lambda error: self.disconnect(error)
[1m[31m/usr/local/lib/python3.13/site-packages/redis/connection.py[0m:730: in _connect
    raise err
_ _ _ _ _ _ _ _ _ _ _ _ _ _ _ _ _ _ _ _ _ _ _ _ _ _ _ _ _ _ _ _ _ _ _ _ _ _ _ _ 
self = <redis.connection.Connection(host=localhost,port=6379,db=1)>
    def _connect(self):
        "Create a TCP socket connection"
        # we want to mimic what socket.create_connection does to support
        # ipv4/ipv6, but we want to set options prior to calling
        # socket.connect()
        err = None
        for res in socket.getaddrinfo(
            self.host, self.port, self.socket_type, socket.SOCK_STREAM
        ):
            family, socktype, proto, canonname, socket_address = res
            sock = None
            try:
                sock = socket.socket(family, socktype, proto)
                # TCP_NODELAY
                sock.setsockopt(socket.IPPROTO_TCP, socket.TCP_NODELAY, 1)
                # TCP_KEEPALIVE
                if self.socket_keepalive:
                    sock.setsockopt(socket.SOL_SOCKET, socket.SO_KEEPALIVE, 1)
                    for k, v in self.socket_keepalive_options.items():
                        sock.setsockopt(socket.IPPROTO_TCP, k, v)
                # set the socket_connect_timeout before we connect
                sock.settimeout(self.socket_connect_timeout)
                # connect
>               sock.connect(socket_address)
[1m[31mE               ConnectionRefusedError: [Errno 111] Connection refused[0m
[1m[31m/usr/local/lib/python3.13/site-packages/redis/connection.py[0m:718: ConnectionRefusedError
[33mDuring handling of the above exception, another exception occurred:[0m
self = <Connection: redis://localhost:6379 at 0xffffb3733c50>
ConnectionError = <class 'kombu.exceptions.OperationalError'>
ChannelError = <class 'kombu.exceptions.OperationalError'>
    @contextmanager
    def _reraise_as_library_errors(
            self,
            ConnectionError=exceptions.OperationalError,
            ChannelError=exceptions.OperationalError):
        try:
>           yield
[1m[31m/usr/local/lib/python3.13/site-packages/kombu/connection.py[0m:472: 
_ _ _ _ _ _ _ _ _ _ _ _ _ _ _ _ _ _ _ _ _ _ _ _ _ _ _ _ _ _ _ _ _ _ _ _ _ _ _ _ 
[1m[31m/usr/local/lib/python3.13/site-packages/celery/app/base.py[0m:800: in send_task
    self.backend.on_task_call(P, task_id)
[1m[31m/usr/local/lib/python3.13/site-packages/celery/backends/redis.py[0m:373: in on_task_call
    self.result_consumer.consume_from(task_id)
[1m[31m/usr/local/lib/python3.13/site-packages/celery/backends/redis.py[0m:169: in consume_from
    return self.start(task_id)
[1m[31m/usr/local/lib/python3.13/site-packages/celery/backends/redis.py[0m:147: in start
    self._consume_from(initial_task_id)
[1m[31m/usr/local/lib/python3.13/site-packages/celery/backends/redis.py[0m:176: in _consume_from
    with self.reconnect_on_error():
[1m[31m/usr/local/lib/python3.13/contextlib.py[0m:162: in __exit__
    self.gen.throw(value)
[1m[31m/usr/local/lib/python3.13/site-packages/celery/backends/redis.py[0m:130: in reconnect_on_error
    self._ensure(self._reconnect_pubsub, ())
[1m[31m/usr/local/lib/python3.13/site-packages/celery/backends/redis.py[0m:384: in ensure
    return retry_over_time(
[1m[31m/usr/local/lib/python3.13/site-packages/kombu/utils/functional.py[0m:318: in retry_over_time
    return fun(*args, **kwargs)
[1m[31m/usr/local/lib/python3.13/site-packages/celery/backends/redis.py[0m:106: in _reconnect_pubsub
    metas = self.backend.client.mget(self.subscribed_to)
[1m[31m/usr/local/lib/python3.13/site-packages/redis/commands/core.py[0m:2009: in mget
    return self.execute_command("MGET", *args, **options)
[1m[31m/usr/local/lib/python3.13/site-packages/redis/client.py[0m:559: in execute_command
    return self._execute_command(*args, **options)
[1m[31m/usr/local/lib/python3.13/site-packages/redis/client.py[0m:565: in _execute_command
    conn = self.connection or pool.get_connection(command_name, **options)
[1m[31m/usr/local/lib/python3.13/site-packages/redis/connection.py[0m:1422: in get_connection
    connection.connect()
_ _ _ _ _ _ _ _ _ _ _ _ _ _ _ _ _ _ _ _ _ _ _ _ _ _ _ _ _ _ _ _ _ _ _ _ _ _ _ _ 
self = <redis.connection.Connection(host=localhost,port=6379,db=1)>
    def connect(self):
        "Connects to the Redis server if not already connected"
        if self._sock:
            return
        try:
            sock = self.retry.call_with_retry(
                lambda: self._connect(), lambda error: self.disconnect(error)
            )
        except socket.timeout:
            raise TimeoutError("Timeout connecting to server")
        except OSError as e:
>           raise ConnectionError(self._error_message(e))
[1m[31mE           redis.exceptions.ConnectionError: Error 111 connecting to localhost:6379. Connection refused.[0m
[1m[31m/usr/local/lib/python3.13/site-packages/redis/connection.py[0m:363: ConnectionError
[33mThe above exception was the direct cause of the following exception:[0m
self = <test_timers_async.TestTimersAsync object at 0xffffb419e5d0>
test_client = <httpx.AsyncClient object at 0xffffb2d07860>
redis_client = <redis.asyncio.client.Redis(<redis.asyncio.connection.ConnectionPool(<redis.asyncio.connection.Connection(host=redis-test,port=6379,db=1)>)>)>
queue_manager_with_checker = <app.queue_manager.QueueManager object at 0xffffb22fec50>
test_logger = <Logger test_logger (INFO)>
>   ???
[1m[31m/Users/chrysostomebeltran/Documents/GitHub/redis_queue/tests/test_timers_async.py[0m:53: 
_ _ _ _ _ _ _ _ _ _ _ _ _ _ _ _ _ _ _ _ _ _ _ _ _ _ _ _ _ _ _ _ _ _ _ _ _ _ _ _ 
[1m[31m/usr/local/lib/python3.13/site-packages/celery/app/base.py[0m:798: in send_task
    with P.connection._reraise_as_library_errors():
[1m[31m/usr/local/lib/python3.13/contextlib.py[0m:162: in __exit__
    self.gen.throw(value)
_ _ _ _ _ _ _ _ _ _ _ _ _ _ _ _ _ _ _ _ _ _ _ _ _ _ _ _ _ _ _ _ _ _ _ _ _ _ _ _ 
self = <Connection: redis://localhost:6379 at 0xffffb3733c50>
ConnectionError = <class 'kombu.exceptions.OperationalError'>
ChannelError = <class 'kombu.exceptions.OperationalError'>
    @contextmanager
    def _reraise_as_library_errors(
            self,
            ConnectionError=exceptions.OperationalError,
            ChannelError=exceptions.OperationalError):
        try:
            yield
        except (ConnectionError, ChannelError):
            raise
        except self.recoverable_connection_errors as exc:
>           raise ConnectionError(str(exc)) from exc
[1m[31mE           kombu.exceptions.OperationalError: Error 111 connecting to localhost:6379. Connection refused.[0m
[1m[31m/usr/local/lib/python3.13/site-packages/kombu/connection.py[0m:476: OperationalError
---------------------------- Captured stderr setup -----------------------------
2025-01-09 21:12:32 - test_logger - INFO - Connexion Redis √©tablie avec succ√®s
2025-01-09 21:12:32 - test_logger - INFO - QueueManager initialis√© avec succ√®s
2025-01-09 21:12:32 - test_logger - INFO - Client de test initialis√© avec succ√®s
2025-01-09 21:12:32 - test_logger - INFO - Slot checker d√©marr√© avec succ√®s
------------------------------ Captured log setup ------------------------------
[32mINFO    [0m test_logger:conftest.py:132 Connexion Redis √©tablie avec succ√®s
[32mINFO    [0m test_logger:conftest.py:155 QueueManager initialis√© avec succ√®s
[32mINFO    [0m test_logger:conftest.py:168 Client de test initialis√© avec succ√®s
[32mINFO    [0m test_logger:conftest.py:179 Slot checker d√©marr√© avec succ√®s
----------------------------- Captured stderr call -----------------------------
2025-01-09 21:12:32 - test_logger - INFO - Celery configur√© en mode asynchrone
2025-01-09 21:12:32 - test_logger - INFO - Tentative d'ajout de l'utilisateur test_user_pubsub_multiple_async
2025-01-09 21:12:32 - test_logger - INFO - Statut actuel: {'status': None}
2025-01-09 21:12:32 - test_logger - INFO - Tentative d'ajout √† la file d'attente pour test_user_pubsub_multiple_async avec statut None
2025-01-09 21:12:32 - test_logger - INFO - R√©sultats de la transaction Redis pour test_user_pubsub_multiple_async: [1, 1, 1]
2025-01-09 21:12:32 - test_logger - INFO - V√©rification post-transaction pour test_user_pubsub_multiple_async: queued=1, in_waiting=True
2025-01-09 21:12:32 - test_logger - INFO - Aucun historique de statuts trouv√© pour test_user_pubsub_multiple_async
2025-01-09 21:12:32 - test_logger - INFO - Tentative d'offre de slot √† test_user_pubsub_multiple_async
2025-01-09 21:12:32 - test_logger - INFO - Slot offert avec succ√®s √† test_user_pubsub_multiple_async
2025-01-09 21:12:32 - test_logger - INFO - Utilisateur test_user_pubsub_multiple_async plac√© en draft avec succ√®s
2025-01-09 21:12:32 - test_logger - INFO - Abonnement PubSub r√©ussi pour le channel timer:channel:test_user_pubsub_multiple_async
2025-01-09 21:12:32 - test_logger - INFO - TTL du draft: 300
2025-01-09 21:12:51 - test_logger - INFO - Test termin√©, nettoyage effectu√©
------------------------------ Captured log call -------------------------------
[32mINFO    [0m test_logger:test_timers_async.py:14 Celery configur√© en mode asynchrone
[32mINFO    [0m test_logger:queue_manager.py:194 Tentative d'ajout de l'utilisateur test_user_pubsub_multiple_async
[32mINFO    [0m test_logger:queue_manager.py:198 Statut actuel: {'status': None}
[32mINFO    [0m test_logger:queue_manager.py:212 Tentative d'ajout √† la file d'attente pour test_user_pubsub_multiple_async avec statut None
[32mINFO    [0m test_logger:queue_manager.py:220 R√©sultats de la transaction Redis pour test_user_pubsub_multiple_async: [1, 1, 1]
[32mINFO    [0m test_logger:queue_manager.py:227 V√©rification post-transaction pour test_user_pubsub_multiple_async: queued=1, in_waiting=True
[32mINFO    [0m test_logger:queue_manager.py:547 Aucun historique de statuts trouv√© pour test_user_pubsub_multiple_async
[32mINFO    [0m test_logger:queue_manager.py:337 Tentative d'offre de slot √† test_user_pubsub_multiple_async
[32mINFO    [0m test_logger:queue_manager.py:390 Slot offert avec succ√®s √† test_user_pubsub_multiple_async
[32mINFO    [0m test_logger:test_timers_async.py:36 Utilisateur test_user_pubsub_multiple_async plac√© en draft avec succ√®s
[32mINFO    [0m test_logger:test_timers_async.py:44 Abonnement PubSub r√©ussi pour le channel timer:channel:test_user_pubsub_multiple_async
[32mINFO    [0m test_logger:test_timers_async.py:49 TTL du draft: 300
[1m[31mERROR   [0m celery.backends.redis:redis.py:391 Connection to Redis lost: Retry (0/20) now.
[1m[31mERROR   [0m celery.backends.redis:redis.py:391 Connection to Redis lost: Retry (1/20) in 1.00 second.
[1m[31mERROR   [0m celery.backends.redis:redis.py:391 Connection to Redis lost: Retry (2/20) in 1.00 second.
[1m[31mERROR   [0m celery.backends.redis:redis.py:391 Connection to Redis lost: Retry (3/20) in 1.00 second.
[1m[31mERROR   [0m celery.backends.redis:redis.py:391 Connection to Redis lost: Retry (4/20) in 1.00 second.
[1m[31mERROR   [0m celery.backends.redis:redis.py:391 Connection to Redis lost: Retry (5/20) in 1.00 second.
[1m[31mERROR   [0m celery.backends.redis:redis.py:391 Connection to Redis lost: Retry (6/20) in 1.00 second.
[1m[31mERROR   [0m celery.backends.redis:redis.py:391 Connection to Redis lost: Retry (7/20) in 1.00 second.
[1m[31mERROR   [0m celery.backends.redis:redis.py:391 Connection to Redis lost: Retry (8/20) in 1.00 second.
[1m[31mERROR   [0m celery.backends.redis:redis.py:391 Connection to Redis lost: Retry (9/20) in 1.00 second.
[1m[31mERROR   [0m celery.backends.redis:redis.py:391 Connection to Redis lost: Retry (10/20) in 1.00 second.
[1m[31mERROR   [0m celery.backends.redis:redis.py:391 Connection to Redis lost: Retry (11/20) in 1.00 second.
[1m[31mERROR   [0m celery.backends.redis:redis.py:391 Connection to Redis lost: Retry (12/20) in 1.00 second.
[1m[31mERROR   [0m celery.backends.redis:redis.py:391 Connection to Redis lost: Retry (13/20) in 1.00 second.
[1m[31mERROR   [0m celery.backends.redis:redis.py:391 Connection to Redis lost: Retry (14/20) in 1.00 second.
[1m[31mERROR   [0m celery.backends.redis:redis.py:391 Connection to Redis lost: Retry (15/20) in 1.00 second.
[1m[31mERROR   [0m celery.backends.redis:redis.py:391 Connection to Redis lost: Retry (16/20) in 1.00 second.
[1m[31mERROR   [0m celery.backends.redis:redis.py:391 Connection to Redis lost: Retry (17/20) in 1.00 second.
[1m[31mERROR   [0m celery.backends.redis:redis.py:391 Connection to Redis lost: Retry (18/20) in 1.00 second.
[1m[31mERROR   [0m celery.backends.redis:redis.py:391 Connection to Redis lost: Retry (19/20) in 1.00 second.
[31mCRITICAL[0m celery.backends.redis:redis.py:132 
Retry limit exceeded while trying to reconnect to the Celery redis result store backend. The Celery application must be restarted.
[32mINFO    [0m test_logger:test_timers_async.py:112 Test termin√©, nettoyage effectu√©
[33m=============================== warnings summary ===============================[0m
tests/test_timers.py::TestTimers::test_get_timers_endpoint_draft
tests/test_timers.py::TestTimers::test_get_timers_endpoint_both
tests/test_timers.py::TestTimers::test_pubsub_connection_draft
  /app/app/queue_manager.py:714: AlwaysEagerIgnored: task_always_eager has no effect on send_task
    celery.send_task(
tests/test_timers.py::TestTimers::test_get_timers_endpoint_session
tests/test_timers.py::TestTimers::test_get_timers_endpoint_both
  /app/app/queue_manager.py:701: AlwaysEagerIgnored: task_always_eager has no effect on send_task
    celery.send_task(
-- Docs: https://docs.pytest.org/en/stable/how-to/capture-warnings.html
---------- coverage: platform linux, python 3.13.1-final-0 -----------
Name                   Stmts   Miss  Cover   Missing
----------------------------------------------------
app/api_endpoints.py       6      6     0%   1-7
app/celery_app.py          6      6     0%   1-19
app/main.py               96     33    66%   22-23, 26-27, 30-38, 46-66, 86, 102, 110, 130-131, 141-151
app/queue_manager.py     486    145    70%   41-53, 72, 76-77, 128-130, 164-166, 187-189, 230-231, 244-245, 286, 311, 318-320, 353-354, 373, 393-400, 435, 447-454, 484-486, 533, 559-562, 585-586, 601, 611-619, 632-675, 706, 719, 746-747, 752-757, 766-809, 814-856, 908-910, 918-920
----------------------------------------------------
TOTAL                    594    190    68%
[36m[1m=========================== short test summary info ============================[0m
[31mFAILED[0m tests/test_api_endpoints.py::[1mTestAPI::test_join_queue_flow_when_full[0m - KeyError: 'position'
[31mFAILED[0m tests/test_api_endpoints.py::[1mTestAPI::test_timers_async[0m - KeyError: 'timer_type'
[31mFAILED[0m tests/test_integration.py::[1mTestIntegration::test_concurrent_users[0m - AssertionError: La file d'attente devrait contenir 5 utilisateurs
[31mFAILED[0m tests/test_timers.py::[1mTestTimers::test_get_timers_endpoint_draft[0m - KeyError: 'timer_type'
[31mFAILED[0m tests/test_timers.py::[1mTestTimers::test_get_timers_endpoint_session[0m - KeyError: 'timer_type'
[31mFAILED[0m tests/test_timers.py::[1mTestTimers::test_get_timers_endpoint_both[0m - KeyError: 'timer_type'
[31mFAILED[0m tests/test_timers.py::[1mTestTimers::test_pubsub_connection_draft[0m - AssertionError: Timer type incorrect: {}
[31mFAILED[0m tests/test_timers.py::[1mTestTimers::test_pubsub_multiple_updates[0m - kombu.exceptions.OperationalError: Error 111 connecting to localhost:6379. ...
[31mFAILED[0m tests/test_timers_async.py::[1mTestTimersAsync::test_pubsub_multiple_updates_async[0m - kombu.exceptions.OperationalError: Error 111 connecting to localhost:6379. ...
[31m============= [31m[1m9 failed[0m, [32m25 passed[0m, [33m5 warnings[0m[31m in 153.72s (0:02:33)[0m[31m =============[0m
</pre>
    </div>
</body>
</html>
